Workbook

Sheet 01.2026
A1: Conta contábil | B1: Código Red. | C1: Descrição da Conta | D1: Saldo anterior | E1: Débito | F1: Crédito | G1: Movimento do Mês | H1: Saldo Atual
A2: 1 | C2: ATIVO | D2: 5330654 | E2: 2385665.3 | F2: 2788249.5 | H2: 4928069.7
A3: 1.1 | C3: ATIVO CIRCULANTE | D3: 2183243.4 | E3: 2201940.8 | F3: 2598441.2 | H3: 1786743
A4: 1.1.01 | C4: DISPONÍVEL | D4: 22157 | E4: 1411427.7 | F4: 1427037.4 | H4: 6547.21
A5: 1.1.01.01 | C5: CAIXA | D5: 0 | E5: 150694.49 | F5: 150694.49 | H5: 0
A6: 1.1.01.01.0010 | B6: 5 | C6: Entre Contas | D6: 0 | E6: 150694.49 | F6: 150694.49 | H6: 0
A7: 1.1.01.02 | C7: BANCOS CONTA MOVIMENTO | D7: 18003.95 | E7: 1260733.2 | F7: 1272189.9 | H7: 6547.21
A8: 1.1.01.02.0001 | B8: 27 | C8: Banco Itaú | D8: 1 | E8: 1076581.6 | F8: 1076582.6 | H8: 0
A9: 1.1.01.02.0002 | B9: 576 | C9: Banco Pag Útil | D9: 0 | E9: 3194.49 | F9: 1834.58 | H9: 1359.91
A10: 1.1.01.02.0101 | B10: 5444 | C10: Mercado Pago - Banco Digital | D10: 4760.31 | E10: 549.21 | F10: 122.22 | H10: 5187.3
A11: 1.1.01.02.0102 | B11: 5860 | C11: Banco Bradesco | D11: 13242.64 | E11: 180407.88 | F11: 193650.52 | H11: 0
A12: 1.1.01.03 | C12: APLICAÇÕES FINANCEIRAS | D12: 4153.05 | E12: 0 | F12: 4153.05 | H12: 0
A13: 1.1.01.03.0001 | B13: 35 | C13: Aplicações Banco Itaú | D13: 4153.05 | E13: 0 | F13: 4153.05 | H13: 0
A14: 1.1.02 | C14: CONTAS A RECEBER | D14: 857471.45 | E14: 710212.13 | F14: 953371.47 | H14: 614312.11
A15: 1.1.02.01 | C15: CLIENTES NACIONAIS | D15: 857471.45 | E15: 710212.13 | F15: 953371.47 | H15: 614312.11
A16: 1.1.02.01.0001 | B16: 43 | C16: Clientes Nacionais | D16: 513164.42 | E16: 651228.61 | F16: 765371.47 | H16: 399021.56
A17: 1.1.02.01.0002 | B17: 5347 | C17: Clientes B2B | D17: 344307.03 | E17: 58983.52 | F17: 188000 | H17: 215290.55
A18: 1.1.03 | C18: OUTROS CRÉDITOS | D18: 350507.25 | E18: 53317.65 | F18: 55870.19 | H18: 347954.71
A19: 1.1.03.01 | C19: CRÉDITOS DE FUNCIONÁRIOS | D19: 6071.56 | E19: 34747.35 | F19: 37600.01 | H19: 3218.9
A20: 1.1.03.01.0002 | B20: 60 | C20: Adiantamento de Férias | D20: 6071.56 | E20: 2972.89 | F20: 5825.55 | H20: 3218.9
A21: 1.1.03.01.0003 | B21: 3263 | C21: Adiantamento de Salários | D21: 0 | E21: 31774.46 | F21: 31774.46 | H21: 0
A22: 1.1.03.02 | C22: ADIANTAMENTO A FORNECEDORES | D22: 147010.2 | E22: 0 | F22: 0 | H22: 147010.2
A23: 1.1.03.02.0001 | B23: 3220 | C23: Adiantamento a Fornecedores | D23: 147010.2 | E23: 0 | F23: 0 | H23: 147010.2
A24: 1.1.03.03 | C24: OUTROS CREDITOS A RECEBER | D24: 126211.51 | E24: 0 | F24: 0 | H24: 126211.51
A25: 1.1.03.03.0001 | B25: 5789 | C25: Outros Creditos a Receber | D25: 126211.51 | E25: 0 | F25: 0 | H25: 126211.51
A26: 1.1.03.05 | C26: IMPOSTOS A RECUPERAR | D26: 7120.88 | E26: 18570.3 | F26: 18270.18 | H26: 7421
A27: 1.1.03.05.0003 | B27: 116 | C27: ICMS a Recuperar | D27: 0 | E27: 18570.3 | F27: 18270.18 | H27: 300.12
A28: 1.1.03.05.0008 | B28: 5274 | C28: ICMS Difal a Recuperar | D28: 7120.88 | E28: 0 | F28: 0 | H28: 7120.88
A29: 1.1.03.06 | C29: TRIBUTOS A COMPENSAR | D29: 64093.1 | E29: 0 | F29: 0 | H29: 64093.1
A30: 1.1.03.06.0003 | B30: 4502 | C30: Saldo Negativo IRPJ | D30: 13.87 | E30: 0 | F30: 0 | H30: 13.87
A31: 1.1.03.06.0004 | B31: 4510 | C31: CSLL a Compensar | D31: 34627.34 | E31: 0 | F31: 0 | H31: 34627.34
A32: 1.1.03.06.0007 | B32: 4545 | C32: IRRF Aplicação | D32: 16.21 | E32: 0 | F32: 0 | H32: 16.21
A33: 1.1.03.06.0009 | B33: 4561 | C33: IRPJ a Compensar | D33: 29435.68 | E33: 0 | F33: 0 | H33: 29435.68
A34: 1.1.06 | C34: ESTOQUES | D34: 953107.73 | E34: 26983.33 | F34: 162162.06 | H34: 817929
A35: 1.1.06.01 | C35: ESTOQUES PARA REVENDA | D35: 953107.73 | E35: 26983.33 | F35: 162162.06 | H35: 817929
A36: 1.1.06.01.0001 | B36: 175 | C36: Mercadorias para Revenda | D36: 953107.73 | E36: 26983.33 | F36: 162162.06 | H36: 817929
A37: 1.2 | C37: ATIVO NÃO CIRCULANTE | D37: 3147410.6 | E37: 0 | F37: 6083.86 | H37: 3141326.7
A38: 1.2.01 | C38: ATIVO REALIZÁVEL A LONGO PRAZO | D38: 3022149 | E38: 0 | F38: 0 | H38: 3022149
A39: 1.2.01.05 | C39: CRÉDITOS A SÓCIOS | D39: 3022149 | E39: 0 | F39: 0 | H39: 3022149
A40: 1.2.01.05.0001 | B40: 3336 | C40: Mutuo Sócios | D40: 1224589.3 | E40: 0 | F40: 0 | H40: 1224589.3
...

Sheet 02.2026
A1: Conta contábil | B1: Código Red. | C1: Descrição da Conta | D1: Saldo anterior | E1: Débito | F1: Crédito | H1: Saldo Atual
A2: 1 | C2: ATIVO | D2: 4928069.7 | E2: 2269040 | F2: 2212147.2 | H2: 4984962.5
A3: 1.1 | C3: ATIVO CIRCULANTE | D3: 1786743 | E3: 2119253.7 | F3: 2056277 | H3: 1849719.7
A4: 1.1.01 | C4: DISPONÍVEL | D4: 6547.21 | E4: 1445920.8 | F4: 1446123.9 | H4: 6344.09
A5: 1.1.01.01 | C5: CAIXA | D5: 0 | E5: 85700 | F5: 85700 | H5: 0
A6: 1.1.01.01.0010 | B6: 5 | C6: Entre Contas | D6: 0 | E6: 85700 | F6: 85700 | H6: 0
A7: 1.1.01.02 | C7: BANCOS CONTA MOVIMENTO | D7: 6547.21 | E7: 1360220.8 | F7: 1360423.9 | H7: 6344.09
A8: 1.1.01.02.0001 | B8: 27 | C8: Banco Itaú | D8: 0 | E8: 1237885.7 | F8: 1237885.7 | H8: 0
A9: 1.1.01.02.0002 | B9: 576 | C9: Banco Pag Útil | D9: 1359.91 | E9: 46700 | F9: 47211.17 | H9: 848.74
A10: 1.1.01.02.0101 | B10: 5444 | C10: Mercado Pago - Banco Digital | D10: 5187.3 | E10: 308.05 | F10: 0 | H10: 5495.35
A11: 1.1.01.02.0102 | B11: 5860 | C11: Banco Bradesco | D11: 0 | E11: 75327 | F11: 75327 | H11: 0
A12: 1.1.02 | C12: CONTAS A RECEBER | D12: 614312.11 | E12: 526674.34 | F12: 366708.72 | H12: 774277.73
A13: 1.1.02.01 | C13: CLIENTES NACIONAIS | D13: 614312.11 | E13: 526674.34 | F13: 366708.72 | H13: 774277.73
A14: 1.1.02.01.0001 | B14: 43 | C14: Clientes Nacionais | D14: 399021.56 | E14: 526674.34 | F14: 366708.72 | H14: 558987.18
A15: 1.1.02.01.0002 | B15: 5347 | C15: Clientes B2B | D15: 215290.55 | E15: 0 | F15: 0 | H15: 215290.55
A16: 1.1.03 | C16: OUTROS CRÉDITOS | D16: 347954.71 | E16: 48831.97 | F16: 156526.52 | H16: 240260.16
A17: 1.1.03.01 | C17: CRÉDITOS DE FUNCIONÁRIOS | D17: 3218.9 | E17: 18863.81 | F17: 21169.83 | H17: 912.88
A18: 1.1.03.01.0002 | B18: 60 | C18: Adiantamento de Férias | D18: 3218.9 | E18: 0 | F18: 2306.02 | H18: 912.88
A19: 1.1.03.01.0003 | B19: 3263 | C19: Adiantamento de Salários | D19: 0 | E19: 18863.81 | F19: 18863.81 | H19: 0
A20: 1.1.03.02 | C20: ADIANTAMENTO A FORNECEDORES | D20: 147010.2 | E20: 0 | F20: 0 | H20: 147010.2
A21: 1.1.03.02.0001 | B21: 3220 | C21: Adiantamento a Fornecedores | D21: 147010.2 | E21: 0 | F21: 0 | H21: 147010.2
A22: 1.1.03.03 | C22: OUTROS CREDITOS A RECEBER | D22: 126211.51 | E22: 0 | F22: 105390.96 | H22: 20820.55
A23: 1.1.03.03.0001 | B23: 5789 | C23: Outros Creditos a Receber | D23: 126211.51 | E23: 0 | F23: 105390.96 | H23: 20820.55
A24: 1.1.03.05 | C24: IMPOSTOS A RECUPERAR | D24: 7421 | E24: 29968.16 | F24: 29965.73 | H24: 7423.43
A25: 1.1.03.05.0001 | B25: 94 | C25: COFINS a Recuperar | D25: 0 | E25: 1087.11 | F25: 1085.36 | H25: 1.75
A26: 1.1.03.05.0003 | B26: 116 | C26: ICMS a Recuperar | D26: 300.12 | E26: 28644.73 | F26: 28644.73 | H26: 300.12
A27: 1.1.03.05.0007 | B27: 159 | C27: PIS a Recuperar | D27: 0 | E27: 236.32 | F27: 235.64 | H27: 0.68
A28: 1.1.03.05.0008 | B28: 5274 | C28: ICMS Difal a Recuperar | D28: 7120.88 | E28: 0 | F28: 0 | H28: 7120.88
A29: 1.1.03.06 | C29: TRIBUTOS A COMPENSAR | D29: 64093.1 | E29: 0 | F29: 0 | H29: 64093.1
A30: 1.1.03.06.0003 | B30: 4502 | C30: Saldo Negativo IRPJ | D30: 13.87 | E30: 0 | F30: 0 | H30: 13.87
A31: 1.1.03.06.0004 | B31: 4510 | C31: CSLL a Compensar | D31: 34627.34 | E31: 0 | F31: 0 | H31: 34627.34
A32: 1.1.03.06.0007 | B32: 4545 | C32: IRRF Aplicação | D32: 16.21 | E32: 0 | F32: 0 | H32: 16.21
A33: 1.1.03.06.0009 | B33: 4561 | C33: IRPJ a Compensar | D33: 29435.68 | E33: 0 | F33: 0 | H33: 29435.68
A34: 1.1.06 | C34: ESTOQUES | D34: 817929 | E34: 97826.59 | F34: 86917.88 | H34: 828837.71
A35: 1.1.06.01 | C35: ESTOQUES PARA REVENDA | D35: 817929 | E35: 97826.59 | F35: 86917.88 | H35: 828837.71
A36: 1.1.06.01.0001 | B36: 175 | C36: Mercadorias para Revenda | D36: 817929 | E36: 97826.59 | F36: 86917.88 | H36: 828837.71
A37: 1.2 | C37: ATIVO NÃO CIRCULANTE | D37: 3141326.7 | E37: 0 | F37: 6083.86 | H37: 3135242.9
A38: 1.2.01 | C38: ATIVO REALIZÁVEL A LONGO PRAZO | D38: 3022149 | E38: 0 | F38: 0 | H38: 3022149
A39: 1.2.01.05 | C39: CRÉDITOS A SÓCIOS | D39: 3022149 | E39: 0 | F39: 0 | H39: 3022149
A40: 1.2.01.05.0001 | B40: 3336 | C40: Mutuo Sócios | D40: 1224589.3 | E40: 0 | F40: 0 | H40: 1224589.3
...

Sheet 03.2026
A1: Conta contábil | B1: Conta contábil | C1: Descrição da Conta | D1: Saldo anterior | E1: Débito | F1: Crédito | H1: Saldo Atual
A2: 1 | C2: ATIVO | D2: 4984962.5 | E2: 3771495.7 | F2: 3554120.9 | H2: 5202337.4
A3: 1.1 | C3: ATIVO CIRCULANTE | D3: 1849719.7 | E3: 2852940.9 | F3: 2629482.2 | H3: 2073178.4
A4: 1.1.01 | C4: DISPONÍVEL | D4: 6344.09 | E4: 1400595.6 | F4: 1404893 | H4: 2046.69
A5: 1.1.01.01 | C5: CAIXA | D5: 0 | E5: 108600 | F5: 108600 | H5: 0
A6: 1.1.01.01.0010 | B6: 5 | C6: Entre Contas | D6: 0 | E6: 108600 | F6: 108600 | H6: 0
A7: 1.1.01.02 | C7: BANCOS CONTA MOVIMENTO | D7: 6344.09 | E7: 1291995.6 | F7: 1296293 | H7: 2046.69
A8: 1.1.01.02.0001 | B8: 27 | C8: Banco Itaú | D8: 0 | E8: 1167251.9 | F8: 1167251.9 | H8: 0
A9: 1.1.01.02.0002 | B9: 576 | C9: Banco Pag Útil | D9: 848.74 | E9: 16200 | F9: 16962.5 | H9: 86.24
A10: 1.1.01.02.0101 | B10: 5444 | C10: Mercado Pago - Banco Digital | D10: 5495.35 | E10: 853.39 | F10: 5400 | H10: 948.74
A11: 1.1.01.02.0102 | B11: 5860 | C11: Banco Bradesco | D11: 0 | E11: 107690.35 | F11: 106678.64 | H11: 1011.71
A12: 1.1.02 | C12: CONTAS A RECEBER | D12: 774277.73 | E12: 884558.89 | F12: 951206 | H12: 707630.62
A13: 1.1.02.01 | C13: CLIENTES NACIONAIS | D13: 774277.73 | E13: 884558.89 | F13: 951206 | H13: 707630.62
A14: 1.1.02.01.0001 | B14: 43 | C14: Clientes Nacionais | D14: 558987.18 | E14: 884558.89 | F14: 951206 | H14: 492340.07
A15: 1.1.02.01.0002 | B15: 5347 | C15: Clientes B2B | D15: 215290.55 | E15: 0 | F15: 0 | H15: 215290.55
A16: 1.1.03 | C16: OUTROS CRÉDITOS | D16: 240260.16 | E16: 81198.76 | F16: 82070.68 | H16: 239388.24
A17: 1.1.03.01 | C17: CRÉDITOS DE FUNCIONÁRIOS | D17: 912.88 | E17: 16675.31 | F17: 17588.19 | H17: 0
A18: 1.1.03.01.0002 | B18: 60 | C18: Adiantamento de Férias | D18: 912.88 | E18: 0 | F18: 912.88 | H18: 0
A19: 1.1.03.01.0003 | B19: 3263 | C19: Adiantamento de Salários | D19: 0 | E19: 16675.31 | F19: 16675.31 | H19: 0
A20: 1.1.03.02 | C20: ADIANTAMENTO A FORNECEDORES | D20: 147010.2 | E20: 0 | F20: 0 | H20: 147010.2
A21: 1.1.03.02.0001 | B21: 3220 | C21: Adiantamento a Fornecedores | D21: 147010.2 | E21: 0 | F21: 0 | H21: 147010.2
A22: 1.1.03.03 | C22: OUTROS CREDITOS A RECEBER | D22: 20820.55 | E22: 0 | F22: 0 | H22: 20820.55
A23: 1.1.03.03.0001 | B23: 5789 | C23: Outros Creditos a Receber | D23: 20820.55 | E23: 0 | F23: 0 | H23: 20820.55
A24: 1.1.03.05 | C24: IMPOSTOS A RECUPERAR | D24: 7423.43 | E24: 64523.45 | F24: 64482.49 | H24: 7464.39
A25: 1.1.03.05.0001 | B25: 94 | C25: COFINS a Recuperar | D25: 1.75 | E25: 1521.73 | F25: 1523.48 | H25: 0
A26: 1.1.03.05.0003 | B26: 116 | C26: ICMS a Recuperar | D26: 300.12 | E26: 62671.65 | F26: 62628.26 | H26: 343.51
A27: 1.1.03.05.0007 | B27: 159 | C27: PIS a Recuperar | D27: 0.68 | E27: 330.07 | F27: 330.75 | H27: 0
A28: 1.1.03.05.0008 | B28: 5274 | C28: ICMS Difal a Recuperar | D28: 7120.88 | E28: 0 | F28: 0 | H28: 7120.88
A29: 1.1.03.06 | C29: TRIBUTOS A COMPENSAR | D29: 64093.1 | E29: 0 | F29: 0 | H29: 64093.1
A30: 1.1.03.06.0003 | B30: 4502 | C30: Saldo Negativo IRPJ | D30: 13.87 | E30: 0 | F30: 0 | H30: 13.87
A31: 1.1.03.06.0004 | B31: 4510 | C31: CSLL a Compensar | D31: 34627.34 | E31: 0 | F31: 0 | H31: 34627.34
A32: 1.1.03.06.0007 | B32: 4545 | C32: IRRF Aplicação | D32: 16.21 | E32: 0 | F32: 0 | H32: 16.21
A33: 1.1.03.06.0009 | B33: 4561 | C33: IRPJ a Compensar | D33: 29435.68 | E33: 0 | F33: 0 | H33: 29435.68
A34: 1.1.06 | C34: ESTOQUES | D34: 828837.71 | E34: 486587.57 | F34: 191312.45 | H34: 1124112.8
A35: 1.1.06.01 | C35: ESTOQUES PARA REVENDA | D35: 828837.71 | E35: 486587.57 | F35: 191312.45 | H35: 1124112.8
A36: 1.1.06.01.0001 | B36: 175 | C36: Mercadorias para Revenda | D36: 828837.71 | E36: 486587.57 | F36: 191312.45 | H36: 1124112.8 | I36: atualizado
A37: 1.2 | C37: ATIVO NÃO CIRCULANTE | D37: 3135242.9 | E37: 0 | F37: 6083.86 | H37: 3129159
A38: 1.2.01 | C38: ATIVO REALIZÁVEL A LONGO PRAZO | D38: 3022149 | E38: 0 | F38: 0 | H38: 3022149
A39: 1.2.01.05 | C39: CRÉDITOS A SÓCIOS | D39: 3022149 | E39: 0 | F39: 0 | H39: 3022149
A40: 1.2.01.05.0001 | B40: 3336 | C40: Mutuo Sócios | D40: 1224589.3 | E40: 0 | F40: 0 | H40: 1224589.3
...

Sheet 04.2026
A1: Conta contábil | B1: Código Reduzido | C1: Descrição da Conta | D1: Saldo anterior | E1: Débito | F1: Crédito | H1: Saldo Atual
A2: 1 | C2: ATIVO | D2: 5202337.4 | E2: 1730488.8 | F2: 1718123.6 | H2: 5214702.5
A3: 1.1 | C3: ATIVO CIRCULANTE | D3: 2073178.4 | E3: 1730488.8 | F3: 1712039.8 | H3: 2091627.3
A4: 1.1.01 | C4: DISPONÍVEL | D4: 2046.69 | E4: 939671.15 | F4: 923363.77 | H4: 18354.07
A5: 1.1.01.01 | C5: CAIXA | D5: 0 | E5: 55000 | F5: 55000 | H5: 0
A6: 1.1.01.01.0010 | B6: 5 | C6: Entre Contas | D6: 0 | E6: 55000 | F6: 55000 | H6: 0
A7: 1.1.01.02 | C7: BANCOS CONTA MOVIMENTO | D7: 2046.69 | E7: 817509.01 | F7: 816270.4 | H7: 3285.3
A8: 1.1.01.02.0001 | B8: 27 | C8: Banco Itaú | D8: 0 | E8: 720738.15 | F8: 720738.15 | H8: 0
A9: 1.1.01.02.0002 | B9: 576 | C9: Banco Pag Útil | D9: 86.24 | E9: 55000 | F9: 53878.04 | H9: 1208.2
A10: 1.1.01.02.0101 | B10: 5444 | C10: Mercado Pago - Banco Digital | D10: 948.74 | E10: 1127.36 | F10: 0 | H10: 2076.1
A11: 1.1.01.02.0102 | B11: 5860 | C11: Banco Bradesco | D11: 1011.71 | E11: 40643.5 | F11: 41654.21 | H11: 1
A12: 1.1.01.03 | C12: APLICAÇÕES FINANCEIRAS | D12: 0 | E12: 67162.14 | F12: 52093.37 | H12: 15068.77
A13: 1.1.01.03.0001 | B13: 35 | C13: Aplicações Banco Itaú | D13: 0 | E13: 52093.37 | F13: 52093.37 | H13: 0 | J13: 0
A14: 1.1.01.03.0002 | B14: 5878 | C14: Aplicações Brando Bradesco | D14: 0 | E14: 15068.77 | F14: 0 | H14: 15068.77
A15: 1.1.02 | C15: CONTAS A RECEBER | D15: 707630.62 | E15: 617787.79 | F15: 655343.63 | H15: 670074.78
A16: 1.1.02.01 | C16: CLIENTES NACIONAIS | D16: 707630.62 | E16: 617787.79 | F16: 655343.63 | H16: 670074.78
A17: 1.1.02.01.0001 | B17: 43 | C17: Clientes Nacionais | D17: 492340.07 | E17: 617787.79 | F17: 614418.01 | H17: 495709.85
A18: 1.1.02.01.0002 | B18: 5347 | C18: Clientes B2B | D18: 215290.55 | E18: 0 | F18: 40925.62 | H18: 174364.93
A19: 1.1.03 | C19: OUTROS CRÉDITOS | D19: 239388.24 | E19: 37771.95 | F19: 35830.03 | H19: 241330.16
A20: 1.1.03.01 | C20: CRÉDITOS DE FUNCIONÁRIOS | D20: 0 | E20: 17071.93 | F20: 15130.01 | H20: 1941.92
A21: 1.1.03.01.0002 | B21: 60 | C21: Adiantamento de Férias | D21: 0 | E21: 1941.92 | F21: 0 | H21: 1941.92
A22: 1.1.03.01.0003 | B22: 3263 | C22: Adiantamento de Salários | D22: 0 | E22: 15130.01 | F22: 15130.01 | H22: 0
A23: 1.1.03.02 | C23: ADIANTAMENTO A FORNECEDORES | D23: 147010.2 | E23: 0 | F23: 0 | H23: 147010.2
A24: 1.1.03.02.0001 | B24: 3220 | C24: Adiantamento a Fornecedores | D24: 147010.2 | E24: 0 | F24: 0 | H24: 147010.2
A25: 1.1.03.03 | C25: OUTROS CREDITOS A RECEBER | D25: 20820.55 | E25: 0 | F25: 0 | H25: 20820.55
A26: 1.1.03.03.0001 | B26: 5789 | C26: Outros Creditos a Receber | D26: 20820.55 | E26: 0 | F26: 0 | H26: 20820.55
A27: 1.1.03.05 | C27: IMPOSTOS A RECUPERAR | D27: 7464.39 | E27: 20700.02 | F27: 20700.02 | H27: 7464.39
A28: 1.1.03.05.0001 | B28: 94 | C28: COFINS a Recuperar | D28: 0 | E28: 108.49 | F28: 108.49 | H28: 0
A29: 1.1.03.05.0003 | B29: 116 | C29: ICMS a Recuperar | D29: 343.51 | E29: 20567.98 | F29: 20567.98 | H29: 343.51
A30: 1.1.03.05.0007 | B30: 159 | C30: PIS a Recuperar | D30: 0 | E30: 23.55 | F30: 23.55 | H30: 0
A31: 1.1.03.05.0008 | B31: 5274 | C31: ICMS Difal a Recuperar | D31: 7120.88 | E31: 0 | F31: 0 | H31: 7120.88
A32: 1.1.03.06 | C32: TRIBUTOS A COMPENSAR | D32: 64093.1 | E32: 0 | F32: 0 | H32: 64093.1
A33: 1.1.03.06.0003 | B33: 4502 | C33: Saldo Negativo IRPJ | D33: 13.87 | E33: 0 | F33: 0 | H33: 13.87
A34: 1.1.03.06.0004 | B34: 4510 | C34: CSLL a Compensar | D34: 34627.34 | E34: 0 | F34: 0 | H34: 34627.34
A35: 1.1.03.06.0007 | B35: 4545 | C35: IRRF Aplicação | D35: 16.21 | E35: 0 | F35: 0 | H35: 16.21
A36: 1.1.03.06.0009 | B36: 4561 | C36: IRPJ a Compensar | D36: 29435.68 | E36: 0 | F36: 0 | H36: 29435.68
A37: 1.1.06 | C37: ESTOQUES | D37: 1124112.8 | E37: 135257.86 | F37: 97502.36 | H37: 1161868.3
A38: 1.1.06.01 | C38: ESTOQUES PARA REVENDA | D38: 1124112.8 | E38: 135257.86 | F38: 97502.36 | H38: 1161868.3
A39: 1.1.06.01.0001 | B39: 175 | C39: Mercadorias para Revenda | D39: 1124112.8 | E39: 135257.86 | F39: 97502.36 | H39: 1161868.3
A40: 1.2 | C40: ATIVO NÃO CIRCULANTE | D40: 3129159 | E40: 0 | F40: 6083.86 | H40: 3123075.1
...

Sheet ANÁLISE DE RESULTADO
A1: Conta Contábil | B1: C. Reduzido | C1: Descrição | D1: JANEIRO | E1: FEVEREIRO | F1: MARÇO | G1: ABRIL | K1: INDICADOR | L1: JANEIRO | M1: FEVEREIRO | N1: MARÇO | O1: ABRIL
A2: 3 | C2: RECEITAS | D2: =D3+D9+D16 -> 656359.67 | E2: =E3+E9+E16 -> 455561.03 | F2: =F3+F9+F16 -> 760260.76 | G2: =G3+G9+G16 -> 456584.58 | K2: RECEITA BRUTA | L2: =D3 -> 704049 | M2: =E3 -> 494905.82 | N2: =F3 -> 873714.52 | O2: =G3 -> 598893.85
A3: 3.1.01 | C3: RECEITAS BRUTAS | D3: =D4+D5+D7 -> 704049 | E3: =E4+E5+E7 -> 494905.82 | F3: =F4+F5+F7 -> 873714.52 | G3: =G4+G5+G7 -> 598893.85 | K3: (-) DEDUÇÕES | L3: =D5 -> -6163.13 | M3: =E5 -> -31768.52 | N3: =F5 -> -10496.15 | O3: =G5 -> -18893.94
A4: 3.1.01.01.0001 | B4: 922 | C4: Revendas de Mercadorias B2C | D4: =SUMIF('01.2026'!B:B,'ANÁLISE DE RESULTADO'!B4,'01.2026'!G:G) -> 651228.61 | E4: =SUMIF('02.2026'!B:B,'ANÁLISE DE RESULTADO'!B4,'02.2026'!G:G) -> 526674.34 | F4: =SUMIF('03.2026'!B:B,'ANÁLISE DE RESULTADO'!B4,'03.2026'!G:G) -> 884210.67 | G4: =SUMIF('04.2026'!B:B,'ANÁLISE DE RESULTADO'!B4,'04.2026'!G:G) -> 617787.79 | K4: (-) IMPOSTOS | L4: =D9 -> -47691.07 | M4: =E9 -> -39345.33 | N4: =F9 -> -113455.43 | O4: =G9 -> -142310.04
A5: 3.1.01.02 | C5: DEDUÇÕES DA RECEITA BRUTA | D5: =D6 -> -6163.13 | E5: =E6 -> -31768.52 | F5: =F6 -> -10496.15 | G5: =G6 -> -18893.94 | K5: "= RECEITA LÍQUIDA | L5: =SUM(L2:L4) -> 650194.8 | M5: =SUM(M2:M4) -> 423791.97 | N5: =SUM(N2:N4) -> 749762.94 | O5: =SUM(O2:O4) -> 437689.87
A6: 3.1.01.02.0004 | B6: 5363 | C6: (-) Devolução de Revenda | D6: =SUMIF('01.2026'!B:B,'ANÁLISE DE RESULTADO'!B6,'01.2026'!G:G) -> -6163.13 | E6: =SUMIF('02.2026'!B:B,'ANÁLISE DE RESULTADO'!B6,'02.2026'!G:G) -> -31768.52 | F6: =SUMIF('03.2026'!B:B,'ANÁLISE DE RESULTADO'!B6,'03.2026'!G:G) -> -10496.15 | G6: =SUMIF('04.2026'!B:B,'ANÁLISE DE RESULTADO'!B6,'04.2026'!G:G) -> -18893.94
A7: 3.1.01.03 | C7: RECEITA BRUTA REVENDA - B2B | D7: =D8 -> 58983.52 | E7: =E8 -> 0 | F7: =F8 -> 0 | G7: =G8 -> 0 | K7: (-) CMV | L7: =D19 -> -117500.55 | M7: =E19 -> -74422.81 | N7: =F19 -> -119524.39 | O7: =G19 -> -85461.46
A8: 3.1.01.03.0001 | B8: 5495 | C8: Revenda de mercadoria - B2B | D8: =SUMIF('01.2026'!B:B,'ANÁLISE DE RESULTADO'!B8,'01.2026'!G:G) -> 58983.52 | E8: =SUMIF('02.2026'!B:B,'ANÁLISE DE RESULTADO'!B8,'02.2026'!G:G) -> 0 | F8: =SUMIF('03.2026'!B:B,'ANÁLISE DE RESULTADO'!B8,'03.2026'!G:G) -> 0 | G8: =SUMIF('04.2026'!B:B,'ANÁLISE DE RESULTADO'!B8,'04.2026'!G:G) -> 0 | K8: = LUCRO BRUTO | L8: =L5+L7 -> 532694.25 | M8: =M5+M7 -> 349369.16 | N8: =N5+N7 -> 630238.55 | O8: =O5+O7 -> 352228.41
A9: 3.1.03 | C9: IMPOSTOS INCIDENTES | D9: =SUM(D10:D14) -> -47691.07 | E9: =SUM(E10:E14) -> -39345.33 | F9: =SUM(F10:F14) -> -113455.43 | G9: =SUM(G10:G14) -> -142310.04 | K9: "= MARGEM BRUTA % | L9: =L8/L5 -> 0.81928408 | M9: =M8/M5 -> 0.82438834 | N9: =N8/N5 -> 0.84058376 | O9: =O8/O5 -> 0.80474426
A10: 3.1.03.03.0001 | B10: 981 | C10: (-) COFINS sobre Revendas | D10: =SUMIF('01.2026'!B:B,'ANÁLISE DE RESULTADO'!B10,'01.2026'!G:G) -> -806.07 | E10: =SUMIF('02.2026'!B:B,'ANÁLISE DE RESULTADO'!B10,'02.2026'!G:G) -> -1085.36 | F10: =SUMIF('03.2026'!B:B,'ANÁLISE DE RESULTADO'!B10,'03.2026'!G:G) -> -2737.65 | G10: =SUMIF('04.2026'!B:B,'ANÁLISE DE RESULTADO'!B10,'04.2026'!G:G) -> -19917.76
A11: 3.1.03.03.0002 | B11: 4014 | C11: (-) PIS sobre Revendas | D11: =SUMIF('01.2026'!B:B,'ANÁLISE DE RESULTADO'!B11,'01.2026'!G:G) -> -175 | E11: =SUMIF('02.2026'!B:B,'ANÁLISE DE RESULTADO'!B11,'02.2026'!G:G) -> -235.64 | F11: =SUMIF('03.2026'!B:B,'ANÁLISE DE RESULTADO'!B11,'03.2026'!G:G) -> -594.37 | G11: =SUMIF('04.2026'!B:B,'ANÁLISE DE RESULTADO'!B11,'04.2026'!G:G) -> -4324.25 | K11: (-) PUBLICIDADE | L11: =D30 -> -275606.45 | M11: =E30 -> -263307.55 | N11: =F30 -> -251337.05 | O11: =G30 -> -292484.28
A12: 3.1.03.03.0003 | B12: 1007 | C12: (-) ICMS sobre Revendas | D12: =SUMIF('01.2026'!B:B,'ANÁLISE DE RESULTADO'!B12,'01.2026'!G:G) -> -57697.01 | E12: =SUMIF('02.2026'!B:B,'ANÁLISE DE RESULTADO'!B12,'02.2026'!G:G) -> -49411.16 | F12: =SUMIF('03.2026'!B:B,'ANÁLISE DE RESULTADO'!B12,'03.2026'!G:G) -> -126027.2 | G12: =SUMIF('04.2026'!B:B,'ANÁLISE DE RESULTADO'!B12,'04.2026'!G:G) -> -80254.67 | K12: (-) DESPESAS COM VENDAS | L12: =D33 -> -158230.31 | M12: =E33 -> -22960.64 | N12: =F33 -> -81358.96 | O12: =G33 -> -138776.03
A13: 3.1.03.03.0004 | B13: 4669 | C13: (-) ICMS Destino Difal s/ Vendas | D13: =SUMIF('01.2026'!B:B,'ANÁLISE DE RESULTADO'!B13,'01.2026'!G:G) -> 0 | E13: =SUMIF('02.2026'!B:B,'ANÁLISE DE RESULTADO'!B13,'02.2026'!G:G) -> 0 | F13: =SUMIF('03.2026'!B:B,'ANÁLISE DE RESULTADO'!B13,'03.2026'!G:G) -> 0 | G13: =SUMIF('04.2026'!B:B,'ANÁLISE DE RESULTADO'!B13,'04.2026'!G:G) -> -54840.9 | K13: "= MARGEM DE CONTRIBUIÇÃO | L13: =L8+L11+L12 -> 98857.49 | M13: =M8+M11+M12 -> 63100.97 | N13: =N8+N11+N12 -> 297542.54 | O13: =O8+O11+O12 -> -79031.9
A14: 3.1.03.03.0015 | B14: 5410 | C14: (-) ICMS Revenda Reg. Especial Cred. Pre | D14: =SUMIF('01.2026'!B:B,'ANÁLISE DE RESULTADO'!B14,'01.2026'!G:G) -> 10987.01 | E14: =SUMIF('02.2026'!B:B,'ANÁLISE DE RESULTADO'!B14,'02.2026'!G:G) -> 11386.83 | F14: =SUMIF('03.2026'!B:B,'ANÁLISE DE RESULTADO'!B14,'03.2026'!G:G) -> 15903.79 | G14: =SUMIF('04.2026'!B:B,'ANÁLISE DE RESULTADO'!B14,'04.2026'!G:G) -> 17027.54 | K14: "= MARGEM CONTRIBUIÇÃO % | L14: =L13/L5 -> 0.15204288 | M14: =M13/M5 -> 0.1488961 | N14: =N13/N5 -> 0.39684882 | O14: =O13/O5 -> -0.18056598
C15: RECEITA LÍQUIDA | D15: =D3+D5+D9 -> 650194.8 | E15: =E3+E5+E9 -> 423791.97 | F15: =F3+F5+F9 -> 749762.94 | G15: =G3+G5+G9 -> 437689.87
A16: 3.2 | C16: OUTRAS RECEITAS OPERACIONAIS | D16: =D17 -> 1.74 | E16: =E17 -> 0.54 | F16: =F17 -> 1.67 | G16: =G17 -> 0.77 | K16: (-) DESPESAS OPERACIONAIS | L16: =D29 -> -876623.77 | M16: =E29 -> -670007.4 | N16: =F29 -> -695571.64 | O16: =G29 -> -720020.31
A17: 3.2.01.01.0001 | B17: 3603 | C17: Rendimento de Aplicações Financeiras | D17: =SUMIF('01.2026'!B:B,'ANÁLISE DE RESULTADO'!B17,'01.2026'!G:G) -> 1.74 | E17: =SUMIF('02.2026'!B:B,'ANÁLISE DE RESULTADO'!B17,'02.2026'!G:G) -> 0.54 | F17: =SUMIF('03.2026'!B:B,'ANÁLISE DE RESULTADO'!B17,'03.2026'!G:G) -> 1.67 | G17: =SUMIF('04.2026'!B:B,'ANÁLISE DE RESULTADO'!B17,'04.2026'!G:G) -> 0.77 | K17: "= RESULTADO OPERACIONAL | L17: =D50 -> -343929.52 | M17: =E50 -> -320638.24 | N17: =F50 -> -65333.09 | O17: =G50 -> -367791.9
A18: 4 | C18: CUSTO E DESPESAS | D18: =D19+D25+D29 -> -1009002.7 | E18: =E19+E25+E29 -> -744627.06 | F18: =F19+F25+F29 -> -815096.03 | G18: =G19+G25+G29 -> -805481.77 | K18: "= MARGEM OPERACIONAL % | L18: =D51 -> -0.52896381 | M18: =E51 -> -0.75659348 | N18: =F51 -> -0.087138329 | O18: =G51 -> -0.84030252
A19: 4.2 | C19: CUSTO DE MERCADORIAS REVENDIDAS | D19: =SUM(D20:D24) -> -117500.55 | E19: =SUM(E20:E24) -> -74422.81 | F19: =SUM(F20:F24) -> -119524.39 | G19: =SUM(G20:G24) -> -85461.46
A20: 4.2.01.01.0001 | B20: 1120 | C20: (+) Estoque Inicial | D20: =SUMIF('01.2026'!B:B,'ANÁLISE DE RESULTADO'!B20,'01.2026'!G:G) -> 953107.73 | E20: =SUMIF('02.2026'!B:B,'ANÁLISE DE RESULTADO'!B20,'02.2026'!G:G) -> 0 | F20: =SUMIF('03.2026'!B:B,'ANÁLISE DE RESULTADO'!B20,'03.2026'!G:G) -> 0 | G20: =SUMIF('04.2026'!B:B,'ANÁLISE DE RESULTADO'!B20,'04.2026'!G:G) -> 0 | K20: (+) DEPRECIAÇÃO / AMORTIZAÇÃO | L20: =D70 -> -6083.86 | M20: =E70 -> -6083.86 | N20: =F70 -> -6083.86 | O20: =G70 -> -6083.86
A21: 4.2.01.01.0002 | B21: 1112 | C21: (+) Compra Mercadorias Brutas | D21: =SUMIF('01.2026'!B:B,'ANÁLISE DE RESULTADO'!B21,'01.2026'!G:G) -> 0 | E21: =SUMIF('02.2026'!B:B,'ANÁLISE DE RESULTADO'!B21,'02.2026'!G:G) -> -25573.5 | F21: =SUMIF('03.2026'!B:B,'ANÁLISE DE RESULTADO'!B21,'03.2026'!G:G) -> -9720 | G21: =SUMIF('04.2026'!B:B,'ANÁLISE DE RESULTADO'!B21,'04.2026'!G:G) -> -12000 | K21: "= EBITDA | L21: =L17-L20 -> -337845.66 | M21: =M17-M20 -> -314554.38 | N21: =N17-N20 -> -59249.23 | O21: =O17-O20 -> -361708.04
A22: 4.2.01.01.0009 | B22: 3034 | C22: (-) Devolução de Compras | D22: =SUMIF('01.2026'!B:B,'ANÁLISE DE RESULTADO'!B22,'01.2026'!G:G) -> 0 | E22: =SUMIF('02.2026'!B:B,'ANÁLISE DE RESULTADO'!B22,'02.2026'!G:G) -> 19240.6 | F22: =SUMIF('03.2026'!B:B,'ANÁLISE DE RESULTADO'!B22,'03.2026'!G:G) -> 0 | G22: =SUMIF('04.2026'!B:B,'ANÁLISE DE RESULTADO'!B22,'04.2026'!G:G) -> 1394.97 | K22: "= MARGEM EBITDA % | L22: =L21/L5 -> -0.51960683 | M22: =M21/M5 -> -0.74223771 | N22: =N21/N5 -> -0.079023951 | O22: =O21/O5 -> -0.82640259
A23: 4.2.01.01.0010 | B23: 1066 | C23: (-) Estoque Final | D23: =SUMIF('01.2026'!B:B,'ANÁLISE DE RESULTADO'!B23,'01.2026'!G:G) -> -1081516.5 | E23: =SUMIF('02.2026'!B:B,'ANÁLISE DE RESULTADO'!B23,'02.2026'!G:G) -> 0 | F23: =SUMIF('03.2026'!B:B,'ANÁLISE DE RESULTADO'!B23,'03.2026'!G:G) -> 0 | G23: =SUMIF('04.2026'!B:B,'ANÁLISE DE RESULTADO'!B23,'04.2026'!G:G) -> 0
A24: 4.2.01.01.0011 | B24: 4847 | C24: CMV | D24: =SUMIF('01.2026'!B:B,'ANÁLISE DE RESULTADO'!B24,'01.2026'!G:G) -> 10908.2 | E24: =SUMIF('02.2026'!B:B,'ANÁLISE DE RESULTADO'!B24,'02.2026'!G:G) -> -68089.91 | F24: =SUMIF('03.2026'!B:B,'ANÁLISE DE RESULTADO'!B24,'03.2026'!G:G) -> -109804.39 | G24: =SUMIF('04.2026'!B:B,'ANÁLISE DE RESULTADO'!B24,'04.2026'!G:G) -> -74856.43
A25: 4.2.01.02 | C25: CUSTO - B2B | D25: =D26 -> -14878.36 | E25: =E26 -> -196.85 | F25: =F26 -> 0 | G25: =G26 -> 0
A26: 4.2.01.02.0001 | B26: 5738 | C26: CMV - B2B | D26: =SUMIF('01.2026'!B:B,'ANÁLISE DE RESULTADO'!B26,'01.2026'!G:G) -> -14878.36 | E26: =SUMIF('02.2026'!B:B,'ANÁLISE DE RESULTADO'!B26,'02.2026'!G:G) -> -196.85 | F26: =SUMIF('03.2026'!B:B,'ANÁLISE DE RESULTADO'!B26,'03.2026'!G:G) -> 0 | G26: =SUMIF('04.2026'!B:B,'ANÁLISE DE RESULTADO'!B26,'04.2026'!G:G) -> 0
C27: LUCRO BRUTO | D27: =D15+D19 -> 532694.25 | E27: =E15+E19 -> 349369.16 | F27: =F15+F19 -> 630238.55 | G27: =G15+G19 -> 352228.41
C28: MARGEM OPERACIONAL BRUTA | D28: =D27/D15 -> 0.81928408 | E28: =E27/E15 -> 0.82438834 | F28: =F27/F15 -> 0.84058376 | G28: =G27/G15 -> 0.80474426
A29: 4.3 | C29: DESPESAS OPERACIONAIS | D29: =D30+D33+D39+D52+D77+D82+D70 -> -876623.77 | E29: =E30+E33+E39+E52+E77+E82+E70 -> -670007.4 | F29: =F30+F33+F39+F52+F77+F82+F70 -> -695571.64 | G29: =G30+G33+G39+G52+G77+G82+G70 -> -720020.31
A30: 4.3.01.01 | C30: DESPESAS COM PUBLICIDADE | D30: =SUM(D31:D32) -> -275606.45 | E30: =SUM(E31:E32) -> -263307.55 | F30: =SUM(F31:F32) -> -251337.05 | G30: =SUM(G31:G32) -> -292484.28
A31: 4.3.01.01.0010 | B31: 4057 | C31: Propaganda e Publicidade Online | D31: =SUMIF('01.2026'!B:B,'ANÁLISE DE RESULTADO'!B31,'01.2026'!G:G) -> -275606.45 | E31: =SUMIF('02.2026'!B:B,'ANÁLISE DE RESULTADO'!B31,'02.2026'!G:G) -> -199538.88 | F31: =SUMIF('03.2026'!B:B,'ANÁLISE DE RESULTADO'!B31,'03.2026'!G:G) -> -251337.05 | G31: =SUMIF('04.2026'!B:B,'ANÁLISE DE RESULTADO'!B31,'04.2026'!G:G) -> -292484.28
A32: 4.3.01.02.0010 | B32: 5665 | C32: Propaganda e Publicidade - B2B | D32: =SUMIF('01.2026'!B:B,'ANÁLISE DE RESULTADO'!B32,'01.2026'!G:G) -> 0 | E32: =SUMIF('02.2026'!B:B,'ANÁLISE DE RESULTADO'!B32,'02.2026'!G:G) -> -63768.67 | F32: =SUMIF('03.2026'!B:B,'ANÁLISE DE RESULTADO'!B32,'03.2026'!G:G) -> 0 | G32: =SUMIF('04.2026'!B:B,'ANÁLISE DE RESULTADO'!B32,'04.2026'!G:G) -> 0
A33: 4.3.01.03 | C33: DESPESAS COM VENDAS | D33: =SUM(D34:D36) -> -158230.31 | E33: =SUM(E34:E36) -> -22960.64 | F33: =SUM(F34:F36) -> -81358.96 | G33: =SUM(G34:G36) -> -138776.03
A34: 4.3.01.03.0001 | B34: 1090 | C34: Fretes e Carretos | D34: =SUMIF('01.2026'!B:B,'ANÁLISE DE RESULTADO'!B34,'01.2026'!G:G) -> -51658.84 | E34: =SUMIF('02.2026'!B:B,'ANÁLISE DE RESULTADO'!B34,'02.2026'!G:G) -> -22551.33 | F34: =SUMIF('03.2026'!B:B,'ANÁLISE DE RESULTADO'!B34,'03.2026'!G:G) -> -42848.64 | G34: =SUMIF('04.2026'!B:B,'ANÁLISE DE RESULTADO'!B34,'04.2026'!G:G) -> -60778.34
A35: 4.3.01.03.0002 | B35: 4049 | C35: Comissões sobre Vendas - PJ | D35: =SUMIF('01.2026'!B:B,'ANÁLISE DE RESULTADO'!B35,'01.2026'!G:G) -> -65490.38 | E35: =SUMIF('02.2026'!B:B,'ANÁLISE DE RESULTADO'!B35,'02.2026'!G:G) -> 13648.26 | F35: =SUMIF('03.2026'!B:B,'ANÁLISE DE RESULTADO'!B35,'03.2026'!G:G) -> -20883.31 | G35: =SUMIF('04.2026'!B:B,'ANÁLISE DE RESULTADO'!B35,'04.2026'!G:G) -> -9597.5
A36: 4.3.01.03.0004 | B36: 4855 | C36: Armazenagem | D36: =SUMIF('01.2026'!B:B,'ANÁLISE DE RESULTADO'!B36,'01.2026'!G:G) -> -41081.09 | E36: =SUMIF('02.2026'!B:B,'ANÁLISE DE RESULTADO'!B36,'02.2026'!G:G) -> -14057.57 | F36: =SUMIF('03.2026'!B:B,'ANÁLISE DE RESULTADO'!B36,'03.2026'!G:G) -> -17627.01 | G36: =SUMIF('04.2026'!B:B,'ANÁLISE DE RESULTADO'!B36,'04.2026'!G:G) -> -68400.19
C37: MARGEM DE CONTRIBUIÇÃO | D37: =(D15+D19+D30+D33) -> 98857.49 | E37: =(E15+E19+E30+E33) -> 63100.97 | F37: =(F15+F19+F30+F33) -> 297542.54 | G37: =(G15+G19+G30+G33) -> -79031.9
C38: MARGEM DE CONTRIBUIÇÃO (%) | D38: =D37/D15 -> 0.15204288 | E38: =E37/E15 -> 0.1488961 | F38: =F37/F15 -> 0.39684882 | G38: =G37/G15 -> -0.18056598
A39: 4.3.02.01 | C39: DESPESAS COM PESSOAL | D39: =SUM(D40:D49) -> -129748.95 | E39: =SUM(E40:E49) -> -115799.86 | F39: =SUM(F40:F49) -> -74183.77 | G39: =SUM(G40:G49) -> -50316.84
A40: 4.3.02.01.0002 | B40: 1465 | C40: Aviso Prévio | D40: =SUMIF('01.2026'!B:B,'ANÁLISE DE RESULTADO'!B40,'01.2026'!G:G) -> 0 | E40: =SUMIF('02.2026'!B:B,'ANÁLISE DE RESULTADO'!B40,'02.2026'!G:G) -> -34669.89 | F40: =SUMIF('03.2026'!B:B,'ANÁLISE DE RESULTADO'!B40,'03.2026'!G:G) -> -1182.42 | G40: =SUMIF('04.2026'!B:B,'ANÁLISE DE RESULTADO'!B40,'04.2026'!G:G) -> -1916.23
...
