Workbook

Sheet Dashboard
B2: GE Beauty — B2B Box · Dashboard
B4: Lista de clientes: | D4: Magenta | I4: ← selecione o cliente para filtrar todo o dashboard
B6: RECEITA TOTAL (R$)
B7: =IF($D$4="Todos",SUM(Histórico!$O$4:$O$503),SUMIF(Histórico!$B$4:$B$503,$D$4,Histórico!$O$4:$O$503)) -> 74220
B8: Pedidos fechados | C8: =IFERROR(IF($D$4="Todos",SUMPRODUCT(IFERROR((Histórico!$F$4:$F$503<>"")/COUNTIFS(Histórico!$F$4:$F$503,Histórico!$F$4:$F$503),0)),SUMPRODUCT(IFERROR((Histórico!$F$4:$F$503<>"")/COUNTIFS(Histórico!$F$4:$F$503,Histórico!$F$4:$F$503,Histórico!$B$4:$B$503,$D$4),0))),0) -> 0 | E8: Margem gerada (R$) | F8: =SUMPRODUCT(IF($D$4="Todos",1,1*(Histórico!$B$4:$B$503=$D$4))*IF(ISNUMBER(Histórico!$M$4:$M$503),Histórico!$M$4:$M$503,0)*Histórico!$O$4:$O$503) -> 0
B9: SKUs distintos | C9: =IFERROR(IF($D$4="Todos",SUMPRODUCT(IFERROR((Histórico!$G$4:$G$503<>"")/COUNTIFS(Histórico!$G$4:$G$503,Histórico!$G$4:$G$503),0)),SUMPRODUCT(IFERROR((Histórico!$G$4:$G$503<>"")/COUNTIFS(Histórico!$G$4:$G$503,Histórico!$G$4:$G$503,Histórico!$B$4:$B$503,$D$4),0))),0) -> 0.5 | E9: Volume total (un.) | F9: =IF($D$4="Todos",SUM(Histórico!$I$4:$I$503),SUMIF(Histórico!$B$4:$B$503,$D$4,Histórico!$I$4:$I$503)) -> 4560
B10: Desc% médio pond. | C10: =IFERROR(IF($D$4="Todos",SUMPRODUCT(IF(ISNUMBER(Histórico!$L$4:$L$503),Histórico!$L$4:$L$503,0)*Histórico!$O$4:$O$503)/SUM(Histórico!$O$4:$O$503),SUMPRODUCT((Histórico!$B$4:$B$503=$D$4)*IF(ISNUMBER(Histórico!$L$4:$L$503),Histórico!$L$4:$L$503,0)*Histórico!$O$4:$O$503)/SUMIF(Histórico!$B$4:$B$503,$D$4,Histórico!$O$4:$O$503)),"") -> 0
B13: Mês | C13: Data | D13: Receita (R$)
B14: jan/26 | C14: 46023 | D14: =IF($D$4="Todos",SUMIF(Histórico!$N$4:$N$503,$C14,Histórico!$O$4:$O$503),SUMIFS(Histórico!$O$4:$O$503,Histórico!$N$4:$N$503,$C14,Histórico!$B$4:$B$503,$D$4)) -> 0
B15: fev/26 | C15: 46054 | D15: =IF($D$4="Todos",SUMIF(Histórico!$N$4:$N$503,$C15,Histórico!$O$4:$O$503),SUMIFS(Histórico!$O$4:$O$503,Histórico!$N$4:$N$503,$C15,Histórico!$B$4:$B$503,$D$4)) -> 0
B16: mar/26 | C16: 46082 | D16: =IF($D$4="Todos",SUMIF(Histórico!$N$4:$N$503,$C16,Histórico!$O$4:$O$503),SUMIFS(Histórico!$O$4:$O$503,Histórico!$N$4:$N$503,$C16,Histórico!$B$4:$B$503,$D$4)) -> 36240
B17: abr/26 | C17: 46113 | D17: =IF($D$4="Todos",SUMIF(Histórico!$N$4:$N$503,$C17,Histórico!$O$4:$O$503),SUMIFS(Histórico!$O$4:$O$503,Histórico!$N$4:$N$503,$C17,Histórico!$B$4:$B$503,$D$4)) -> 0
B18: mai/26 | C18: 46143 | D18: =IF($D$4="Todos",SUMIF(Histórico!$N$4:$N$503,$C18,Histórico!$O$4:$O$503),SUMIFS(Histórico!$O$4:$O$503,Histórico!$N$4:$N$503,$C18,Histórico!$B$4:$B$503,$D$4)) -> 37980
B19: jun/26 | C19: 46174 | D19: =IF($D$4="Todos",SUMIF(Histórico!$N$4:$N$503,$C19,Histórico!$O$4:$O$503),SUMIFS(Histórico!$O$4:$O$503,Histórico!$N$4:$N$503,$C19,Histórico!$B$4:$B$503,$D$4)) -> 0
B20: jul/26 | C20: 46204 | D20: =IF($D$4="Todos",SUMIF(Histórico!$N$4:$N$503,$C20,Histórico!$O$4:$O$503),SUMIFS(Histórico!$O$4:$O$503,Histórico!$N$4:$N$503,$C20,Histórico!$B$4:$B$503,$D$4)) -> 0
B21: ago/26 | C21: 46235 | D21: =IF($D$4="Todos",SUMIF(Histórico!$N$4:$N$503,$C21,Histórico!$O$4:$O$503),SUMIFS(Histórico!$O$4:$O$503,Histórico!$N$4:$N$503,$C21,Histórico!$B$4:$B$503,$D$4)) -> 0
B22: set/26 | C22: 46266 | D22: =IF($D$4="Todos",SUMIF(Histórico!$N$4:$N$503,$C22,Histórico!$O$4:$O$503),SUMIFS(Histórico!$O$4:$O$503,Histórico!$N$4:$N$503,$C22,Histórico!$B$4:$B$503,$D$4)) -> 0
B23: out/26 | C23: 46296 | D23: =IF($D$4="Todos",SUMIF(Histórico!$N$4:$N$503,$C23,Histórico!$O$4:$O$503),SUMIFS(Histórico!$O$4:$O$503,Histórico!$N$4:$N$503,$C23,Histórico!$B$4:$B$503,$D$4)) -> 0
B24: nov/26 | C24: 46327 | D24: =IF($D$4="Todos",SUMIF(Histórico!$N$4:$N$503,$C24,Histórico!$O$4:$O$503),SUMIFS(Histórico!$O$4:$O$503,Histórico!$N$4:$N$503,$C24,Histórico!$B$4:$B$503,$D$4)) -> 0
B25: dez/26 | C25: 46357 | D25: =IF($D$4="Todos",SUMIF(Histórico!$N$4:$N$503,$C25,Histórico!$O$4:$O$503),SUMIFS(Histórico!$O$4:$O$503,Histórico!$N$4:$N$503,$C25,Histórico!$B$4:$B$503,$D$4)) -> 0
B29: LEDGER — HISTÓRICO
B30: SKU | C30: Produto | D30: Qtd (geral) | E30: Min% (geral) | F30: Max% (geral) | G30: Qtd (cliente) | H30: Min% (cliente) | I30: Max% (cliente)
B31: GEB 008 | C31: =IFERROR(INDEX(COGS!$C$4:$C$20,MATCH($B31,COGS!$B$4:$B$20,0)),"?") -> Shampoo a Seco GE Beauty 150ml | D31: =COUNTIFS(Histórico!$G$4:$G$503,$B31) -> 3 | E31: =IFERROR(IF(D31=0,"—",_xludf.MINIFS(Histórico!$L$4:$L$503,Histórico!$G$4:$G$503,$B31)),"—") -> — | F31: =IFERROR(IF(D31=0,"—",_xludf.MAXIFS(Histórico!$L$4:$L$503,Histórico!$G$4:$G$503,$B31)),"—") -> — | G31: =COUNTIFS(Histórico!$G$4:$G$503,$B31,Histórico!$B$4:$B$503,$D$4) -> 0 | H31: =IFERROR(IF(G31=0,"—",_xludf.MINIFS(Histórico!$L$4:$L$503,Histórico!$G$4:$G$503,$B31,Histórico!$B$4:$B$503,$D$4)),"—") -> — | I31: =IFERROR(IF(G31=0,"—",_xludf.MAXIFS(Histórico!$L$4:$L$503,Histórico!$G$4:$G$503,$B31,Histórico!$B$4:$B$503,$D$4)),"—") -> —
B32: GEB 019 | C32: =IFERROR(INDEX(COGS!$C$4:$C$20,MATCH($B32,COGS!$B$4:$B$20,0)),"?") -> Booster Fortificante GE Beauty 15ml | D32: =COUNTIFS(Histórico!$G$4:$G$503,$B32) -> 1 | E32: =IFERROR(IF(D32=0,"—",_xludf.MINIFS(Histórico!$L$4:$L$503,Histórico!$G$4:$G$503,$B32)),"—") -> — | F32: =IFERROR(IF(D32=0,"—",_xludf.MAXIFS(Histórico!$L$4:$L$503,Histórico!$G$4:$G$503,$B32)),"—") -> — | G32: =COUNTIFS(Histórico!$G$4:$G$503,$B32,Histórico!$B$4:$B$503,$D$4) -> 0 | H32: =IFERROR(IF(G32=0,"—",_xludf.MINIFS(Histórico!$L$4:$L$503,Histórico!$G$4:$G$503,$B32,Histórico!$B$4:$B$503,$D$4)),"—") -> — | I32: =IFERROR(IF(G32=0,"—",_xludf.MAXIFS(Histórico!$L$4:$L$503,Histórico!$G$4:$G$503,$B32,Histórico!$B$4:$B$503,$D$4)),"—") -> —
B33: GEB 023 | C33: =IFERROR(INDEX(COGS!$C$4:$C$20,MATCH($B33,COGS!$B$4:$B$20,0)),"?") -> Booster Antioxidante GE Beauty 15ml | D33: =COUNTIFS(Histórico!$G$4:$G$503,$B33) -> 1 | E33: =IFERROR(IF(D33=0,"—",_xludf.MINIFS(Histórico!$L$4:$L$503,Histórico!$G$4:$G$503,$B33)),"—") -> — | F33: =IFERROR(IF(D33=0,"—",_xludf.MAXIFS(Histórico!$L$4:$L$503,Histórico!$G$4:$G$503,$B33)),"—") -> — | G33: =COUNTIFS(Histórico!$G$4:$G$503,$B33,Histórico!$B$4:$B$503,$D$4) -> 0 | H33: =IFERROR(IF(G33=0,"—",_xludf.MINIFS(Histórico!$L$4:$L$503,Histórico!$G$4:$G$503,$B33,Histórico!$B$4:$B$503,$D$4)),"—") -> — | I33: =IFERROR(IF(G33=0,"—",_xludf.MAXIFS(Histórico!$L$4:$L$503,Histórico!$G$4:$G$503,$B33,Histórico!$B$4:$B$503,$D$4)),"—") -> —
B34: GEB 020 | C34: =IFERROR(INDEX(COGS!$C$4:$C$20,MATCH($B34,COGS!$B$4:$B$20,0)),"?") -> Booster Hidratante GE Beauty 15ml | D34: =COUNTIFS(Histórico!$G$4:$G$503,$B34) -> 2 | E34: =IFERROR(IF(D34=0,"—",_xludf.MINIFS(Histórico!$L$4:$L$503,Histórico!$G$4:$G$503,$B34)),"—") -> — | F34: =IFERROR(IF(D34=0,"—",_xludf.MAXIFS(Histórico!$L$4:$L$503,Histórico!$G$4:$G$503,$B34)),"—") -> — | G34: =COUNTIFS(Histórico!$G$4:$G$503,$B34,Histórico!$B$4:$B$503,$D$4) -> 0 | H34: =IFERROR(IF(G34=0,"—",_xludf.MINIFS(Histórico!$L$4:$L$503,Histórico!$G$4:$G$503,$B34,Histórico!$B$4:$B$503,$D$4)),"—") -> — | I34: =IFERROR(IF(G34=0,"—",_xludf.MAXIFS(Histórico!$L$4:$L$503,Histórico!$G$4:$G$503,$B34,Histórico!$B$4:$B$503,$D$4)),"—") -> —
B35: GEB 003 | C35: =IFERROR(INDEX(COGS!$C$4:$C$20,MATCH($B35,COGS!$B$4:$B$20,0)),"?") -> Leave-in com proteção térmica GE Beauty 150ml | D35: =COUNTIFS(Histórico!$G$4:$G$503,$B35) -> 3 | E35: =IFERROR(IF(D35=0,"—",_xludf.MINIFS(Histórico!$L$4:$L$503,Histórico!$G$4:$G$503,$B35)),"—") -> — | F35: =IFERROR(IF(D35=0,"—",_xludf.MAXIFS(Histórico!$L$4:$L$503,Histórico!$G$4:$G$503,$B35)),"—") -> — | G35: =COUNTIFS(Histórico!$G$4:$G$503,$B35,Histórico!$B$4:$B$503,$D$4) -> 2 | H35: =IFERROR(IF(G35=0,"—",_xludf.MINIFS(Histórico!$L$4:$L$503,Histórico!$G$4:$G$503,$B35,Histórico!$B$4:$B$503,$D$4)),"—") -> — | I35: =IFERROR(IF(G35=0,"—",_xludf.MAXIFS(Histórico!$L$4:$L$503,Histórico!$G$4:$G$503,$B35,Histórico!$B$4:$B$503,$D$4)),"—") -> —
B36: GEB 002 | C36: =IFERROR(INDEX(COGS!$C$4:$C$20,MATCH($B36,COGS!$B$4:$B$20,0)),"?") -> Máscara Condicionadora GE Beauty 200ml | D36: =COUNTIFS(Histórico!$G$4:$G$503,$B36) -> 2 | E36: =IFERROR(IF(D36=0,"—",_xludf.MINIFS(Histórico!$L$4:$L$503,Histórico!$G$4:$G$503,$B36)),"—") -> — | F36: =IFERROR(IF(D36=0,"—",_xludf.MAXIFS(Histórico!$L$4:$L$503,Histórico!$G$4:$G$503,$B36)),"—") -> — | G36: =COUNTIFS(Histórico!$G$4:$G$503,$B36,Histórico!$B$4:$B$503,$D$4) -> 2 | H36: =IFERROR(IF(G36=0,"—",_xludf.MINIFS(Histórico!$L$4:$L$503,Histórico!$G$4:$G$503,$B36,Histórico!$B$4:$B$503,$D$4)),"—") -> — | I36: =IFERROR(IF(G36=0,"—",_xludf.MAXIFS(Histórico!$L$4:$L$503,Histórico!$G$4:$G$503,$B36,Histórico!$B$4:$B$503,$D$4)),"—") -> —
B37: GEB 013 | C37: =IFERROR(INDEX(COGS!$C$4:$C$20,MATCH($B37,COGS!$B$4:$B$20,0)),"?") -> Shampoo GE Beauty 60 ml | D37: =COUNTIFS(Histórico!$G$4:$G$503,$B37) -> 1 | E37: =IFERROR(IF(D37=0,"—",_xludf.MINIFS(Histórico!$L$4:$L$503,Histórico!$G$4:$G$503,$B37)),"—") -> — | F37: =IFERROR(IF(D37=0,"—",_xludf.MAXIFS(Histórico!$L$4:$L$503,Histórico!$G$4:$G$503,$B37)),"—") -> — | G37: =COUNTIFS(Histórico!$G$4:$G$503,$B37,Histórico!$B$4:$B$503,$D$4) -> 0 | H37: =IFERROR(IF(G37=0,"—",_xludf.MINIFS(Histórico!$L$4:$L$503,Histórico!$G$4:$G$503,$B37,Histórico!$B$4:$B$503,$D$4)),"—") -> — | I37: =IFERROR(IF(G37=0,"—",_xludf.MAXIFS(Histórico!$L$4:$L$503,Histórico!$G$4:$G$503,$B37,Histórico!$B$4:$B$503,$D$4)),"—") -> —
B38: GEB 010 | C38: =IFERROR(INDEX(COGS!$C$4:$C$20,MATCH($B38,COGS!$B$4:$B$20,0)),"?") -> Mascara Condicionadora GE Beauty 50ml | D38: =COUNTIFS(Histórico!$G$4:$G$503,$B38) -> 1 | E38: =IFERROR(IF(D38=0,"—",_xludf.MINIFS(Histórico!$L$4:$L$503,Histórico!$G$4:$G$503,$B38)),"—") -> — | F38: =IFERROR(IF(D38=0,"—",_xludf.MAXIFS(Histórico!$L$4:$L$503,Histórico!$G$4:$G$503,$B38)),"—") -> — | G38: =COUNTIFS(Histórico!$G$4:$G$503,$B38,Histórico!$B$4:$B$503,$D$4) -> 0 | H38: =IFERROR(IF(G38=0,"—",_xludf.MINIFS(Histórico!$L$4:$L$503,Histórico!$G$4:$G$503,$B38,Histórico!$B$4:$B$503,$D$4)),"—") -> — | I38: =IFERROR(IF(G38=0,"—",_xludf.MAXIFS(Histórico!$L$4:$L$503,Histórico!$G$4:$G$503,$B38,Histórico!$B$4:$B$503,$D$4)),"—") -> —
B39: GEB 021 | C39: =IFERROR(INDEX(COGS!$C$4:$C$20,MATCH($B39,COGS!$B$4:$B$20,0)),"?") -> Booster Definição GE Beauty 15ml | D39: =COUNTIFS(Histórico!$G$4:$G$503,$B39) -> 1 | E39: =IFERROR(IF(D39=0,"—",_xludf.MINIFS(Histórico!$L$4:$L$503,Histórico!$G$4:$G$503,$B39)),"—") -> — | F39: =IFERROR(IF(D39=0,"—",_xludf.MAXIFS(Histórico!$L$4:$L$503,Histórico!$G$4:$G$503,$B39)),"—") -> — | G39: =COUNTIFS(Histórico!$G$4:$G$503,$B39,Histórico!$B$4:$B$503,$D$4) -> 0 | H39: =IFERROR(IF(G39=0,"—",_xludf.MINIFS(Histórico!$L$4:$L$503,Histórico!$G$4:$G$503,$B39,Histórico!$B$4:$B$503,$D$4)),"—") -> — | I39: =IFERROR(IF(G39=0,"—",_xludf.MAXIFS(Histórico!$L$4:$L$503,Histórico!$G$4:$G$503,$B39,Histórico!$B$4:$B$503,$D$4)),"—") -> —
B40: GEB 022 | C40: =IFERROR(INDEX(COGS!$C$4:$C$20,MATCH($B40,COGS!$B$4:$B$20,0)),"?") -> Booster Antifrizz GE Beauty 15ml | D40: =COUNTIFS(Histórico!$G$4:$G$503,$B40) -> 1 | E40: =IFERROR(IF(D40=0,"—",_xludf.MINIFS(Histórico!$L$4:$L$503,Histórico!$G$4:$G$503,$B40)),"—") -> — | F40: =IFERROR(IF(D40=0,"—",_xludf.MAXIFS(Histórico!$L$4:$L$503,Histórico!$G$4:$G$503,$B40)),"—") -> — | G40: =COUNTIFS(Histórico!$G$4:$G$503,$B40,Histórico!$B$4:$B$503,$D$4) -> 0 | H40: =IFERROR(IF(G40=0,"—",_xludf.MINIFS(Histórico!$L$4:$L$503,Histórico!$G$4:$G$503,$B40,Histórico!$B$4:$B$503,$D$4)),"—") -> — | I40: =IFERROR(IF(G40=0,"—",_xludf.MAXIFS(Histórico!$L$4:$L$503,Histórico!$G$4:$G$503,$B40,Histórico!$B$4:$B$503,$D$4)),"—") -> —
B43: PROPOSTA EM CONSTRUÇÃO
B44: Operador: | C44: =$D$4 -> Magenta | F44: Data proposta: | I44: Prazo: | K44: dias
B46: SKU | C46: Produto | D46: Volume | E46: Preço unit. | F46: COGS ES | G46: Retail | H46: Desc% | I46: GM% | J46: Receita | K46: Margem | L46: Hist. min% (cliente) | M46: Hist. max% (cliente) | N46: Hist. min% (geral) | O46: Hist. max% (geral) | P46: Flag
B47: GEB 023 | C47: =IFERROR(INDEX(COGS!$C$4:$C$20,MATCH($B47,COGS!$B$4:$B$20,0)),"") -> Booster Antioxidante GE Beauty 15ml | D47: 3000 | E47: 24.65 | F47: =IFERROR(INDEX(COGS!$D$4:$D$20,MATCH($B47,COGS!$B$4:$B$20,0)),"") -> 0 | G47: =IFERROR(INDEX(COGS!$F$4:$F$20,MATCH($B47,COGS!$B$4:$B$20,0)),"") -> 75 | H47: =IF(OR($B47="",$E47="",$G47=""),"",(G47-E47)/G47) -> 0.67133333 | I47: =IF(OR($B47="",$E47="",$F47=""),"",(E47-F47)/E47) -> 1 | J47: =IF(OR($B47="",$D47="",$E47=""),"",D47*E47) -> 73950 | K47: =IF(OR($B47="",$D47="",$E47="",$F47=""),"",D47*(E47-F47)) -> 73950 | L47: =IFERROR(IF(COUNTIFS(Histórico!$G$4:$G$503,$B47,Histórico!$B$4:$B$503,$D$4)=0,"—",_xludf.MINIFS(Histórico!$L$4:$L$503,Histórico!$G$4:$G$503,$B47,Histórico!$B$4:$B$503,$D$4)),"—") -> — | M47: =IFERROR(IF(COUNTIFS(Histórico!$G$4:$G$503,$B47,Histórico!$B$4:$B$503,$D$4)=0,"—",_xludf.MAXIFS(Histórico!$L$4:$L$503,Histórico!$G$4:$G$503,$B47,Histórico!$B$4:$B$503,$D$4)),"—") -> — | N47: =IFERROR(IF(COUNTIFS(Histórico!$G$4:$G$503,$B47)=0,"—",_xludf.MINIFS(Histórico!$L$4:$L$503,Histórico!$G$4:$G$503,$B47)),"—") -> — | O47: =IFERROR(IF(COUNTIFS(Histórico!$G$4:$G$503,$B47)=0,"—",_xludf.MAXIFS(Histórico!$L$4:$L$503,Histórico!$G$4:$G$503,$B47)),"—") -> — | P47: =IF($B47="","",IF($H47="","",IF($L47="—","novo para cliente",IF($H47<$L47,"+ melhor que o histórico",IF($H47>$M47,"! acima do max histórico","~ no range histórico"))))) -> novo para cliente
B48: GEB 022 | C48: =IFERROR(INDEX(COGS!$C$4:$C$20,MATCH($B48,COGS!$B$4:$B$20,0)),"") -> Booster Antifrizz GE Beauty 15ml | D48: 2000 | E48: 22.7 | F48: =IFERROR(INDEX(COGS!$D$4:$D$20,MATCH($B48,COGS!$B$4:$B$20,0)),"") -> 9.24 | G48: =IFERROR(INDEX(COGS!$F$4:$F$20,MATCH($B48,COGS!$B$4:$B$20,0)),"") -> 79 | H48: =IF(OR($B48="",$E48="",$G48=""),"",(G48-E48)/G48) -> 0.71265823 | I48: =IF(OR($B48="",$E48="",$F48=""),"",(E48-F48)/E48) -> 0.59295154 | J48: =IF(OR($B48="",$D48="",$E48=""),"",D48*E48) -> 45400 | K48: =IF(OR($B48="",$D48="",$E48="",$F48=""),"",D48*(E48-F48)) -> 26920 | L48: =IFERROR(IF(COUNTIFS(Histórico!$G$4:$G$503,$B48,Histórico!$B$4:$B$503,$D$4)=0,"—",_xludf.MINIFS(Histórico!$L$4:$L$503,Histórico!$G$4:$G$503,$B48,Histórico!$B$4:$B$503,$D$4)),"—") -> — | M48: =IFERROR(IF(COUNTIFS(Histórico!$G$4:$G$503,$B48,Histórico!$B$4:$B$503,$D$4)=0,"—",_xludf.MAXIFS(Histórico!$L$4:$L$503,Histórico!$G$4:$G$503,$B48,Histórico!$B$4:$B$503,$D$4)),"—") -> — | N48: =IFERROR(IF(COUNTIFS(Histórico!$G$4:$G$503,$B48)=0,"—",_xludf.MINIFS(Histórico!$L$4:$L$503,Histórico!$G$4:$G$503,$B48)),"—") -> — | O48: =IFERROR(IF(COUNTIFS(Histórico!$G$4:$G$503,$B48)=0,"—",_xludf.MAXIFS(Histórico!$L$4:$L$503,Histórico!$G$4:$G$503,$B48)),"—") -> — | P48: =IF($B48="","",IF($H48="","",IF($L48="—","novo para cliente",IF($H48<$L48,"+ melhor que o histórico",IF($H48>$M48,"! acima do max histórico","~ no range histórico"))))) -> novo para cliente
B49: GEB 102 | C49: =IFERROR(INDEX(COGS!$C$4:$C$20,MATCH($B49,COGS!$B$4:$B$20,0)),"") -> Primer Liso Intacto GE Beauty 150ml | D49: 4000 | E49: 31 | F49: =IFERROR(INDEX(COGS!$D$4:$D$20,MATCH($B49,COGS!$B$4:$B$20,0)),"") -> 0 | G49: =IFERROR(INDEX(COGS!$F$4:$F$20,MATCH($B49,COGS!$B$4:$B$20,0)),"") -> 139 | H49: =IF(OR($B49="",$E49="",$G49=""),"",(G49-E49)/G49) -> 0.77697842 | I49: =IF(OR($B49="",$E49="",$F49=""),"",(E49-F49)/E49) -> 1 | J49: =IF(OR($B49="",$D49="",$E49=""),"",D49*E49) -> 124000 | K49: =IF(OR($B49="",$D49="",$E49="",$F49=""),"",D49*(E49-F49)) -> 124000 | L49: =IFERROR(IF(COUNTIFS(Histórico!$G$4:$G$503,$B49,Histórico!$B$4:$B$503,$D$4)=0,"—",_xludf.MINIFS(Histórico!$L$4:$L$503,Histórico!$G$4:$G$503,$B49,Histórico!$B$4:$B$503,$D$4)),"—") -> — | M49: =IFERROR(IF(COUNTIFS(Histórico!$G$4:$G$503,$B49,Histórico!$B$4:$B$503,$D$4)=0,"—",_xludf.MAXIFS(Histórico!$L$4:$L$503,Histórico!$G$4:$G$503,$B49,Histórico!$B$4:$B$503,$D$4)),"—") -> — | N49: =IFERROR(IF(COUNTIFS(Histórico!$G$4:$G$503,$B49)=0,"—",_xludf.MINIFS(Histórico!$L$4:$L$503,Histórico!$G$4:$G$503,$B49)),"—") -> — | O49: =IFERROR(IF(COUNTIFS(Histórico!$G$4:$G$503,$B49)=0,"—",_xludf.MAXIFS(Histórico!$L$4:$L$503,Histórico!$G$4:$G$503,$B49)),"—") -> — | P49: =IF($B49="","",IF($H49="","",IF($L49="—","novo para cliente",IF($H49<$L49,"+ melhor que o histórico",IF($H49>$M49,"! acima do max histórico","~ no range histórico"))))) -> novo para cliente
B50: GEB 024 | C50: =IFERROR(INDEX(COGS!$C$4:$C$20,MATCH($B50,COGS!$B$4:$B$20,0)),"") -> Body Hair Mist Melon Mood GE Beauty 200ml | D50: 5000 | E50: 28.5 | F50: =IFERROR(INDEX(COGS!$D$4:$D$20,MATCH($B50,COGS!$B$4:$B$20,0)),"") -> 20.68 | G50: =IFERROR(INDEX(COGS!$F$4:$F$20,MATCH($B50,COGS!$B$4:$B$20,0)),"") -> 129 | H50: =IF(OR($B50="",$E50="",$G50=""),"",(G50-E50)/G50) -> 0.77906977 | I50: =IF(OR($B50="",$E50="",$F50=""),"",(E50-F50)/E50) -> 0.27438596 | J50: =IF(OR($B50="",$D50="",$E50=""),"",D50*E50) -> 142500 | K50: =IF(OR($B50="",$D50="",$E50="",$F50=""),"",D50*(E50-F50)) -> 39100 | L50: =IFERROR(IF(COUNTIFS(Histórico!$G$4:$G$503,$B50,Histórico!$B$4:$B$503,$D$4)=0,"—",_xludf.MINIFS(Histórico!$L$4:$L$503,Histórico!$G$4:$G$503,$B50,Histórico!$B$4:$B$503,$D$4)),"—") -> — | M50: =IFERROR(IF(COUNTIFS(Histórico!$G$4:$G$503,$B50,Histórico!$B$4:$B$503,$D$4)=0,"—",_xludf.MAXIFS(Histórico!$L$4:$L$503,Histórico!$G$4:$G$503,$B50,Histórico!$B$4:$B$503,$D$4)),"—") -> — | N50: =IFERROR(IF(COUNTIFS(Histórico!$G$4:$G$503,$B50)=0,"—",_xludf.MINIFS(Histórico!$L$4:$L$503,Histórico!$G$4:$G$503,$B50)),"—") -> — | O50: =IFERROR(IF(COUNTIFS(Histórico!$G$4:$G$503,$B50)=0,"—",_xludf.MAXIFS(Histórico!$L$4:$L$503,Histórico!$G$4:$G$503,$B50)),"—") -> — | P50: =IF($B50="","",IF($H50="","",IF($L50="—","novo para cliente",IF($H50<$L50,"+ melhor que o histórico",IF($H50>$M50,"! acima do max histórico","~ no range histórico"))))) -> novo para cliente
B51: GEB 029 | C51: =IFERROR(INDEX(COGS!$C$4:$C$20,MATCH($B51,COGS!$B$4:$B$20,0)),"") -> Melon Mood Mini Body & Hair Mist | D51: 4000 | E51: 23.45 | F51: =IFERROR(INDEX(COGS!$D$4:$D$20,MATCH($B51,COGS!$B$4:$B$20,0)),"") -> 16.7 | G51: =IFERROR(INDEX(COGS!$F$4:$F$20,MATCH($B51,COGS!$B$4:$B$20,0)),"") -> 79 | H51: =IF(OR($B51="",$E51="",$G51=""),"",(G51-E51)/G51) -> 0.70316456 | I51: =IF(OR($B51="",$E51="",$F51=""),"",(E51-F51)/E51) -> 0.28784648 | J51: =IF(OR($B51="",$D51="",$E51=""),"",D51*E51) -> 93800 | K51: =IF(OR($B51="",$D51="",$E51="",$F51=""),"",D51*(E51-F51)) -> 27000 | L51: =IFERROR(IF(COUNTIFS(Histórico!$G$4:$G$503,$B51,Histórico!$B$4:$B$503,$D$4)=0,"—",_xludf.MINIFS(Histórico!$L$4:$L$503,Histórico!$G$4:$G$503,$B51,Histórico!$B$4:$B$503,$D$4)),"—") -> — | M51: =IFERROR(IF(COUNTIFS(Histórico!$G$4:$G$503,$B51,Histórico!$B$4:$B$503,$D$4)=0,"—",_xludf.MAXIFS(Histórico!$L$4:$L$503,Histórico!$G$4:$G$503,$B51,Histórico!$B$4:$B$503,$D$4)),"—") -> — | N51: =IFERROR(IF(COUNTIFS(Histórico!$G$4:$G$503,$B51)=0,"—",_xludf.MINIFS(Histórico!$L$4:$L$503,Histórico!$G$4:$G$503,$B51)),"—") -> — | O51: =IFERROR(IF(COUNTIFS(Histórico!$G$4:$G$503,$B51)=0,"—",_xludf.MAXIFS(Histórico!$L$4:$L$503,Histórico!$G$4:$G$503,$B51)),"—") -> — | P51: =IF($B51="","",IF($H51="","",IF($L51="—","novo para cliente",IF($H51<$L51,"+ melhor que o histórico",IF($H51>$M51,"! acima do max histórico","~ no range histórico"))))) -> novo para cliente
...

Sheet COGS
B2: GE Beauty — B2B · Base COGS
B3: SKU | C3: Produto | D3: COGS ES | E3: COGS SP | F3: Retail | G3: Fonte
B4: GEB 001 | C4: Shampoo sem sulfato GE Beauty 250ml | D4: 17.33 | E4: 18.52 | F4: 95 | G4: Shopify
B5: GEB 002 | C5: Máscara Condicionadora GE Beauty 200ml | D5: 10.64 | E5: 11.37 | F5: 95 | G5: Shopify
B6: GEB 003 | C6: Leave-in com proteção térmica GE Beauty 150ml | D6: 8.35 | E6: 8.72 | F6: 99 | G6: Shopify
B7: GEB 008 | C7: Shampoo a Seco GE Beauty 150ml | D7: 12.14 | E7: 12.14 | F7: 69 | G7: Shopify
B8: GEB 010 | C8: Mascara Condicionadora GE Beauty 50ml | D8: 5.11 | E8: 5.81 | F8: 40 | G8: Shopify
B9: GEB 013 | C9: Shampoo GE Beauty 60 ml | D9: 6.49 | E9: 6.85 | F9: 40 | G9: Shopify
B10: GEB 022 | C10: Booster Antifrizz GE Beauty 15ml | D10: 9.24 | E10: 9.86 | F10: 79 | G10: Shopify
B11: GEB 029 | C11: Melon Mood Mini Body & Hair Mist | D11: 16.7 | E11: 17.2 | F11: 79 | G11: Shopify
B12: GEB 101 | C12: Primer Cachos Definidos GE Beauty 250ml | D12: 15.73 | E12: 16.01 | F12: 149 | G12: Shopify
B13: GEB 121 | C13: MÁSCARA RECONSTRUTORA MAYDAY GE Beauty (200ml) | D13: 29.88 | E13: 30.38 | F13: 111 | G13: Shopify
B14: GEB 019 | C14: Booster Fortificante GE Beauty 15ml | F14: 75 | G14: Shopify
B15: GEB 020 | C15: Booster Hidratante GE Beauty 15ml | F15: 69 | G15: Shopify
B16: GEB 021 | C16: Booster Definição GE Beauty 15ml | F16: 69 | G16: Shopify
B17: GEB 023 | C17: Booster Antioxidante GE Beauty 15ml | F17: 75 | G17: Shopify
B18: GEB 024 | C18: Body Hair Mist Melon Mood GE Beauty 200ml | D18: 20.68 | E18: 21.18 | F18: 129 | G18: Shopify
B19: GEB 102 | C19: Primer Liso Intacto GE Beauty 150ml | F19: 139 | G19: Shopify
B20: GEB 120 | C20: Leave-in Pluma GE Beauty 200ml | F20: 149 | G20: Shopify

Sheet Histórico
B2: GE Beauty — B2B · Histórico de Deals
B3: Operador | C3: Data | D3: NF | E3: Status | F3: ID_Deal | G3: SKU | H3: Produto | I3: Volume | J3: Preco | K3: Retail_hist | L3: Desconto_pct | M3: GM_pct | N3: Mês | O3: Receita | P3: Último preço
B4: B4A | C4: 45933 | D4: 00076502 | E4: completed | F4: b4a_2025-10-03_nf00076502 | G4: GEB 008 | H4: Shampoo a Seco GE Beauty 150ml | I4: 300 | J4: 15 | L4: =IFERROR(IF(K4=0,"",((K4-J4)/K4)),"") | M4: =IFERROR((J4-INDEX(COGS!$D$4:$D$20,MATCH($G4,COGS!$B$4:$B$20,0)))/J4,"") -> 0.19066667 | N4: =EOMONTH(C4,-1)+1 -> 45931 | O4: =J4*I4 -> 4500 | P4: =IFERROR(INDEX($J$4:$J$503,MATCH(_xludf.MAXIFS($C$4:$C$503,$G$4:$G$503,$G4,$B$4:$B$503,$B4),$C$4:$C$503,0)),"—") -> —
B5: UAU Box | C5: 45967 | D5: 00077620 | E5: completed | F5: uaubox_2025-11-06_nf00077620 | G5: GEB 019 | H5: Booster Fortificante GE Beauty 15ml | I5: 1250 | J5: 16.37 | L5: =IFERROR(IF(K5=0,"",((K5-J5)/K5)),"") | M5: =IFERROR((J5-INDEX(COGS!$D$4:$D$20,MATCH($G5,COGS!$B$4:$B$20,0)))/J5,"") -> 1 | N5: =EOMONTH(C5,-1)+1 -> 45962 | O5: =J5*I5 -> 20462.5 | P5: =IFERROR(INDEX($J$4:$J$503,MATCH(_xludf.MAXIFS($C$4:$C$503,$G$4:$G$503,$G5,$B$4:$B$503,$B5),$C$4:$C$503,0)),"—") -> —
B6: UAU Box | C6: 45967 | D6: 00077620 | E6: completed | F6: uaubox_2025-11-06_nf00077620 | G6: GEB 023 | H6: Booster Antioxidante GE Beauty 15ml | I6: 1250 | J6: 18.32 | L6: =IFERROR(IF(K6=0,"",((K6-J6)/K6)),"") | M6: =IFERROR((J6-INDEX(COGS!$D$4:$D$20,MATCH($G6,COGS!$B$4:$B$20,0)))/J6,"") -> 1 | N6: =EOMONTH(C6,-1)+1 -> 45962 | O6: =J6*I6 -> 22900 | P6: =IFERROR(INDEX($J$4:$J$503,MATCH(_xludf.MAXIFS($C$4:$C$503,$G$4:$G$503,$G6,$B$4:$B$503,$B6),$C$4:$C$503,0)),"—") -> —
B7: UAU Box | C7: 46062 | D7: 84.166 | E7: completed | F7: uaubox-2026-02 | G7: GEB 008 | H7: Shampoo a Seco GE Beauty 150ml | I7: 17000 | J7: 17.19 | K7: 58.65 | L7: =IFERROR(IF(K7=0,"",((K7-J7)/K7)),"") -> 0.70690537 | M7: =IFERROR((J7-INDEX(COGS!$D$4:$D$20,MATCH($G7,COGS!$B$4:$B$20,0)))/J7,"") -> 0.29377545 | N7: =EOMONTH(C7,-1)+1 -> 46054 | O7: =J7*I7 -> 292230 | P7: =IFERROR(INDEX($J$4:$J$503,MATCH(_xludf.MAXIFS($C$4:$C$503,$G$4:$G$503,$G7,$B$4:$B$503,$B7),$C$4:$C$503,0)),"—") -> —
B8: UAU Box | C8: 46112 | D8: 00001921 | E8: completed | F8: uaubox_2026-03-31_nf00001921 | G8: GEB 020 | H8: Booster Hidratante GE Beauty 15ml | I8: 17000 | J8: 18.29 | L8: =IFERROR(IF(K8=0,"",((K8-J8)/K8)),"") | M8: =IFERROR((J8-INDEX(COGS!$D$4:$D$20,MATCH($G8,COGS!$B$4:$B$20,0)))/J8,"") -> 1 | N8: =EOMONTH(C8,-1)+1 -> 46082 | O8: =J8*I8 -> 310930 | P8: =IFERROR(INDEX($J$4:$J$503,MATCH(_xludf.MAXIFS($C$4:$C$503,$G$4:$G$503,$G8,$B$4:$B$503,$B8),$C$4:$C$503,0)),"—") -> —
B9: Magenta | C9: 46112 | D9: 00001928 | E9: completed | F9: magenta_2026-03-31_nf00001928 | G9: GEB 003 | H9: Leave-in com proteção térmica GE Beauty 150ml | I9: 2000 | J9: 13.5 | L9: =IFERROR(IF(K9=0,"",((K9-J9)/K9)),"") | M9: =IFERROR((J9-INDEX(COGS!$D$4:$D$20,MATCH($G9,COGS!$B$4:$B$20,0)))/J9,"") -> 0.38148148 | N9: =EOMONTH(C9,-1)+1 -> 46082 | O9: =J9*I9 -> 27000 | P9: =IFERROR(INDEX($J$4:$J$503,MATCH(_xludf.MAXIFS($C$4:$C$503,$G$4:$G$503,$G9,$B$4:$B$503,$B9),$C$4:$C$503,0)),"—") -> —
B10: Magenta | C10: 46112 | D10: 00001928 | E10: completed | F10: magenta_2026-03-31_nf00001928 | G10: GEB 002 | H10: Máscara Condicionadora GE Beauty 200ml | I10: 560 | J10: 16.5 | L10: =IFERROR(IF(K10=0,"",((K10-J10)/K10)),"") | M10: =IFERROR((J10-INDEX(COGS!$D$4:$D$20,MATCH($G10,COGS!$B$4:$B$20,0)))/J10,"") -> 0.35515152 | N10: =EOMONTH(C10,-1)+1 -> 46082 | O10: =J10*I10 -> 9240 | P10: =IFERROR(INDEX($J$4:$J$503,MATCH(_xludf.MAXIFS($C$4:$C$503,$G$4:$G$503,$G10,$B$4:$B$503,$B10),$C$4:$C$503,0)),"—") -> —
B11: UAU Box | C11: 46129 | D11: 00002174 | E11: completed | F11: uaubox_2026-04-17_nf00002174 | G11: GEB 020 | H11: Booster Hidratante GE Beauty 15ml | I11: 1500 | J11: 18.29 | L11: =IFERROR(IF(K11=0,"",((K11-J11)/K11)),"") | M11: =IFERROR((J11-INDEX(COGS!$D$4:$D$20,MATCH($G11,COGS!$B$4:$B$20,0)))/J11,"") -> 1 | N11: =EOMONTH(C11,-1)+1 -> 46113 | O11: =J11*I11 -> 27435 | P11: =IFERROR(INDEX($J$4:$J$503,MATCH(_xludf.MAXIFS($C$4:$C$503,$G$4:$G$503,$G11,$B$4:$B$503,$B11),$C$4:$C$503,0)),"—") -> —
B12: Magenta | C12: 46169 | D12: 00002682 | E12: completed | F12: magenta_2026-05-27_nf00002682 | G12: GEB 003 | H12: Leave-in com proteção térmica GE Beauty 150ml | I12: 1000 | J12: 18.81 | L12: =IFERROR(IF(K12=0,"",((K12-J12)/K12)),"") | M12: =IFERROR((J12-INDEX(COGS!$D$4:$D$20,MATCH($G12,COGS!$B$4:$B$20,0)))/J12,"") -> 0.55608719 | N12: =EOMONTH(C12,-1)+1 -> 46143 | O12: =J12*I12 -> 18810 | P12: =IFERROR(INDEX($J$4:$J$503,MATCH(_xludf.MAXIFS($C$4:$C$503,$G$4:$G$503,$G12,$B$4:$B$503,$B12),$C$4:$C$503,0)),"—") -> —
B13: Magenta | C13: 46169 | D13: 00002682 | E13: completed | F13: magenta_2026-05-27_nf00002682 | G13: GEB 002 | H13: Máscara Condicionadora GE Beauty 200ml | I13: 1000 | J13: 19.17 | L13: =IFERROR(IF(K13=0,"",((K13-J13)/K13)),"") | M13: =IFERROR((J13-INDEX(COGS!$D$4:$D$20,MATCH($G13,COGS!$B$4:$B$20,0)))/J13,"") -> 0.44496609 | N13: =EOMONTH(C13,-1)+1 -> 46143 | O13: =J13*I13 -> 19170 | P13: =IFERROR(INDEX($J$4:$J$503,MATCH(_xludf.MAXIFS($C$4:$C$503,$G$4:$G$503,$G13,$B$4:$B$503,$B13),$C$4:$C$503,0)),"—") -> —
B14: B4A | C14: 46171 | D14: 00002701 | E14: completed | F14: b4a_2026-05-29_nf00002701 | G14: GEB 013 | H14: Shampoo GE Beauty 60 ml | I14: 15000 | J14: 7 | L14: =IFERROR(IF(K14=0,"",((K14-J14)/K14)),"") | M14: =IFERROR((J14-INDEX(COGS!$D$4:$D$20,MATCH($G14,COGS!$B$4:$B$20,0)))/J14,"") -> 0.072857143 | N14: =EOMONTH(C14,-1)+1 -> 46143 | O14: =J14*I14 -> 105000 | P14: =IFERROR(INDEX($J$4:$J$503,MATCH(_xludf.MAXIFS($C$4:$C$503,$G$4:$G$503,$G14,$B$4:$B$503,$B14),$C$4:$C$503,0)),"—") -> —
B15: B4A | C15: 46171 | D15: 00002702 | E15: completed | F15: b4a_2026-05-29_nf00002702 | G15: GEB 010 | H15: Mascara Condicionadora GE Beauty 50ml | I15: 15000 | J15: 7 | L15: =IFERROR(IF(K15=0,"",((K15-J15)/K15)),"") | M15: =IFERROR((J15-INDEX(COGS!$D$4:$D$20,MATCH($G15,COGS!$B$4:$B$20,0)))/J15,"") -> 0.27 | N15: =EOMONTH(C15,-1)+1 -> 46143 | O15: =J15*I15 -> 105000 | P15: =IFERROR(INDEX($J$4:$J$503,MATCH(_xludf.MAXIFS($C$4:$C$503,$G$4:$G$503,$G15,$B$4:$B$503,$B15),$C$4:$C$503,0)),"—") -> —
B16: UAU Box | C16: 46310 | E16: contracted | F16: uaubox_2026-11_contracted | G16: GEB 021 | H16: Booster Definição GE Beauty 15ml | I16: 17000 | J16: 21.83 | L16: =IFERROR(IF(K16=0,"",((K16-J16)/K16)),"") | M16: =IFERROR((J16-INDEX(COGS!$D$4:$D$20,MATCH($G16,COGS!$B$4:$B$20,0)))/J16,"") -> 1 | N16: =EOMONTH(C16,-1)+1 -> 46296 | O16: =J16*I16 -> 371110 | P16: =IFERROR(INDEX($J$4:$J$503,MATCH(_xludf.MAXIFS($C$4:$C$503,$G$4:$G$503,$G16,$B$4:$B$503,$B16),$C$4:$C$503,0)),"—") -> —
B17: B4A | C17: 46235 | E17: completed | F17: b4a-2026-ago-out | G17: GEB 003 | H17: Leave-in com proteção térmica GE Beauty 150ml | I17: 15000 | J17: 12 | K17: 84.15 | L17: =IFERROR(IF(K17=0,"",((K17-J17)/K17)),"") -> 0.8573975 | M17: =IFERROR((J17-INDEX(COGS!$D$4:$D$20,MATCH($G17,COGS!$B$4:$B$20,0)))/J17,"") -> 0.30416667 | N17: =EOMONTH(C17,-1)+1 -> 46235 | O17: =J17*I17 -> 180000 | P17: =IFERROR(INDEX($J$4:$J$503,MATCH(_xludf.MAXIFS($C$4:$C$503,$G$4:$G$503,$G17,$B$4:$B$503,$B17),$C$4:$C$503,0)),"—") -> —
B18: B4A | C18: 46235 | E18: completed | F18: b4a-2026-ago-out | G18: GEB 008 | H18: Shampoo a Seco GE Beauty 150ml | I18: 15000 | J18: 14 | K18: 58.65 | L18: =IFERROR(IF(K18=0,"",((K18-J18)/K18)),"") -> 0.76129582 | M18: =IFERROR((J18-INDEX(COGS!$D$4:$D$20,MATCH($G18,COGS!$B$4:$B$20,0)))/J18,"") -> 0.13285714 | N18: =EOMONTH(C18,-1)+1 -> 46235 | O18: =J18*I18 -> 210000 | P18: =IFERROR(INDEX($J$4:$J$503,MATCH(_xludf.MAXIFS($C$4:$C$503,$G$4:$G$503,$G18,$B$4:$B$503,$B18),$C$4:$C$503,0)),"—") -> —
B19: B4A | C19: 46235 | E19: completed | F19: b4a-2026-ago-out | G19: GEB 022 | H19: Booster Antifrizz GE Beauty 15ml | I19: 20000 | J19: 12 | K19: 67.15 | L19: =IFERROR(IF(K19=0,"",((K19-J19)/K19)),"") -> 0.82129561 | M19: =IFERROR((J19-INDEX(COGS!$D$4:$D$20,MATCH($G19,COGS!$B$4:$B$20,0)))/J19,"") -> 0.23 | N19: =EOMONTH(C19,-1)+1 -> 46235 | O19: =J19*I19 -> 240000 | P19: =IFERROR(INDEX($J$4:$J$503,MATCH(_xludf.MAXIFS($C$4:$C$503,$G$4:$G$503,$G19,$B$4:$B$503,$B19),$C$4:$C$503,0)),"—") -> —

Sheet Estoque
B2: GE Beauty — Estoque Omie · 30/06/2026 16:33
B3: SKU | C3: Produto | D3: CD (un.) | E3: Lojas (un.) | F3: Total (un.)
B4: GEB 001 | C4: Shampoo sem sulfato GE Beauty 250ml | D4: 0 | E4: 0 | F4: 0
B5: GEB 002 | C5: Máscara Condicionadora GE Beauty 200ml | D5: 0 | E5: 0 | F5: 0
B6: GEB 003 | C6: Leave-in com proteção térmica GE Beauty 150ml | D6: 0 | E6: 0 | F6: 0
B7: GEB 008 | C7: Shampoo a Seco GE Beauty 150ml | D7: 0 | E7: 0 | F7: 0
B8: GEB 010 | C8: Mascara Condicionadora GE Beauty 50ml | D8: 0 | E8: 0 | F8: 0
B9: GEB 011 | C9: Leave-in GE Beauty 50ml | D9: 0 | E9: 0 | F9: 0
B10: GEB 013 | C10: Shampoo GE Beauty 60 ml | D10: 0 | E10: 0 | F10: 0
B11: GEB 019 | C11: Booster Fortificante GE Beauty 15ml | D11: 0 | E11: 0 | F11: 0
B12: GEB 020 | C12: Booster Hidratante GE Beauty 15ml | D12: 0 | E12: 0 | F12: 0
B13: GEB 021 | C13: Booster Definição GE Beauty 15ml | D13: 0 | E13: 0 | F13: 0
B14: GEB 022 | C14: Booster Antifrizz GE Beauty 15ml | D14: 0 | E14: 0 | F14: 0
B15: GEB 023 | C15: Booster Antioxidante GE Beauty 15ml | D15: 0 | E15: 0 | F15: 0
... B32: GEB 303 | C32: SACHÊ LEAVE-IN GE BEAUTY 15ml | D32: 0 | E32: 0 | F32: 0
