Workbook
Name B2B_canais: #REF!
Name B2B_inicio: #REF!
Name B2B_início: #REF!
Name B2B_margem: #REF!
Name B2B_maturacao: #REF!
Name B2B_receitabruta: #REF!
Name B2B_sazonalidade: #REF!
Name B2B_sellout: #REF!
Name B2B_volume: #REF!
Name B2B_volumeprodutos: #REF!
Name B2B_volumeref: #REF!
Name Premissas_curvaabcajustada: #REF!
Name Premissas_produtos: #REF!

Sheet Grade
D1: 45261 | E1: 45292 | F1: 45323 | G1: 45352 | H1: 45383 | I1: 45413 | J1: 45444 | K1: 45474 | L1: 45505 | M1: 45536 | N1: 45566 | O1: 45597 | P1: 45627 | S1: 45292 | T1: 45323 | U1: 45352 | V1: 45383 | W1: 45413 | X1: 45444 | Y1: 45474 | Z1: 45505 | AA1: 45536 | AB1: 45566 | AC1: 45597 | AD1: 45627 | AH1: =EDATE(E1,-12) -> 44927 | AI1: =EDATE(F1,-12) -> 44958 | AJ1: =EDATE(G1,-12) -> 44986 | AK1: =EDATE(H1,-12) -> 45017 | AL1: =EDATE(I1,-12) -> 45047 | AM1: =EDATE(J1,-12) -> 45078 | AN1: =EDATE(K1,-12) -> 45108 | AO1: =EDATE(L1,-12) -> 45139 | ... AS1: =EDATE(P1,-12) -> 45261 | AW1: YTD | BA1: YTD | BG1: YTD
C2: 45627 | AW2: 45627 | BA2: =AW2 -> 45627 | BG2: =EDATE(AW2,-12) -> 45261
E3: Real | F3: Real | G3: Real | H3: Real | I3: Real | J3: Real | K3: Real | L3: Real | M3: Real | N3: Real | O3: Real | P3: Real | Q3: % | S3: Meta | T3: Meta | U3: Meta | V3: Meta | W3: Meta | X3: Meta | Y3: Meta | Z3: Meta | AA3: Meta | AB3: Meta | AC3: Meta | AD3: Meta | AE3: var R$ | AF3: var % | AH3: Ano-1 | AI3: Ano-1 | AJ3: Ano-1 | AK3: Ano-1 | AL3: Ano-1 | AM3: Ano-1 | AN3: Ano-1 | AO3: Ano-1 | AP3: Ano-1 | AQ3: Ano-1 | AR3: Ano-1 | AS3: Ano-1 | AT3: var R$ | AU3: var % | AW3: Real R$ | AX3: Real % | BA3: Meta R$ | BB3: Meta % | BC3: var R$ | BD3: var %/pp | BG3: Ano-1 R$ | BH3: Ano-1 % | BI3: var R$ | BJ3: var %/pp
A4: Receita | C4: Faturamento bruto | E4: =E5+E33+E34+E35 -> #REF! | F4: =F5+F33+F34+F35 -> #REF! | G4: =G5+G33+G34+G35 -> #REF! | H4: =H5+H33+H34+H35 -> #REF! | I4: =I5+I33+I34+I35 -> #REF! | J4: =J5+J33+J34+J35 -> #REF! | K4: =K5+K33+K34+K35 -> #REF! | L4: =L5+L33+L34+L35 -> #REF! | ... P4: =P5+P33+P34+P35 -> #REF! | S4: =S5+S33+S34+S35 -> #REF! | T4: =T5+T33+T34+T35 -> #REF! | U4: =U5+U33+U34+U35 -> #REF! | V4: =V5+V33+V34+V35 -> #REF! | W4: =W5+W33+W34+W35 -> #REF! | X4: =X5+X33+X34+X35 -> #REF! | Y4: =Y5+Y33+Y34+Y35 -> #REF! | Z4: =Z5+Z33+Z34+Z35 -> #REF! | ... AD4: =AD5+AD33+AD34+AD35 -> #REF! | AE4: =INDEX($E4:$P4,1,MATCH($C$2,$E$1:$P$1,0))-INDEX(S4:AD4,1,MATCH($C$2,S$1:AD$1,0)) -> #REF! | AF4: =IFERROR(INDEX($E4:$P4,1,MATCH($C$2,$E$1:$P$1,0))/INDEX($S4:$AD4,1,MATCH($C$2,S$1:AD$1,0))-1,0) -> 0 | AH4: =AH5+AH33+AH34+AH35 -> #REF! | AI4: =AI5+AI33+AI34+AI35 -> #REF! | AJ4: =AJ5+AJ33+AJ34+AJ35 -> #REF! | AK4: =AK5+AK33+AK34+AK35 -> #REF! | AL4: =AL5+AL33+AL34+AL35 -> #REF! | AM4: =AM5+AM33+AM34+AM35 -> #REF! | AN4: =AN5+AN33+AN34+AN35 -> #REF! | AO4: =AO5+AO33+AO34+AO35 -> #REF! | ... AS4: =AS5+AS33+AS34+AS35 -> #REF! | AT4: =INDEX($E4:$P4,1,MATCH($C$2,$E$1:$P$1,0))-INDEX(AH4:AS4,1,MATCH(EDATE($C$2,-12),AH$1:AS$1,0)) -> #REF! | AU4: =IFERROR(INDEX($E4:$P4,1,MATCH($C$2,$E$1:$P$1,0))/INDEX(AH4:AS4,1,MATCH(EDATE($C$2,-12),AH$1:AS$1,0))-1,0) -> 0 | AW4: =AW5+AW33+AW34+AW35 -> #REF! | BA4: =BA5+BA33+BA35 -> #REF! | BC4: =$AW4-BA4 -> #REF! | BD4: =IFERROR($AW4/BA4-1,"-") -> - | BG4: =SUMIF(AH$1:AS$1,"<="&BG$2,AH4:AS4) -> #REF! | BI4: =$AW4-BG4 -> #REF! | BJ4: =IFERROR($AW4/BG4-1,"-") -> -
A5: Receita | C5: Produtos | E5: =E6+E21+E15 -> #REF! | F5: =F6+F21+F15 -> #REF! | G5: =G6+G21+G15 -> #REF! | H5: =H6+H21+H15 -> #REF! | I5: =I6+I21+I15 -> #REF! | J5: =J6+J21+J15 -> #REF! | K5: =K6+K21+K15 -> #REF! | L5: =L6+L21+L15 -> #REF! | ... P5: =P6+P21+P15 -> #REF! | S5: =S6+S21 -> #REF! | T5: =T6+T21 -> #REF! | U5: =U6+U21 -> #REF! | V5: =V6+V21 -> #REF! | W5: =W6+W21 -> #REF! | X5: =X6+X21 -> #REF! | Y5: =Y6+Y21 -> #REF! | Z5: =Z6+Z21 -> #REF! | ... AD5: =AD6+AD21 -> #REF! | AE5: =INDEX($E5:$P5,1,MATCH($C$2,$E$1:$P$1,0))-INDEX(S5:AD5,1,MATCH($C$2,S$1:AD$1,0)) -> #REF! | AF5: =IFERROR(INDEX($E5:$P5,1,MATCH($C$2,$E$1:$P$1,0))/INDEX($S5:$AD5,1,MATCH($C$2,S$1:AD$1,0))-1,0) -> 0 | AH5: =AH6+AH21 -> #REF! | AI5: =AI6+AI21 -> #REF! | AJ5: =AJ6+AJ21 -> #REF! | AK5: =AK6+AK21 -> #REF! | AL5: =AL6+AL21 -> #REF! | AM5: =AM6+AM21 -> #REF! | AN5: =AN6+AN21 -> #REF! | AO5: =AO6+AO21 -> #REF! | ... AS5: =AS6+AS21 -> #REF! | AT5: =INDEX($E5:$P5,1,MATCH($C$2,$E$1:$P$1,0))-INDEX(AH5:AS5,1,MATCH(EDATE($C$2,-12),AH$1:AS$1,0)) -> #REF! | AU5: =IFERROR(INDEX($E5:$P5,1,MATCH($C$2,$E$1:$P$1,0))/INDEX(AH5:AS5,1,MATCH(EDATE($C$2,-12),AH$1:AS$1,0))-1,0) -> 0 | AW5: =AW6+AW21+AW15 -> #REF! | BA5: =BA6+BA21 -> #REF! | BC5: =$AW5-BA5 -> #REF! | BD5: =IFERROR($AW5/BA5-1,"-") -> - | BG5: =BG6+BG21 -> #REF! | BI5: =$AW5-BG5 -> #REF! | BJ5: =IFERROR($AW5/BG5-1,"-") -> -
A6: Receita | C6: Fórmulas | E6: =SUM(E7:E14) -> #REF! | F6: =SUM(F7:F14) -> #REF! | G6: =SUM(G7:G14) -> #REF! | H6: =SUM(H7:H14) -> #REF! | I6: =SUM(I7:I14) -> #REF! | J6: =SUM(J7:J14) -> #REF! | K6: =SUM(K7:K14) -> #REF! | L6: =SUM(L7:L14) -> #REF! | ... P6: =SUM(P7:P14) -> #REF! | S6: =SUM(S7:S14) -> #REF! | T6: =SUM(T7:T14) -> #REF! | U6: =SUM(U7:U14) -> #REF! | V6: =SUM(V7:V14) -> #REF! | W6: =SUM(W7:W14) -> #REF! | X6: =SUM(X7:X14) -> #REF! | Y6: =SUM(Y7:Y14) -> #REF! | Z6: =SUM(Z7:Z14) -> #REF! | ... AD6: =SUM(AD7:AD14) -> #REF! | AE6: =INDEX($E6:$P6,1,MATCH($C$2,$E$1:$P$1,0))-INDEX(S6:AD6,1,MATCH($C$2,S$1:AD$1,0)) -> #REF! | AF6: =IFERROR(INDEX($E6:$P6,1,MATCH($C$2,$E$1:$P$1,0))/INDEX($S6:$AD6,1,MATCH($C$2,S$1:AD$1,0))-1,0) -> 0 | AH6: =SUM(AH7:AH14) -> #REF! | AI6: =SUM(AI7:AI14) -> #REF! | AJ6: =SUM(AJ7:AJ14) -> #REF! | AK6: =SUM(AK7:AK14) -> #REF! | AL6: =SUM(AL7:AL14) -> #REF! | AM6: =SUM(AM7:AM14) -> #REF! | AN6: =SUM(AN7:AN14) -> #REF! | AO6: =SUM(AO7:AO14) -> #REF! | ... AS6: =SUM(AS7:AS14) -> #REF! | AT6: =INDEX($E6:$P6,1,MATCH($C$2,$E$1:$P$1,0))-INDEX(AH6:AS6,1,MATCH(EDATE($C$2,-12),AH$1:AS$1,0)) -> #REF! | AU6: =IFERROR(INDEX($E6:$P6,1,MATCH($C$2,$E$1:$P$1,0))/INDEX(AH6:AS6,1,MATCH(EDATE($C$2,-12),AH$1:AS$1,0))-1,0) -> 0 | AW6: =SUM(AW7:AW14) -> #REF! | BA6: =SUM(BA7:BA14) -> #REF! | BC6: =$AW6-BA6 -> #REF! | BD6: =IFERROR($AW6/BA6-1,"-") -> - | BG6: =SUM(BG7:BG14) -> #REF! | BI6: =$AW6-BG6 -> #REF! | BJ6: =IFERROR($AW6/BG6-1,"-") -> -
A7: Receita | C7: Shampoo 250ml | E7: {=INDEX(#REF!,MATCH($C7,#REF!,0),MATCH(E$1,#REF!,0))} -> #REF! | F7: {=INDEX(#REF!,MATCH($C7,#REF!,0),MATCH(F$1,#REF!,0))} -> #REF! | G7: {=INDEX(#REF!,MATCH($C7,#REF!,0),MATCH(G$1,#REF!,0))} -> #REF! | H7: {=INDEX(#REF!,MATCH($C7,#REF!,0),MATCH(H$1,#REF!,0))} -> #REF! | I7: {=INDEX(#REF!,MATCH($C7,#REF!,0),MATCH(I$1,#REF!,0))} -> #REF! | J7: {=INDEX(#REF!,MATCH($C7,#REF!,0),MATCH(J$1,#REF!,0))} -> #REF! | K7: {=INDEX(#REF!,MATCH($C7,#REF!,0),MATCH(K$1,#REF!,0))} -> #REF! | L7: {=INDEX(#REF!,MATCH($C7,#REF!,0),MATCH(L$1,#REF!,0))} -> #REF! | ... P7: {=INDEX(#REF!,MATCH($C7,#REF!,0),MATCH(P$1,#REF!,0))} -> #REF! | S7: {=INDEX(#REF!,MATCH($C7,#REF!,0),MATCH(S$1,#REF!,0))} -> #REF! | T7: {=INDEX(#REF!,MATCH($C7,#REF!,0),MATCH(T$1,#REF!,0))} -> #REF! | U7: {=INDEX(#REF!,MATCH($C7,#REF!,0),MATCH(U$1,#REF!,0))} -> #REF! | V7: {=INDEX(#REF!,MATCH($C7,#REF!,0),MATCH(V$1,#REF!,0))} -> #REF! | W7: {=INDEX(#REF!,MATCH($C7,#REF!,0),MATCH(W$1,#REF!,0))} -> #REF! | X7: {=INDEX(#REF!,MATCH($C7,#REF!,0),MATCH(X$1,#REF!,0))} -> #REF! | Y7: {=INDEX(#REF!,MATCH($C7,#REF!,0),MATCH(Y$1,#REF!,0))} -> #REF! | Z7: {=INDEX(#REF!,MATCH($C7,#REF!,0),MATCH(Z$1,#REF!,0))} -> #REF! | ... AD7: {=INDEX(#REF!,MATCH($C7,#REF!,0),MATCH(AD$1,#REF!,0))} -> #REF! | AE7: =INDEX($E7:$P7,1,MATCH($C$2,$E$1:$P$1,0))-INDEX(S7:AD7,1,MATCH($C$2,S$1:AD$1,0)) -> #REF! | AF7: =IFERROR(INDEX($E7:$P7,1,MATCH($C$2,$E$1:$P$1,0))/INDEX($S7:$AD7,1,MATCH($C$2,S$1:AD$1,0))-1,0) -> 0 | AH7: {=INDEX(#REF!,MATCH($C7,#REF!,0),MATCH(AH$1,#REF!,0))} -> #REF! | AI7: {=INDEX(#REF!,MATCH($C7,#REF!,0),MATCH(AI$1,#REF!,0))} -> #REF! | AJ7: {=INDEX(#REF!,MATCH($C7,#REF!,0),MATCH(AJ$1,#REF!,0))} -> #REF! | AK7: {=INDEX(#REF!,MATCH($C7,#REF!,0),MATCH(AK$1,#REF!,0))} -> #REF! | AL7: {=INDEX(#REF!,MATCH($C7,#REF!,0),MATCH(AL$1,#REF!,0))} -> #REF! | AM7: {=INDEX(#REF!,MATCH($C7,#REF!,0),MATCH(AM$1,#REF!,0))} -> #REF! | AN7: {=INDEX(#REF!,MATCH($C7,#REF!,0),MATCH(AN$1,#REF!,0))} -> #REF! | AO7: {=INDEX(#REF!,MATCH($C7,#REF!,0),MATCH(AO$1,#REF!,0))} -> #REF! | ... AS7: {=INDEX(#REF!,MATCH($C7,#REF!,0),MATCH(AS$1,#REF!,0))} -> #REF! | AT7: =INDEX($E7:$P7,1,MATCH($C$2,$E$1:$P$1,0))-INDEX(AH7:AS7,1,MATCH(EDATE($C$2,-12),AH$1:AS$1,0)) -> #REF! | AU7: =IFERROR(INDEX($E7:$P7,1,MATCH($C$2,$E$1:$P$1,0))/INDEX(AH7:AS7,1,MATCH(EDATE($C$2,-12),AH$1:AS$1,0))-1,0) -> 0 | AW7: =SUMIF(E$1:P$1,"<="&AW$2,E7:P7) -> #REF! | BA7: =SUMIF(S$1:AD$1,"<="&BA$2,S7:AD7) -> #REF! | BC7: =$AW7-BA7 -> #REF! | BD7: =IFERROR($AW7/BA7-1,"-") -> - | BG7: =SUMIF(AH$1:AS$1,"<="&BG$2,AH7:AS7) -> #REF! | BI7: =$AW7-BG7 -> #REF! | BJ7: =IFERROR($AW7/BG7-1,"-") -> -
A8: Receita | C8: Máscara 200ml | E8: {=INDEX(#REF!,MATCH($C8,#REF!,0),MATCH(E$1,#REF!,0))} -> #REF! | F8: {=INDEX(#REF!,MATCH($C8,#REF!,0),MATCH(F$1,#REF!,0))} -> #REF! | G8: {=INDEX(#REF!,MATCH($C8,#REF!,0),MATCH(G$1,#REF!,0))} -> #REF! | H8: {=INDEX(#REF!,MATCH($C8,#REF!,0),MATCH(H$1,#REF!,0))} -> #REF! | I8: {=INDEX(#REF!,MATCH($C8,#REF!,0),MATCH(I$1,#REF!,0))} -> #REF! | J8: {=INDEX(#REF!,MATCH($C8,#REF!,0),MATCH(J$1,#REF!,0))} -> #REF! | K8: {=INDEX(#REF!,MATCH($C8,#REF!,0),MATCH(K$1,#REF!,0))} -> #REF! | L8: {=INDEX(#REF!,MATCH($C8,#REF!,0),MATCH(L$1,#REF!,0))} -> #REF! | ... P8: {=INDEX(#REF!,MATCH($C8,#REF!,0),MATCH(P$1,#REF!,0))} -> #REF! | S8: {=INDEX(#REF!,MATCH($C8,#REF!,0),MATCH(S$1,#REF!,0))} -> #REF! | T8: {=INDEX(#REF!,MATCH($C8,#REF!,0),MATCH(T$1,#REF!,0))} -> #REF! | U8: {=INDEX(#REF!,MATCH($C8,#REF!,0),MATCH(U$1,#REF!,0))} -> #REF! | V8: {=INDEX(#REF!,MATCH($C8,#REF!,0),MATCH(V$1,#REF!,0))} -> #REF! | W8: {=INDEX(#REF!,MATCH($C8,#REF!,0),MATCH(W$1,#REF!,0))} -> #REF! | X8: {=INDEX(#REF!,MATCH($C8,#REF!,0),MATCH(X$1,#REF!,0))} -> #REF! | Y8: {=INDEX(#REF!,MATCH($C8,#REF!,0),MATCH(Y$1,#REF!,0))} -> #REF! | Z8: {=INDEX(#REF!,MATCH($C8,#REF!,0),MATCH(Z$1,#REF!,0))} -> #REF! | ... AD8: {=INDEX(#REF!,MATCH($C8,#REF!,0),MATCH(AD$1,#REF!,0))} -> #REF! | AE8: =INDEX($E8:$P8,1,MATCH($C$2,$E$1:$P$1,0))-INDEX(S8:AD8,1,MATCH($C$2,S$1:AD$1,0)) -> #REF! | AF8: =IFERROR(INDEX($E8:$P8,1,MATCH($C$2,$E$1:$P$1,0))/INDEX($S8:$AD8,1,MATCH($C$2,S$1:AD$1,0))-1,0) -> 0 | AH8: {=INDEX(#REF!,MATCH($C8,#REF!,0),MATCH(AH$1,#REF!,0))} -> #REF! | AI8: {=INDEX(#REF!,MATCH($C8,#REF!,0),MATCH(AI$1,#REF!,0))} -> #REF! | AJ8: {=INDEX(#REF!,MATCH($C8,#REF!,0),MATCH(AJ$1,#REF!,0))} -> #REF! | AK8: {=INDEX(#REF!,MATCH($C8,#REF!,0),MATCH(AK$1,#REF!,0))} -> #REF! | AL8: {=INDEX(#REF!,MATCH($C8,#REF!,0),MATCH(AL$1,#REF!,0))} -> #REF! | AM8: {=INDEX(#REF!,MATCH($C8,#REF!,0),MATCH(AM$1,#REF!,0))} -> #REF! | AN8: {=INDEX(#REF!,MATCH($C8,#REF!,0),MATCH(AN$1,#REF!,0))} -> #REF! | AO8: {=INDEX(#REF!,MATCH($C8,#REF!,0),MATCH(AO$1,#REF!,0))} -> #REF! | ... AS8: {=INDEX(#REF!,MATCH($C8,#REF!,0),MATCH(AS$1,#REF!,0))} -> #REF! | AT8: =INDEX($E8:$P8,1,MATCH($C$2,$E$1:$P$1,0))-INDEX(AH8:AS8,1,MATCH(EDATE($C$2,-12),AH$1:AS$1,0)) -> #REF! | AU8: =IFERROR(INDEX($E8:$P8,1,MATCH($C$2,$E$1:$P$1,0))/INDEX(AH8:AS8,1,MATCH(EDATE($C$2,-12),AH$1:AS$1,0))-1,0) -> 0 | AW8: =SUMIF(E$1:P$1,"<="&AW$2,E8:P8) -> #REF! | BA8: =SUMIF(S$1:AD$1,"<="&BA$2,S8:AD8) -> #REF! | BC8: =$AW8-BA8 -> #REF! | BD8: =IFERROR($AW8/BA8-1,"-") -> - | BG8: =SUMIF(AH$1:AS$1,"<="&BG$2,AH8:AS8) -> #REF! | BI8: =$AW8-BG8 -> #REF! | BJ8: =IFERROR($AW8/BG8-1,"-") -> -
A9: Receita | C9: Leave-in 150ml | E9: {=INDEX(#REF!,MATCH($C9,#REF!,0),MATCH(E$1,#REF!,0))} -> #REF! | F9: {=INDEX(#REF!,MATCH($C9,#REF!,0),MATCH(F$1,#REF!,0))} -> #REF! | G9: {=INDEX(#REF!,MATCH($C9,#REF!,0),MATCH(G$1,#REF!,0))} -> #REF! | H9: {=INDEX(#REF!,MATCH($C9,#REF!,0),MATCH(H$1,#REF!,0))} -> #REF! | I9: {=INDEX(#REF!,MATCH($C9,#REF!,0),MATCH(I$1,#REF!,0))} -> #REF! | J9: {=INDEX(#REF!,MATCH($C9,#REF!,0),MATCH(J$1,#REF!,0))} -> #REF! | K9: {=INDEX(#REF!,MATCH($C9,#REF!,0),MATCH(K$1,#REF!,0))} -> #REF! | L9: {=INDEX(#REF!,MATCH($C9,#REF!,0),MATCH(L$1,#REF!,0))} -> #REF! | ... P9: {=INDEX(#REF!,MATCH($C9,#REF!,0),MATCH(P$1,#REF!,0))} -> #REF! | S9: {=INDEX(#REF!,MATCH($C9,#REF!,0),MATCH(S$1,#REF!,0))} -> #REF! | T9: {=INDEX(#REF!,MATCH($C9,#REF!,0),MATCH(T$1,#REF!,0))} -> #REF! | U9: {=INDEX(#REF!,MATCH($C9,#REF!,0),MATCH(U$1,#REF!,0))} -> #REF! | V9: {=INDEX(#REF!,MATCH($C9,#REF!,0),MATCH(V$1,#REF!,0))} -> #REF! | W9: {=INDEX(#REF!,MATCH($C9,#REF!,0),MATCH(W$1,#REF!,0))} -> #REF! | X9: {=INDEX(#REF!,MATCH($C9,#REF!,0),MATCH(X$1,#REF!,0))} -> #REF! | Y9: {=INDEX(#REF!,MATCH($C9,#REF!,0),MATCH(Y$1,#REF!,0))} -> #REF! | Z9: {=INDEX(#REF!,MATCH($C9,#REF!,0),MATCH(Z$1,#REF!,0))} -> #REF! | ... AD9: {=INDEX(#REF!,MATCH($C9,#REF!,0),MATCH(AD$1,#REF!,0))} -> #REF! | AE9: =INDEX($E9:$P9,1,MATCH($C$2,$E$1:$P$1,0))-INDEX(S9:AD9,1,MATCH($C$2,S$1:AD$1,0)) -> #REF! | AF9: =IFERROR(INDEX($E9:$P9,1,MATCH($C$2,$E$1:$P$1,0))/INDEX($S9:$AD9,1,MATCH($C$2,S$1:AD$1,0))-1,0) -> 0 | AH9: {=INDEX(#REF!,MATCH($C9,#REF!,0),MATCH(AH$1,#REF!,0))} -> #REF! | AI9: {=INDEX(#REF!,MATCH($C9,#REF!,0),MATCH(AI$1,#REF!,0))} -> #REF! | AJ9: {=INDEX(#REF!,MATCH($C9,#REF!,0),MATCH(AJ$1,#REF!,0))} -> #REF! | AK9: {=INDEX(#REF!,MATCH($C9,#REF!,0),MATCH(AK$1,#REF!,0))} -> #REF! | AL9: {=INDEX(#REF!,MATCH($C9,#REF!,0),MATCH(AL$1,#REF!,0))} -> #REF! | AM9: {=INDEX(#REF!,MATCH($C9,#REF!,0),MATCH(AM$1,#REF!,0))} -> #REF! | AN9: {=INDEX(#REF!,MATCH($C9,#REF!,0),MATCH(AN$1,#REF!,0))} -> #REF! | AO9: {=INDEX(#REF!,MATCH($C9,#REF!,0),MATCH(AO$1,#REF!,0))} -> #REF! | ... AS9: {=INDEX(#REF!,MATCH($C9,#REF!,0),MATCH(AS$1,#REF!,0))} -> #REF! | AT9: =INDEX($E9:$P9,1,MATCH($C$2,$E$1:$P$1,0))-INDEX(AH9:AS9,1,MATCH(EDATE($C$2,-12),AH$1:AS$1,0)) -> #REF! | AU9: =IFERROR(INDEX($E9:$P9,1,MATCH($C$2,$E$1:$P$1,0))/INDEX(AH9:AS9,1,MATCH(EDATE($C$2,-12),AH$1:AS$1,0))-1,0) -> 0 | AW9: =SUMIF(E$1:P$1,"<="&AW$2,E9:P9) -> #REF! | BA9: =SUMIF(S$1:AD$1,"<="&BA$2,S9:AD9) -> #REF! | BC9: =$AW9-BA9 -> #REF! | BD9: =IFERROR($AW9/BA9-1,"-") -> - | BG9: =SUMIF(AH$1:AS$1,"<="&BG$2,AH9:AS9) -> #REF! | BI9: =$AW9-BG9 -> #REF! | BJ9: =IFERROR($AW9/BG9-1,"-") -> -
A10: Receita | C10: Booster antioxidante | E10: {=INDEX(#REF!,MATCH($C10,#REF!,0),MATCH(E$1,#REF!,0))} -> #REF! | F10: {=INDEX(#REF!,MATCH($C10,#REF!,0),MATCH(F$1,#REF!,0))} -> #REF! | G10: {=INDEX(#REF!,MATCH($C10,#REF!,0),MATCH(G$1,#REF!,0))} -> #REF! | H10: {=INDEX(#REF!,MATCH($C10,#REF!,0),MATCH(H$1,#REF!,0))} -> #REF! | I10: {=INDEX(#REF!,MATCH($C10,#REF!,0),MATCH(I$1,#REF!,0))} -> #REF! | J10: {=INDEX(#REF!,MATCH($C10,#REF!,0),MATCH(J$1,#REF!,0))} -> #REF! | K10: {=INDEX(#REF!,MATCH($C10,#REF!,0),MATCH(K$1,#REF!,0))} -> #REF! | L10: {=INDEX(#REF!,MATCH($C10,#REF!,0),MATCH(L$1,#REF!,0))} -> #REF! | ... P10: {=INDEX(#REF!,MATCH($C10,#REF!,0),MATCH(P$1,#REF!,0))} -> #REF! | S10: {=INDEX(#REF!,MATCH($C10,#REF!,0),MATCH(S$1,#REF!,0))} -> #REF! | T10: {=INDEX(#REF!,MATCH($C10,#REF!,0),MATCH(T$1,#REF!,0))} -> #REF! | U10: {=INDEX(#REF!,MATCH($C10,#REF!,0),MATCH(U$1,#REF!,0))} -> #REF! | V10: {=INDEX(#REF!,MATCH($C10,#REF!,0),MATCH(V$1,#REF!,0))} -> #REF! | W10: {=INDEX(#REF!,MATCH($C10,#REF!,0),MATCH(W$1,#REF!,0))} -> #REF! | X10: {=INDEX(#REF!,MATCH($C10,#REF!,0),MATCH(X$1,#REF!,0))} -> #REF! | Y10: {=INDEX(#REF!,MATCH($C10,#REF!,0),MATCH(Y$1,#REF!,0))} -> #REF! | Z10: {=INDEX(#REF!,MATCH($C10,#REF!,0),MATCH(Z$1,#REF!,0))} -> #REF! | ... AD10: {=INDEX(#REF!,MATCH($C10,#REF!,0),MATCH(AD$1,#REF!,0))} -> #REF! | AE10: =INDEX($E10:$P10,1,MATCH($C$2,$E$1:$P$1,0))-INDEX(S10:AD10,1,MATCH($C$2,S$1:AD$1,0)) -> #REF! | AF10: =IFERROR(INDEX($E10:$P10,1,MATCH($C$2,$E$1:$P$1,0))/INDEX($S10:$AD10,1,MATCH($C$2,S$1:AD$1,0))-1,0) -> 0 | AH10: {=INDEX(#REF!,MATCH($C10,#REF!,0),MATCH(AH$1,#REF!,0))} -> #REF! | AI10: {=INDEX(#REF!,MATCH($C10,#REF!,0),MATCH(AI$1,#REF!,0))} -> #REF! | AJ10: {=INDEX(#REF!,MATCH($C10,#REF!,0),MATCH(AJ$1,#REF!,0))} -> #REF! | AK10: {=INDEX(#REF!,MATCH($C10,#REF!,0),MATCH(AK$1,#REF!,0))} -> #REF! | AL10: {=INDEX(#REF!,MATCH($C10,#REF!,0),MATCH(AL$1,#REF!,0))} -> #REF! | AM10: {=INDEX(#REF!,MATCH($C10,#REF!,0),MATCH(AM$1,#REF!,0))} -> #REF! | AN10: {=INDEX(#REF!,MATCH($C10,#REF!,0),MATCH(AN$1,#REF!,0))} -> #REF! | AO10: {=INDEX(#REF!,MATCH($C10,#REF!,0),MATCH(AO$1,#REF!,0))} -> #REF! | ... AS10: {=INDEX(#REF!,MATCH($C10,#REF!,0),MATCH(AS$1,#REF!,0))} -> #REF! | AT10: =INDEX($E10:$P10,1,MATCH($C$2,$E$1:$P$1,0))-INDEX(AH10:AS10,1,MATCH(EDATE($C$2,-12),AH$1:AS$1,0)) -> #REF! | AU10: =IFERROR(INDEX($E10:$P10,1,MATCH($C$2,$E$1:$P$1,0))/INDEX(AH10:AS10,1,MATCH(EDATE($C$2,-12),AH$1:AS$1,0))-1,0) -> 0 | AW10: =SUMIF(E$1:P$1,"<="&AW$2,E10:P10) -> #REF! | BA10: =SUMIF(S$1:AD$1,"<="&BA$2,S10:AD10) -> #REF! | BC10: =$AW10-BA10 -> #REF! | BD10: =IFERROR($AW10/BA10-1,"-") -> - | BG10: =SUMIF(AH$1:AS$1,"<="&BG$2,AH10:AS10) -> #REF! | BI10: =$AW10-BG10 -> #REF! | BJ10: =IFERROR($AW10/BG10-1,"-") -> -
A11: Receita | C11: Booster definição | E11: {=INDEX(#REF!,MATCH($C11,#REF!,0),MATCH(E$1,#REF!,0))} -> #REF! | F11: {=INDEX(#REF!,MATCH($C11,#REF!,0),MATCH(F$1,#REF!,0))} -> #REF! | G11: {=INDEX(#REF!,MATCH($C11,#REF!,0),MATCH(G$1,#REF!,0))} -> #REF! | H11: {=INDEX(#REF!,MATCH($C11,#REF!,0),MATCH(H$1,#REF!,0))} -> #REF! | I11: {=INDEX(#REF!,MATCH($C11,#REF!,0),MATCH(I$1,#REF!,0))} -> #REF! | J11: {=INDEX(#REF!,MATCH($C11,#REF!,0),MATCH(J$1,#REF!,0))} -> #REF! | K11: {=INDEX(#REF!,MATCH($C11,#REF!,0),MATCH(K$1,#REF!,0))} -> #REF! | L11: {=INDEX(#REF!,MATCH($C11,#REF!,0),MATCH(L$1,#REF!,0))} -> #REF! | ... P11: {=INDEX(#REF!,MATCH($C11,#REF!,0),MATCH(P$1,#REF!,0))} -> #REF! | S11: {=INDEX(#REF!,MATCH($C11,#REF!,0),MATCH(S$1,#REF!,0))} -> #REF! | T11: {=INDEX(#REF!,MATCH($C11,#REF!,0),MATCH(T$1,#REF!,0))} -> #REF! | U11: {=INDEX(#REF!,MATCH($C11,#REF!,0),MATCH(U$1,#REF!,0))} -> #REF! | V11: {=INDEX(#REF!,MATCH($C11,#REF!,0),MATCH(V$1,#REF!,0))} -> #REF! | W11: {=INDEX(#REF!,MATCH($C11,#REF!,0),MATCH(W$1,#REF!,0))} -> #REF! | X11: {=INDEX(#REF!,MATCH($C11,#REF!,0),MATCH(X$1,#REF!,0))} -> #REF! | Y11: {=INDEX(#REF!,MATCH($C11,#REF!,0),MATCH(Y$1,#REF!,0))} -> #REF! | Z11: {=INDEX(#REF!,MATCH($C11,#REF!,0),MATCH(Z$1,#REF!,0))} -> #REF! | ... AD11: {=INDEX(#REF!,MATCH($C11,#REF!,0),MATCH(AD$1,#REF!,0))} -> #REF! | AE11: =INDEX($E11:$P11,1,MATCH($C$2,$E$1:$P$1,0))-INDEX(S11:AD11,1,MATCH($C$2,S$1:AD$1,0)) -> #REF! | AF11: =IFERROR(INDEX($E11:$P11,1,MATCH($C$2,$E$1:$P$1,0))/INDEX($S11:$AD11,1,MATCH($C$2,S$1:AD$1,0))-1,0) -> 0 | AH11: {=INDEX(#REF!,MATCH($C11,#REF!,0),MATCH(AH$1,#REF!,0))} -> #REF! | AI11: {=INDEX(#REF!,MATCH($C11,#REF!,0),MATCH(AI$1,#REF!,0))} -> #REF! | AJ11: {=INDEX(#REF!,MATCH($C11,#REF!,0),MATCH(AJ$1,#REF!,0))} -> #REF! | AK11: {=INDEX(#REF!,MATCH($C11,#REF!,0),MATCH(AK$1,#REF!,0))} -> #REF! | AL11: {=INDEX(#REF!,MATCH($C11,#REF!,0),MATCH(AL$1,#REF!,0))} -> #REF! | AM11: {=INDEX(#REF!,MATCH($C11,#REF!,0),MATCH(AM$1,#REF!,0))} -> #REF! | AN11: {=INDEX(#REF!,MATCH($C11,#REF!,0),MATCH(AN$1,#REF!,0))} -> #REF! | AO11: {=INDEX(#REF!,MATCH($C11,#REF!,0),MATCH(AO$1,#REF!,0))} -> #REF! | ... AS11: {=INDEX(#REF!,MATCH($C11,#REF!,0),MATCH(AS$1,#REF!,0))} -> #REF! | AT11: =INDEX($E11:$P11,1,MATCH($C$2,$E$1:$P$1,0))-INDEX(AH11:AS11,1,MATCH(EDATE($C$2,-12),AH$1:AS$1,0)) -> #REF! | AU11: =IFERROR(INDEX($E11:$P11,1,MATCH($C$2,$E$1:$P$1,0))/INDEX(AH11:AS11,1,MATCH(EDATE($C$2,-12),AH$1:AS$1,0))-1,0) -> 0 | AW11: =SUMIF(E$1:P$1,"<="&AW$2,E11:P11) -> #REF! | BA11: =SUMIF(S$1:AD$1,"<="&BA$2,S11:AD11) -> #REF! | BC11: =$AW11-BA11 -> #REF! | BD11: =IFERROR($AW11/BA11-1,"-") -> - | BG11: =SUMIF(AH$1:AS$1,"<="&BG$2,AH11:AS11) -> #REF! | BI11: =$AW11-BG11 -> #REF! | BJ11: =IFERROR($AW11/BG11-1,"-") -> -
A12: Receita | C12: Booster hidratante | E12: {=INDEX(#REF!,MATCH($C12,#REF!,0),MATCH(E$1,#REF!,0))} -> #REF! | F12: {=INDEX(#REF!,MATCH($C12,#REF!,0),MATCH(F$1,#REF!,0))} -> #REF! | G12: {=INDEX(#REF!,MATCH($C12,#REF!,0),MATCH(G$1,#REF!,0))} -> #REF! | H12: {=INDEX(#REF!,MATCH($C12,#REF!,0),MATCH(H$1,#REF!,0))} -> #REF! | I12: {=INDEX(#REF!,MATCH($C12,#REF!,0),MATCH(I$1,#REF!,0))} -> #REF! | J12: {=INDEX(#REF!,MATCH($C12,#REF!,0),MATCH(J$1,#REF!,0))} -> #REF! | K12: {=INDEX(#REF!,MATCH($C12,#REF!,0),MATCH(K$1,#REF!,0))} -> #REF! | L12: {=INDEX(#REF!,MATCH($C12,#REF!,0),MATCH(L$1,#REF!,0))} -> #REF! | ... P12: {=INDEX(#REF!,MATCH($C12,#REF!,0),MATCH(P$1,#REF!,0))} -> #REF! | S12: {=INDEX(#REF!,MATCH($C12,#REF!,0),MATCH(S$1,#REF!,0))} -> #REF! | T12: {=INDEX(#REF!,MATCH($C12,#REF!,0),MATCH(T$1,#REF!,0))} -> #REF! | U12: {=INDEX(#REF!,MATCH($C12,#REF!,0),MATCH(U$1,#REF!,0))} -> #REF! | V12: {=INDEX(#REF!,MATCH($C12,#REF!,0),MATCH(V$1,#REF!,0))} -> #REF! | W12: {=INDEX(#REF!,MATCH($C12,#REF!,0),MATCH(W$1,#REF!,0))} -> #REF! | X12: {=INDEX(#REF!,MATCH($C12,#REF!,0),MATCH(X$1,#REF!,0))} -> #REF! | Y12: {=INDEX(#REF!,MATCH($C12,#REF!,0),MATCH(Y$1,#REF!,0))} -> #REF! | Z12: {=INDEX(#REF!,MATCH($C12,#REF!,0),MATCH(Z$1,#REF!,0))} -> #REF! | ... AD12: {=INDEX(#REF!,MATCH($C12,#REF!,0),MATCH(AD$1,#REF!,0))} -> #REF! | AE12: =INDEX($E12:$P12,1,MATCH($C$2,$E$1:$P$1,0))-INDEX(S12:AD12,1,MATCH($C$2,S$1:AD$1,0)) -> #REF! | AF12: =IFERROR(INDEX($E12:$P12,1,MATCH($C$2,$E$1:$P$1,0))/INDEX($S12:$AD12,1,MATCH($C$2,S$1:AD$1,0))-1,0) -> 0 | AH12: {=INDEX(#REF!,MATCH($C12,#REF!,0),MATCH(AH$1,#REF!,0))} -> #REF! | AI12: {=INDEX(#REF!,MATCH($C12,#REF!,0),MATCH(AI$1,#REF!,0))} -> #REF! | AJ12: {=INDEX(#REF!,MATCH($C12,#REF!,0),MATCH(AJ$1,#REF!,0))} -> #REF! | AK12: {=INDEX(#REF!,MATCH($C12,#REF!,0),MATCH(AK$1,#REF!,0))} -> #REF! | AL12: {=INDEX(#REF!,MATCH($C12,#REF!,0),MATCH(AL$1,#REF!,0))} -> #REF! | AM12: {=INDEX(#REF!,MATCH($C12,#REF!,0),MATCH(AM$1,#REF!,0))} -> #REF! | AN12: {=INDEX(#REF!,MATCH($C12,#REF!,0),MATCH(AN$1,#REF!,0))} -> #REF! | AO12: {=INDEX(#REF!,MATCH($C12,#REF!,0),MATCH(AO$1,#REF!,0))} -> #REF! | ... AS12: {=INDEX(#REF!,MATCH($C12,#REF!,0),MATCH(AS$1,#REF!,0))} -> #REF! | AT12: =INDEX($E12:$P12,1,MATCH($C$2,$E$1:$P$1,0))-INDEX(AH12:AS12,1,MATCH(EDATE($C$2,-12),AH$1:AS$1,0)) -> #REF! | AU12: =IFERROR(INDEX($E12:$P12,1,MATCH($C$2,$E$1:$P$1,0))/INDEX(AH12:AS12,1,MATCH(EDATE($C$2,-12),AH$1:AS$1,0))-1,0) -> 0 | AW12: =SUMIF(E$1:P$1,"<="&AW$2,E12:P12) -> #REF! | BA12: =SUMIF(S$1:AD$1,"<="&BA$2,S12:AD12) -> #REF! | BC12: =$AW12-BA12 -> #REF! | BD12: =IFERROR($AW12/BA12-1,"-") -> - | BG12: =SUMIF(AH$1:AS$1,"<="&BG$2,AH12:AS12) -> #REF! | BI12: =$AW12-BG12 -> #REF! | BJ12: =IFERROR($AW12/BG12-1,"-") -> -
A13: Receita | C13: Booster fortificante | E13: {=INDEX(#REF!,MATCH($C13,#REF!,0),MATCH(E$1,#REF!,0))} -> #REF! | F13: {=INDEX(#REF!,MATCH($C13,#REF!,0),MATCH(F$1,#REF!,0))} -> #REF! | G13: {=INDEX(#REF!,MATCH($C13,#REF!,0),MATCH(G$1,#REF!,0))} -> #REF! | H13: {=INDEX(#REF!,MATCH($C13,#REF!,0),MATCH(H$1,#REF!,0))} -> #REF! | I13: {=INDEX(#REF!,MATCH($C13,#REF!,0),MATCH(I$1,#REF!,0))} -> #REF! | J13: {=INDEX(#REF!,MATCH($C13,#REF!,0),MATCH(J$1,#REF!,0))} -> #REF! | K13: {=INDEX(#REF!,MATCH($C13,#REF!,0),MATCH(K$1,#REF!,0))} -> #REF! | L13: {=INDEX(#REF!,MATCH($C13,#REF!,0),MATCH(L$1,#REF!,0))} -> #REF! | ... P13: {=INDEX(#REF!,MATCH($C13,#REF!,0),MATCH(P$1,#REF!,0))} -> #REF! | S13: {=INDEX(#REF!,MATCH($C13,#REF!,0),MATCH(S$1,#REF!,0))} -> #REF! | T13: {=INDEX(#REF!,MATCH($C13,#REF!,0),MATCH(T$1,#REF!,0))} -> #REF! | U13: {=INDEX(#REF!,MATCH($C13,#REF!,0),MATCH(U$1,#REF!,0))} -> #REF! | V13: {=INDEX(#REF!,MATCH($C13,#REF!,0),MATCH(V$1,#REF!,0))} -> #REF! | W13: {=INDEX(#REF!,MATCH($C13,#REF!,0),MATCH(W$1,#REF!,0))} -> #REF! | X13: {=INDEX(#REF!,MATCH($C13,#REF!,0),MATCH(X$1,#REF!,0))} -> #REF! | Y13: {=INDEX(#REF!,MATCH($C13,#REF!,0),MATCH(Y$1,#REF!,0))} -> #REF! | Z13: {=INDEX(#REF!,MATCH($C13,#REF!,0),MATCH(Z$1,#REF!,0))} -> #REF! | ... AD13: {=INDEX(#REF!,MATCH($C13,#REF!,0),MATCH(AD$1,#REF!,0))} -> #REF! | AE13: =INDEX($E13:$P13,1,MATCH($C$2,$E$1:$P$1,0))-INDEX(S13:AD13,1,MATCH($C$2,S$1:AD$1,0)) -> #REF! | AF13: =IFERROR(INDEX($E13:$P13,1,MATCH($C$2,$E$1:$P$1,0))/INDEX($S13:$AD13,1,MATCH($C$2,S$1:AD$1,0))-1,0) -> 0 | AH13: {=INDEX(#REF!,MATCH($C13,#REF!,0),MATCH(AH$1,#REF!,0))} -> #REF! | AI13: {=INDEX(#REF!,MATCH($C13,#REF!,0),MATCH(AI$1,#REF!,0))} -> #REF! | AJ13: {=INDEX(#REF!,MATCH($C13,#REF!,0),MATCH(AJ$1,#REF!,0))} -> #REF! | AK13: {=INDEX(#REF!,MATCH($C13,#REF!,0),MATCH(AK$1,#REF!,0))} -> #REF! | AL13: {=INDEX(#REF!,MATCH($C13,#REF!,0),MATCH(AL$1,#REF!,0))} -> #REF! | AM13: {=INDEX(#REF!,MATCH($C13,#REF!,0),MATCH(AM$1,#REF!,0))} -> #REF! | AN13: {=INDEX(#REF!,MATCH($C13,#REF!,0),MATCH(AN$1,#REF!,0))} -> #REF! | AO13: {=INDEX(#REF!,MATCH($C13,#REF!,0),MATCH(AO$1,#REF!,0))} -> #REF! | ... AS13: {=INDEX(#REF!,MATCH($C13,#REF!,0),MATCH(AS$1,#REF!,0))} -> #REF! | AT13: =INDEX($E13:$P13,1,MATCH($C$2,$E$1:$P$1,0))-INDEX(AH13:AS13,1,MATCH(EDATE($C$2,-12),AH$1:AS$1,0)) -> #REF! | AU13: =IFERROR(INDEX($E13:$P13,1,MATCH($C$2,$E$1:$P$1,0))/INDEX(AH13:AS13,1,MATCH(EDATE($C$2,-12),AH$1:AS$1,0))-1,0) -> 0 | AW13: =SUMIF(E$1:P$1,"<="&AW$2,E13:P13) -> #REF! | BA13: =SUMIF(S$1:AD$1,"<="&BA$2,S13:AD13) -> #REF! | BC13: =$AW13-BA13 -> #REF! | BD13: =IFERROR($AW13/BA13-1,"-") -> - | BG13: =SUMIF(AH$1:AS$1,"<="&BG$2,AH13:AS13) -> #REF! | BI13: =$AW13-BG13 -> #REF! | BJ13: =IFERROR($AW13/BG13-1,"-") -> -
A14: Receita | C14: Shampoo a seco 150ml | E14: {=INDEX(#REF!,MATCH($C14,#REF!,0),MATCH(E$1,#REF!,0))} -> #REF! | F14: {=INDEX(#REF!,MATCH($C14,#REF!,0),MATCH(F$1,#REF!,0))} -> #REF! | G14: {=INDEX(#REF!,MATCH($C14,#REF!,0),MATCH(G$1,#REF!,0))} -> #REF! | H14: {=INDEX(#REF!,MATCH($C14,#REF!,0),MATCH(H$1,#REF!,0))} -> #REF! | I14: {=INDEX(#REF!,MATCH($C14,#REF!,0),MATCH(I$1,#REF!,0))} -> #REF! | J14: {=INDEX(#REF!,MATCH($C14,#REF!,0),MATCH(J$1,#REF!,0))} -> #REF! | K14: {=INDEX(#REF!,MATCH($C14,#REF!,0),MATCH(K$1,#REF!,0))} -> #REF! | L14: {=INDEX(#REF!,MATCH($C14,#REF!,0),MATCH(L$1,#REF!,0))} -> #REF! | ... P14: {=INDEX(#REF!,MATCH($C14,#REF!,0),MATCH(P$1,#REF!,0))} -> #REF! | S14: {=INDEX(#REF!,MATCH($C14,#REF!,0),MATCH(S$1,#REF!,0))} -> #REF! | T14: {=INDEX(#REF!,MATCH($C14,#REF!,0),MATCH(T$1,#REF!,0))} -> #REF! | U14: {=INDEX(#REF!,MATCH($C14,#REF!,0),MATCH(U$1,#REF!,0))} -> #REF! | V14: {=INDEX(#REF!,MATCH($C14,#REF!,0),MATCH(V$1,#REF!,0))} -> #REF! | W14: {=INDEX(#REF!,MATCH($C14,#REF!,0),MATCH(W$1,#REF!,0))} -> #REF! | X14: {=INDEX(#REF!,MATCH($C14,#REF!,0),MATCH(X$1,#REF!,0))} -> #REF! | Y14: {=INDEX(#REF!,MATCH($C14,#REF!,0),MATCH(Y$1,#REF!,0))} -> #REF! | Z14: {=INDEX(#REF!,MATCH($C14,#REF!,0),MATCH(Z$1,#REF!,0))} -> #REF! | ... AD14: {=INDEX(#REF!,MATCH($C14,#REF!,0),MATCH(AD$1,#REF!,0))} -> #REF! | AE14: =INDEX($E14:$P14,1,MATCH($C$2,$E$1:$P$1,0))-INDEX(S14:AD14,1,MATCH($C$2,S$1:AD$1,0)) -> #REF! | AF14: =IFERROR(INDEX($E14:$P14,1,MATCH($C$2,$E$1:$P$1,0))/INDEX($S14:$AD14,1,MATCH($C$2,S$1:AD$1,0))-1,0) -> 0 | AH14: {=INDEX(#REF!,MATCH($C14,#REF!,0),MATCH(AH$1,#REF!,0))} -> #REF! | AI14: {=INDEX(#REF!,MATCH($C14,#REF!,0),MATCH(AI$1,#REF!,0))} -> #REF! | AJ14: {=INDEX(#REF!,MATCH($C14,#REF!,0),MATCH(AJ$1,#REF!,0))} -> #REF! | AK14: {=INDEX(#REF!,MATCH($C14,#REF!,0),MATCH(AK$1,#REF!,0))} -> #REF! | AL14: {=INDEX(#REF!,MATCH($C14,#REF!,0),MATCH(AL$1,#REF!,0))} -> #REF! | AM14: {=INDEX(#REF!,MATCH($C14,#REF!,0),MATCH(AM$1,#REF!,0))} -> #REF! | AN14: {=INDEX(#REF!,MATCH($C14,#REF!,0),MATCH(AN$1,#REF!,0))} -> #REF! | AO14: {=INDEX(#REF!,MATCH($C14,#REF!,0),MATCH(AO$1,#REF!,0))} -> #REF! | ... AS14: {=INDEX(#REF!,MATCH($C14,#REF!,0),MATCH(AS$1,#REF!,0))} -> #REF! | AT14: =INDEX($E14:$P14,1,MATCH($C$2,$E$1:$P$1,0))-INDEX(AH14:AS14,1,MATCH(EDATE($C$2,-12),AH$1:AS$1,0)) -> #REF! | AU14: =IFERROR(INDEX($E14:$P14,1,MATCH($C$2,$E$1:$P$1,0))/INDEX(AH14:AS14,1,MATCH(EDATE($C$2,-12),AH$1:AS$1,0))-1,0) -> 0 | AW14: =SUMIF(E$1:P$1,"<="&AW$2,E14:P14) -> #REF! | BA14: =SUMIF(S$1:AD$1,"<="&BA$2,S14:AD14) -> #REF! | BC14: =$AW14-BA14 -> #REF! | BD14: =IFERROR($AW14/BA14-1,"-") -> - | BG14: =SUMIF(AH$1:AS$1,"<="&BG$2,AH14:AS14) -> #REF! | BI14: =$AW14-BG14 -> #REF! | BJ14: =IFERROR($AW14/BG14-1,"-") -> -
A15: Receita | C15: Lançamentos | E15: =SUM(E16:E20) -> #REF! | F15: =SUM(F16:F20) -> #REF! | G15: =SUM(G16:G20) -> #REF! | H15: =SUM(H16:H20) -> #REF! | I15: =SUM(I16:I20) -> #REF! | J15: =SUM(J16:J20) -> #REF! | K15: =SUM(K16:K20) -> #REF! | L15: =SUM(L16:L20) -> #REF! | ... P15: =SUM(P16:P20) -> #REF! | S15: =SUM(S16:S20) -> #REF! | T15: =SUM(T16:T20) -> #REF! | U15: =SUM(U16:U20) -> #REF! | V15: =SUM(V16:V20) -> #REF! | W15: =SUM(W16:W20) -> #REF! | X15: =SUM(X16:X20) -> #REF! | Y15: =SUM(Y16:Y20) -> #REF! | Z15: =SUM(Z16:Z20) -> #REF! | ... AD15: =SUM(AD16:AD20) -> #REF! | AE15: =INDEX($E15:$P15,1,MATCH($C$2,$E$1:$P$1,0))-INDEX(S15:AD15,1,MATCH($C$2,S$1:AD$1,0)) -> #REF! | AF15: =IFERROR(INDEX($E15:$P15,1,MATCH($C$2,$E$1:$P$1,0))/INDEX($S15:$AD15,1,MATCH($C$2,S$1:AD$1,0))-1,0) -> 0 | AH15: =SUM(AH16:AH20) -> #REF! | AI15: =SUM(AI16:AI20) -> #REF! | AJ15: =SUM(AJ16:AJ20) -> #REF! | AK15: =SUM(AK16:AK20) -> #REF! | AL15: =SUM(AL16:AL20) -> #REF! | AM15: =SUM(AM16:AM20) -> #REF! | AN15: =SUM(AN16:AN20) -> #REF! | AO15: =SUM(AO16:AO20) -> #REF! | ... AS15: =SUM(AS16:AS20) -> #REF! | AT15: =INDEX($E15:$P15,1,MATCH($C$2,$E$1:$P$1,0))-INDEX(AH15:AS15,1,MATCH(EDATE($C$2,-12),AH$1:AS$1,0)) -> #REF! | AU15: =IFERROR(INDEX($E15:$P15,1,MATCH($C$2,$E$1:$P$1,0))/INDEX(AH15:AS15,1,MATCH(EDATE($C$2,-12),AH$1:AS$1,0))-1,0) -> 0 | AW15: =SUM(AW16:AW20) -> #REF! | BA15: =SUM(BA16:BA20) -> #REF! | BC15: =$AW15-BA15 -> #REF! | BD15: =IFERROR($AW15/BA15-1,"-") -> - | BG15: =SUM(BG16:BG20) -> #REF! | BI15: =$AW15-BG15 -> #REF! | BJ15: =IFERROR($AW15/BG15-1,"-") -> -
A16: Receita | B16: 1 | C16: {=INDEX(#REF!,MATCH($C$15&$B16,#REF!,0),MATCH(C$15,#REF!,0))} -> #REF! | E16: {=INDEX(#REF!,MATCH($C16,#REF!,0),MATCH(E$1,#REF!,0))} -> #REF! | F16: {=INDEX(#REF!,MATCH($C16,#REF!,0),MATCH(F$1,#REF!,0))} -> #REF! | G16: {=INDEX(#REF!,MATCH($C16,#REF!,0),MATCH(G$1,#REF!,0))} -> #REF! | H16: {=INDEX(#REF!,MATCH($C16,#REF!,0),MATCH(H$1,#REF!,0))} -> #REF! | I16: {=INDEX(#REF!,MATCH($C16,#REF!,0),MATCH(I$1,#REF!,0))} -> #REF! | J16: {=INDEX(#REF!,MATCH($C16,#REF!,0),MATCH(J$1,#REF!,0))} -> #REF! | K16: {=INDEX(#REF!,MATCH($C16,#REF!,0),MATCH(K$1,#REF!,0))} -> #REF! | L16: {=INDEX(#REF!,MATCH($C16,#REF!,0),MATCH(L$1,#REF!,0))} -> #REF! | ... P16: {=INDEX(#REF!,MATCH($C16,#REF!,0),MATCH(P$1,#REF!,0))} -> #REF! | S16: {=INDEX(#REF!,MATCH($C16,#REF!,0),MATCH(S$1,#REF!,0))} -> #REF! | T16: {=INDEX(#REF!,MATCH($C16,#REF!,0),MATCH(T$1,#REF!,0))} -> #REF! | U16: {=INDEX(#REF!,MATCH($C16,#REF!,0),MATCH(U$1,#REF!,0))} -> #REF! | V16: {=INDEX(#REF!,MATCH($C16,#REF!,0),MATCH(V$1,#REF!,0))} -> #REF! | W16: {=INDEX(#REF!,MATCH($C16,#REF!,0),MATCH(W$1,#REF!,0))} -> #REF! | X16: {=INDEX(#REF!,MATCH($C16,#REF!,0),MATCH(X$1,#REF!,0))} -> #REF! | Y16: {=INDEX(#REF!,MATCH($C16,#REF!,0),MATCH(Y$1,#REF!,0))} -> #REF! | Z16: {=INDEX(#REF!,MATCH($C16,#REF!,0),MATCH(Z$1,#REF!,0))} -> #REF! | ... AD16: {=INDEX(#REF!,MATCH($C16,#REF!,0),MATCH(AD$1,#REF!,0))} -> #REF! | AE16: =INDEX($E16:$P16,1,MATCH($C$2,$E$1:$P$1,0))-INDEX(S16:AD16,1,MATCH($C$2,S$1:AD$1,0)) -> #REF! | AF16: =IFERROR(INDEX($E16:$P16,1,MATCH($C$2,$E$1:$P$1,0))/INDEX($S16:$AD16,1,MATCH($C$2,S$1:AD$1,0))-1,0) -> 0 | AH16: {=INDEX(#REF!,MATCH($C16,#REF!,0),MATCH(AH$1,#REF!,0))} -> #REF! | AI16: {=INDEX(#REF!,MATCH($C16,#REF!,0),MATCH(AI$1,#REF!,0))} -> #REF! | AJ16: {=INDEX(#REF!,MATCH($C16,#REF!,0),MATCH(AJ$1,#REF!,0))} -> #REF! | AK16: {=INDEX(#REF!,MATCH($C16,#REF!,0),MATCH(AK$1,#REF!,0))} -> #REF! | AL16: {=INDEX(#REF!,MATCH($C16,#REF!,0),MATCH(AL$1,#REF!,0))} -> #REF! | AM16: {=INDEX(#REF!,MATCH($C16,#REF!,0),MATCH(AM$1,#REF!,0))} -> #REF! | AN16: {=INDEX(#REF!,MATCH($C16,#REF!,0),MATCH(AN$1,#REF!,0))} -> #REF! | AO16: {=INDEX(#REF!,MATCH($C16,#REF!,0),MATCH(AO$1,#REF!,0))} -> #REF! | ... AS16: {=INDEX(#REF!,MATCH($C16,#REF!,0),MATCH(AS$1,#REF!,0))} -> #REF! | AT16: =INDEX($E16:$P16,1,MATCH($C$2,$E$1:$P$1,0))-INDEX(AH16:AS16,1,MATCH(EDATE($C$2,-12),AH$1:AS$1,0)) -> #REF! | AU16: =IFERROR(INDEX($E16:$P16,1,MATCH($C$2,$E$1:$P$1,0))/INDEX(AH16:AS16,1,MATCH(EDATE($C$2,-12),AH$1:AS$1,0))-1,0) -> 0 | AW16: =SUMIF(E$1:P$1,"<="&AW$2,E16:P16) -> #REF! | BA16: =SUMIF(S$1:AD$1,"<="&BA$2,S16:AD16) -> #REF! | BC16: =$AW16-BA16 -> #REF! | BD16: =IFERROR($AW16/BA16-1,"-") -> - | BG16: =SUMIF(AH$1:AS$1,"<="&BG$2,AH16:AS16) -> #REF! | BI16: =$AW16-BG16 -> #REF! | BJ16: =IFERROR($AW16/BG16-1,"-") -> - | BK16: 1
A17: Receita | B17: 2 | C17: {=INDEX(#REF!,MATCH($C$15&$B17,#REF!,0),MATCH(C$15,#REF!,0))} -> #REF! | E17: {=INDEX(#REF!,MATCH($C17,#REF!,0),MATCH(E$1,#REF!,0))} -> #REF! | F17: {=INDEX(#REF!,MATCH($C17,#REF!,0),MATCH(F$1,#REF!,0))} -> #REF! | G17: {=INDEX(#REF!,MATCH($C17,#REF!,0),MATCH(G$1,#REF!,0))} -> #REF! | H17: {=INDEX(#REF!,MATCH($C17,#REF!,0),MATCH(H$1,#REF!,0))} -> #REF! | I17: {=INDEX(#REF!,MATCH($C17,#REF!,0),MATCH(I$1,#REF!,0))} -> #REF! | J17: {=INDEX(#REF!,MATCH($C17,#REF!,0),MATCH(J$1,#REF!,0))} -> #REF! | K17: {=INDEX(#REF!,MATCH($C17,#REF!,0),MATCH(K$1,#REF!,0))} -> #REF! | L17: {=INDEX(#REF!,MATCH($C17,#REF!,0),MATCH(L$1,#REF!,0))} -> #REF! | ... P17: {=INDEX(#REF!,MATCH($C17,#REF!,0),MATCH(P$1,#REF!,0))} -> #REF! | S17: {=INDEX(#REF!,MATCH($C17,#REF!,0),MATCH(S$1,#REF!,0))} -> #REF! | T17: {=INDEX(#REF!,MATCH($C17,#REF!,0),MATCH(T$1,#REF!,0))} -> #REF! | U17: {=INDEX(#REF!,MATCH($C17,#REF!,0),MATCH(U$1,#REF!,0))} -> #REF! | V17: {=INDEX(#REF!,MATCH($C17,#REF!,0),MATCH(V$1,#REF!,0))} -> #REF! | W17: {=INDEX(#REF!,MATCH($C17,#REF!,0),MATCH(W$1,#REF!,0))} -> #REF! | X17: {=INDEX(#REF!,MATCH($C17,#REF!,0),MATCH(X$1,#REF!,0))} -> #REF! | Y17: {=INDEX(#REF!,MATCH($C17,#REF!,0),MATCH(Y$1,#REF!,0))} -> #REF! | Z17: {=INDEX(#REF!,MATCH($C17,#REF!,0),MATCH(Z$1,#REF!,0))} -> #REF! | ... AD17: {=INDEX(#REF!,MATCH($C17,#REF!,0),MATCH(AD$1,#REF!,0))} -> #REF! | AE17: =INDEX($E17:$P17,1,MATCH($C$2,$E$1:$P$1,0))-INDEX(S17:AD17,1,MATCH($C$2,S$1:AD$1,0)) -> #REF! | AF17: =IFERROR(INDEX($E17:$P17,1,MATCH($C$2,$E$1:$P$1,0))/INDEX($S17:$AD17,1,MATCH($C$2,S$1:AD$1,0))-1,0) -> 0 | AH17: {=INDEX(#REF!,MATCH($C17,#REF!,0),MATCH(AH$1,#REF!,0))} -> #REF! | AI17: {=INDEX(#REF!,MATCH($C17,#REF!,0),MATCH(AI$1,#REF!,0))} -> #REF! | AJ17: {=INDEX(#REF!,MATCH($C17,#REF!,0),MATCH(AJ$1,#REF!,0))} -> #REF! | AK17: {=INDEX(#REF!,MATCH($C17,#REF!,0),MATCH(AK$1,#REF!,0))} -> #REF! | AL17: {=INDEX(#REF!,MATCH($C17,#REF!,0),MATCH(AL$1,#REF!,0))} -> #REF! | AM17: {=INDEX(#REF!,MATCH($C17,#REF!,0),MATCH(AM$1,#REF!,0))} -> #REF! | AN17: {=INDEX(#REF!,MATCH($C17,#REF!,0),MATCH(AN$1,#REF!,0))} -> #REF! | AO17: {=INDEX(#REF!,MATCH($C17,#REF!,0),MATCH(AO$1,#REF!,0))} -> #REF! | ... AS17: {=INDEX(#REF!,MATCH($C17,#REF!,0),MATCH(AS$1,#REF!,0))} -> #REF! | AT17: =INDEX($E17:$P17,1,MATCH($C$2,$E$1:$P$1,0))-INDEX(AH17:AS17,1,MATCH(EDATE($C$2,-12),AH$1:AS$1,0)) -> #REF! | AU17: =IFERROR(INDEX($E17:$P17,1,MATCH($C$2,$E$1:$P$1,0))/INDEX(AH17:AS17,1,MATCH(EDATE($C$2,-12),AH$1:AS$1,0))-1,0) -> 0 | AW17: =SUMIF(E$1:P$1,"<="&AW$2,E17:P17) -> #REF! | BA17: =SUMIF(S$1:AD$1,"<="&BA$2,S17:AD17) -> #REF! | BC17: =$AW17-BA17 -> #REF! | BD17: =IFERROR($AW17/BA17-1,"-") -> - | BG17: =SUMIF(AH$1:AS$1,"<="&BG$2,AH17:AS17) -> #REF! | BI17: =$AW17-BG17 -> #REF! | BJ17: =IFERROR($AW17/BG17-1,"-") -> - | BK17: 2
A18: Receita | B18: 3 | C18: {=INDEX(#REF!,MATCH($C$15&$B18,#REF!,0),MATCH(C$15,#REF!,0))} -> #REF! | E18: {=INDEX(#REF!,MATCH($C18,#REF!,0),MATCH(E$1,#REF!,0))} -> #REF! | F18: {=INDEX(#REF!,MATCH($C18,#REF!,0),MATCH(F$1,#REF!,0))} -> #REF! | G18: {=INDEX(#REF!,MATCH($C18,#REF!,0),MATCH(G$1,#REF!,0))} -> #REF! | H18: {=INDEX(#REF!,MATCH($C18,#REF!,0),MATCH(H$1,#REF!,0))} -> #REF! | I18: {=INDEX(#REF!,MATCH($C18,#REF!,0),MATCH(I$1,#REF!,0))} -> #REF! | J18: {=INDEX(#REF!,MATCH($C18,#REF!,0),MATCH(J$1,#REF!,0))} -> #REF! | K18: {=INDEX(#REF!,MATCH($C18,#REF!,0),MATCH(K$1,#REF!,0))} -> #REF! | L18: {=INDEX(#REF!,MATCH($C18,#REF!,0),MATCH(L$1,#REF!,0))} -> #REF! | ... P18: {=INDEX(#REF!,MATCH($C18,#REF!,0),MATCH(P$1,#REF!,0))} -> #REF! | S18: {=INDEX(#REF!,MATCH($C18,#REF!,0),MATCH(S$1,#REF!,0))} -> #REF! | T18: {=INDEX(#REF!,MATCH($C18,#REF!,0),MATCH(T$1,#REF!,0))} -> #REF! | U18: {=INDEX(#REF!,MATCH($C18,#REF!,0),MATCH(U$1,#REF!,0))} -> #REF! | V18: {=INDEX(#REF!,MATCH($C18,#REF!,0),MATCH(V$1,#REF!,0))} -> #REF! | W18: {=INDEX(#REF!,MATCH($C18,#REF!,0),MATCH(W$1,#REF!,0))} -> #REF! | X18: {=INDEX(#REF!,MATCH($C18,#REF!,0),MATCH(X$1,#REF!,0))} -> #REF! | Y18: {=INDEX(#REF!,MATCH($C18,#REF!,0),MATCH(Y$1,#REF!,0))} -> #REF! | Z18: {=INDEX(#REF!,MATCH($C18,#REF!,0),MATCH(Z$1,#REF!,0))} -> #REF! | ... AD18: {=INDEX(#REF!,MATCH($C18,#REF!,0),MATCH(AD$1,#REF!,0))} -> #REF! | AE18: =INDEX($E18:$P18,1,MATCH($C$2,$E$1:$P$1,0))-INDEX(S18:AD18,1,MATCH($C$2,S$1:AD$1,0)) -> #REF! | AF18: =IFERROR(INDEX($E18:$P18,1,MATCH($C$2,$E$1:$P$1,0))/INDEX($S18:$AD18,1,MATCH($C$2,S$1:AD$1,0))-1,0) -> 0 | AH18: {=INDEX(#REF!,MATCH($C18,#REF!,0),MATCH(AH$1,#REF!,0))} -> #REF! | AI18: {=INDEX(#REF!,MATCH($C18,#REF!,0),MATCH(AI$1,#REF!,0))} -> #REF! | AJ18: {=INDEX(#REF!,MATCH($C18,#REF!,0),MATCH(AJ$1,#REF!,0))} -> #REF! | AK18: {=INDEX(#REF!,MATCH($C18,#REF!,0),MATCH(AK$1,#REF!,0))} -> #REF! | AL18: {=INDEX(#REF!,MATCH($C18,#REF!,0),MATCH(AL$1,#REF!,0))} -> #REF! | AM18: {=INDEX(#REF!,MATCH($C18,#REF!,0),MATCH(AM$1,#REF!,0))} -> #REF! | AN18: {=INDEX(#REF!,MATCH($C18,#REF!,0),MATCH(AN$1,#REF!,0))} -> #REF! | AO18: {=INDEX(#REF!,MATCH($C18,#REF!,0),MATCH(AO$1,#REF!,0))} -> #REF! | ... AS18: {=INDEX(#REF!,MATCH($C18,#REF!,0),MATCH(AS$1,#REF!,0))} -> #REF! | AT18: =INDEX($E18:$P18,1,MATCH($C$2,$E$1:$P$1,0))-INDEX(AH18:AS18,1,MATCH(EDATE($C$2,-12),AH$1:AS$1,0)) -> #REF! | AU18: =IFERROR(INDEX($E18:$P18,1,MATCH($C$2,$E$1:$P$1,0))/INDEX(AH18:AS18,1,MATCH(EDATE($C$2,-12),AH$1:AS$1,0))-1,0) -> 0 | AW18: =SUMIF(E$1:P$1,"<="&AW$2,E18:P18) -> #REF! | BA18: =SUMIF(S$1:AD$1,"<="&BA$2,S18:AD18) -> #REF! | BC18: =$AW18-BA18 -> #REF! | BD18: =IFERROR($AW18/BA18-1,"-") -> - | BG18: =SUMIF(AH$1:AS$1,"<="&BG$2,AH18:AS18) -> #REF! | BI18: =$AW18-BG18 -> #REF! | BJ18: =IFERROR($AW18/BG18-1,"-") -> - | BK18: 3
A19: Receita | B19: 2 | C19: Primer cachos definidos 250ml | E19: {=INDEX(#REF!,MATCH($C19,#REF!,0),MATCH(E$1,#REF!,0))} -> #REF! | F19: {=INDEX(#REF!,MATCH($C19,#REF!,0),MATCH(F$1,#REF!,0))} -> #REF! | G19: {=INDEX(#REF!,MATCH($C19,#REF!,0),MATCH(G$1,#REF!,0))} -> #REF! | H19: {=INDEX(#REF!,MATCH($C19,#REF!,0),MATCH(H$1,#REF!,0))} -> #REF! | I19: {=INDEX(#REF!,MATCH($C19,#REF!,0),MATCH(I$1,#REF!,0))} -> #REF! | J19: {=INDEX(#REF!,MATCH($C19,#REF!,0),MATCH(J$1,#REF!,0))} -> #REF! | K19: {=INDEX(#REF!,MATCH($C19,#REF!,0),MATCH(K$1,#REF!,0))} -> #REF! | L19: {=INDEX(#REF!,MATCH($C19,#REF!,0),MATCH(L$1,#REF!,0))} -> #REF! | ... P19: {=INDEX(#REF!,MATCH($C19,#REF!,0),MATCH(P$1,#REF!,0))} -> #REF! | S19: {=INDEX(#REF!,MATCH($C19,#REF!,0),MATCH(S$1,#REF!,0))} -> #REF! | T19: {=INDEX(#REF!,MATCH($C19,#REF!,0),MATCH(T$1,#REF!,0))} -> #REF! | U19: {=INDEX(#REF!,MATCH($C19,#REF!,0),MATCH(U$1,#REF!,0))} -> #REF! | V19: {=INDEX(#REF!,MATCH($C19,#REF!,0),MATCH(V$1,#REF!,0))} -> #REF! | W19: {=INDEX(#REF!,MATCH($C19,#REF!,0),MATCH(W$1,#REF!,0))} -> #REF! | X19: {=INDEX(#REF!,MATCH($C19,#REF!,0),MATCH(X$1,#REF!,0))} -> #REF! | Y19: {=INDEX(#REF!,MATCH($C19,#REF!,0),MATCH(Y$1,#REF!,0))} -> #REF! | Z19: {=INDEX(#REF!,MATCH($C19,#REF!,0),MATCH(Z$1,#REF!,0))} -> #REF! | ... AD19: {=INDEX(#REF!,MATCH($C19,#REF!,0),MATCH(AD$1,#REF!,0))} -> #REF! | AE19: =INDEX($E19:$P19,1,MATCH($C$2,$E$1:$P$1,0))-INDEX(S19:AD19,1,MATCH($C$2,S$1:AD$1,0)) -> #REF! | AF19: =IFERROR(INDEX($E19:$P19,1,MATCH($C$2,$E$1:$P$1,0))/INDEX($S19:$AD19,1,MATCH($C$2,S$1:AD$1,0))-1,0) -> 0 | AH19: {=INDEX(#REF!,MATCH($C19,#REF!,0),MATCH(AH$1,#REF!,0))} -> #REF! | AI19: {=INDEX(#REF!,MATCH($C19,#REF!,0),MATCH(AI$1,#REF!,0))} -> #REF! | AJ19: {=INDEX(#REF!,MATCH($C19,#REF!,0),MATCH(AJ$1,#REF!,0))} -> #REF! | AK19: {=INDEX(#REF!,MATCH($C19,#REF!,0),MATCH(AK$1,#REF!,0))} -> #REF! | AL19: {=INDEX(#REF!,MATCH($C19,#REF!,0),MATCH(AL$1,#REF!,0))} -> #REF! | AM19: {=INDEX(#REF!,MATCH($C19,#REF!,0),MATCH(AM$1,#REF!,0))} -> #REF! | AN19: {=INDEX(#REF!,MATCH($C19,#REF!,0),MATCH(AN$1,#REF!,0))} -> #REF! | AO19: {=INDEX(#REF!,MATCH($C19,#REF!,0),MATCH(AO$1,#REF!,0))} -> #REF! | ... AS19: {=INDEX(#REF!,MATCH($C19,#REF!,0),MATCH(AS$1,#REF!,0))} -> #REF! | AT19: =INDEX($E19:$P19,1,MATCH($C$2,$E$1:$P$1,0))-INDEX(AH19:AS19,1,MATCH(EDATE($C$2,-12),AH$1:AS$1,0)) -> #REF! | AU19: =IFERROR(INDEX($E19:$P19,1,MATCH($C$2,$E$1:$P$1,0))/INDEX(AH19:AS19,1,MATCH(EDATE($C$2,-12),AH$1:AS$1,0))-1,0) -> 0 | AW19: =SUMIF(E$1:P$1,"<="&AW$2,E19:P19) -> #REF! | BA19: =SUMIF(S$1:AD$1,"<="&BA$2,S19:AD19) -> #REF! | BC19: =$AW19-BA19 -> #REF! | BD19: =IFERROR($AW19/BA19-1,"-") -> - | BG19: =SUMIF(AH$1:AS$1,"<="&BG$2,AH19:AS19) -> #REF! | BI19: =$AW19-BG19 -> #REF! | BJ19: =IFERROR($AW19/BG19-1,"-") -> - | BK19: 2
A20: Receita | B20: 3 | C20: Primer liso intacto 150ml | E20: {=INDEX(#REF!,MATCH($C20,#REF!,0),MATCH(E$1,#REF!,0))} -> #REF! | F20: {=INDEX(#REF!,MATCH($C20,#REF!,0),MATCH(F$1,#REF!,0))} -> #REF! | G20: {=INDEX(#REF!,MATCH($C20,#REF!,0),MATCH(G$1,#REF!,0))} -> #REF! | H20: {=INDEX(#REF!,MATCH($C20,#REF!,0),MATCH(H$1,#REF!,0))} -> #REF! | I20: {=INDEX(#REF!,MATCH($C20,#REF!,0),MATCH(I$1,#REF!,0))} -> #REF! | J20: {=INDEX(#REF!,MATCH($C20,#REF!,0),MATCH(J$1,#REF!,0))} -> #REF! | K20: {=INDEX(#REF!,MATCH($C20,#REF!,0),MATCH(K$1,#REF!,0))} -> #REF! | L20: {=INDEX(#REF!,MATCH($C20,#REF!,0),MATCH(L$1,#REF!,0))} -> #REF! | ... P20: {=INDEX(#REF!,MATCH($C20,#REF!,0),MATCH(P$1,#REF!,0))} -> #REF! | S20: {=INDEX(#REF!,MATCH($C20,#REF!,0),MATCH(S$1,#REF!,0))} -> #REF! | T20: {=INDEX(#REF!,MATCH($C20,#REF!,0),MATCH(T$1,#REF!,0))} -> #REF! | U20: {=INDEX(#REF!,MATCH($C20,#REF!,0),MATCH(U$1,#REF!,0))} -> #REF! | V20: {=INDEX(#REF!,MATCH($C20,#REF!,0),MATCH(V$1,#REF!,0))} -> #REF! | W20: {=INDEX(#REF!,MATCH($C20,#REF!,0),MATCH(W$1,#REF!,0))} -> #REF! | X20: {=INDEX(#REF!,MATCH($C20,#REF!,0),MATCH(X$1,#REF!,0))} -> #REF! | Y20: {=INDEX(#REF!,MATCH($C20,#REF!,0),MATCH(Y$1,#REF!,0))} -> #REF! | Z20: {=INDEX(#REF!,MATCH($C20,#REF!,0),MATCH(Z$1,#REF!,0))} -> #REF! | ... AD20: {=INDEX(#REF!,MATCH($C20,#REF!,0),MATCH(AD$1,#REF!,0))} -> #REF! | AE20: =INDEX($E20:$P20,1,MATCH($C$2,$E$1:$P$1,0))-INDEX(S20:AD20,1,MATCH($C$2,S$1:AD$1,0)) -> #REF! | AF20: =IFERROR(INDEX($E20:$P20,1,MATCH($C$2,$E$1:$P$1,0))/INDEX($S20:$AD20,1,MATCH($C$2,S$1:AD$1,0))-1,0) -> 0 | AH20: {=INDEX(#REF!,MATCH($C20,#REF!,0),MATCH(AH$1,#REF!,0))} -> #REF! | AI20: {=INDEX(#REF!,MATCH($C20,#REF!,0),MATCH(AI$1,#REF!,0))} -> #REF! | AJ20: {=INDEX(#REF!,MATCH($C20,#REF!,0),MATCH(AJ$1,#REF!,0))} -> #REF! | AK20: {=INDEX(#REF!,MATCH($C20,#REF!,0),MATCH(AK$1,#REF!,0))} -> #REF! | AL20: {=INDEX(#REF!,MATCH($C20,#REF!,0),MATCH(AL$1,#REF!,0))} -> #REF! | AM20: {=INDEX(#REF!,MATCH($C20,#REF!,0),MATCH(AM$1,#REF!,0))} -> #REF! | AN20: {=INDEX(#REF!,MATCH($C20,#REF!,0),MATCH(AN$1,#REF!,0))} -> #REF! | AO20: {=INDEX(#REF!,MATCH($C20,#REF!,0),MATCH(AO$1,#REF!,0))} -> #REF! | ... AS20: {=INDEX(#REF!,MATCH($C20,#REF!,0),MATCH(AS$1,#REF!,0))} -> #REF! | AT20: =INDEX($E20:$P20,1,MATCH($C$2,$E$1:$P$1,0))-INDEX(AH20:AS20,1,MATCH(EDATE($C$2,-12),AH$1:AS$1,0)) -> #REF! | AU20: =IFERROR(INDEX($E20:$P20,1,MATCH($C$2,$E$1:$P$1,0))/INDEX(AH20:AS20,1,MATCH(EDATE($C$2,-12),AH$1:AS$1,0))-1,0) -> 0 | AW20: =SUMIF(E$1:P$1,"<="&AW$2,E20:P20) -> #REF! | BA20: =SUMIF(S$1:AD$1,"<="&BA$2,S20:AD20) -> #REF! | BC20: =$AW20-BA20 -> #REF! | BD20: =IFERROR($AW20/BA20-1,"-") -> - | BG20: =SUMIF(AH$1:AS$1,"<="&BG$2,AH20:AS20) -> #REF! | BI20: =$AW20-BG20 -> #REF! | BJ20: =IFERROR($AW20/BG20-1,"-") -> - | BK20: 3
A21: Receita | C21: Acessórios | E21: =SUM(E22:E32) -> #REF! | F21: =SUM(F22:F32) -> #REF! | G21: =SUM(G22:G32) -> #REF! | H21: =SUM(H22:H32) -> #REF! | I21: =SUM(I22:I32) -> #REF! | J21: =SUM(J22:J32) -> #REF! | K21: =SUM(K22:K32) -> #REF! | L21: =SUM(L22:L32) -> #REF! | ... P21: =SUM(P22:P32) -> #REF! | S21: =SUM(S22:S32) -> #REF! | T21: =SUM(T22:T32) -> #REF! | U21: =SUM(U22:U32) -> #REF! | V21: =SUM(V22:V32) -> #REF! | W21: =SUM(W22:W32) -> #REF! | X21: =SUM(X22:X32) -> #REF! | Y21: =SUM(Y22:Y32) -> #REF! | Z21: =SUM(Z22:Z32) -> #REF! | ... AD21: =SUM(AD22:AD32) -> #REF! | AE21: =INDEX($E21:$P21,1,MATCH($C$2,$E$1:$P$1,0))-INDEX(S21:AD21,1,MATCH($C$2,S$1:AD$1,0)) -> #REF! | AF21: =IFERROR(INDEX($E21:$P21,1,MATCH($C$2,$E$1:$P$1,0))/INDEX($S21:$AD21,1,MATCH($C$2,S$1:AD$1,0))-1,0) -> 0 | AH21: =SUM(AH22:AH32) -> #REF! | AI21: =SUM(AI22:AI32) -> #REF! | AJ21: =SUM(AJ22:AJ32) -> #REF! | AK21: =SUM(AK22:AK32) -> #REF! | AL21: =SUM(AL22:AL32) -> #REF! | AM21: =SUM(AM22:AM32) -> #REF! | AN21: =SUM(AN22:AN32) -> #REF! | AO21: =SUM(AO22:AO32) -> #REF! | ... AS21: =SUM(AS22:AS32) -> #REF! | AT21: =INDEX($E21:$P21,1,MATCH($C$2,$E$1:$P$1,0))-INDEX(AH21:AS21,1,MATCH(EDATE($C$2,-12),AH$1:AS$1,0)) -> #REF! | AU21: =IFERROR(INDEX($E21:$P21,1,MATCH($C$2,$E$1:$P$1,0))/INDEX(AH21:AS21,1,MATCH(EDATE($C$2,-12),AH$1:AS$1,0))-1,0) -> 0 | AW21: =SUM(AW22:AW32) -> #REF! | BA21: =SUM(BA22:BA32) -> #REF! | BC21: =$AW21-BA21 -> #REF! | BD21: =IFERROR($AW21/BA21-1,"-") -> - | BG21: =SUM(BG22:BG32) -> #REF! | BI21: =$AW21-BG21 -> #REF! | BJ21: =IFERROR($AW21/BG21-1,"-") -> -
A22: Receita | C22: Cubeta pequena | E22: {=INDEX(#REF!,MATCH($C22,#REF!,0),MATCH(E$1,#REF!,0))} -> #REF! | F22: {=INDEX(#REF!,MATCH($C22,#REF!,0),MATCH(F$1,#REF!,0))} -> #REF! | G22: {=INDEX(#REF!,MATCH($C22,#REF!,0),MATCH(G$1,#REF!,0))} -> #REF! | H22: {=INDEX(#REF!,MATCH($C22,#REF!,0),MATCH(H$1,#REF!,0))} -> #REF! | I22: {=INDEX(#REF!,MATCH($C22,#REF!,0),MATCH(I$1,#REF!,0))} -> #REF! | J22: {=INDEX(#REF!,MATCH($C22,#REF!,0),MATCH(J$1,#REF!,0))} -> #REF! | K22: {=INDEX(#REF!,MATCH($C22,#REF!,0),MATCH(K$1,#REF!,0))} -> #REF! | L22: {=INDEX(#REF!,MATCH($C22,#REF!,0),MATCH(L$1,#REF!,0))} -> #REF! | ... P22: {=INDEX(#REF!,MATCH($C22,#REF!,0),MATCH(P$1,#REF!,0))} -> #REF! | S22: {=INDEX(#REF!,MATCH($C22,#REF!,0),MATCH(S$1,#REF!,0))} -> #REF! | T22: {=INDEX(#REF!,MATCH($C22,#REF!,0),MATCH(T$1,#REF!,0))} -> #REF! | U22: {=INDEX(#REF!,MATCH($C22,#REF!,0),MATCH(U$1,#REF!,0))} -> #REF! | V22: {=INDEX(#REF!,MATCH($C22,#REF!,0),MATCH(V$1,#REF!,0))} -> #REF! | W22: {=INDEX(#REF!,MATCH($C22,#REF!,0),MATCH(W$1,#REF!,0))} -> #REF! | X22: {=INDEX(#REF!,MATCH($C22,#REF!,0),MATCH(X$1,#REF!,0))} -> #REF! | Y22: {=INDEX(#REF!,MATCH($C22,#REF!,0),MATCH(Y$1,#REF!,0))} -> #REF! | Z22: {=INDEX(#REF!,MATCH($C22,#REF!,0),MATCH(Z$1,#REF!,0))} -> #REF! | ... AD22: {=INDEX(#REF!,MATCH($C22,#REF!,0),MATCH(AD$1,#REF!,0))} -> #REF! | AE22: =INDEX($E22:$P22,1,MATCH($C$2,$E$1:$P$1,0))-INDEX(S22:AD22,1,MATCH($C$2,S$1:AD$1,0)) -> #REF! | AF22: =IFERROR(INDEX($E22:$P22,1,MATCH($C$2,$E$1:$P$1,0))/INDEX($S22:$AD22,1,MATCH($C$2,S$1:AD$1,0))-1,0) -> 0 | AH22: {=INDEX(#REF!,MATCH($C22,#REF!,0),MATCH(AH$1,#REF!,0))} -> #REF! | AI22: {=INDEX(#REF!,MATCH($C22,#REF!,0),MATCH(AI$1,#REF!,0))} -> #REF! | AJ22: {=INDEX(#REF!,MATCH($C22,#REF!,0),MATCH(AJ$1,#REF!,0))} -> #REF! | AK22: {=INDEX(#REF!,MATCH($C22,#REF!,0),MATCH(AK$1,#REF!,0))} -> #REF! | AL22: {=INDEX(#REF!,MATCH($C22,#REF!,0),MATCH(AL$1,#REF!,0))} -> #REF! | AM22: {=INDEX(#REF!,MATCH($C22,#REF!,0),MATCH(AM$1,#REF!,0))} -> #REF! | AN22: {=INDEX(#REF!,MATCH($C22,#REF!,0),MATCH(AN$1,#REF!,0))} -> #REF! | AO22: {=INDEX(#REF!,MATCH($C22,#REF!,0),MATCH(AO$1,#REF!,0))} -> #REF! | ... AS22: {=INDEX(#REF!,MATCH($C22,#REF!,0),MATCH(AS$1,#REF!,0))} -> #REF! | AT22: =INDEX($E22:$P22,1,MATCH($C$2,$E$1:$P$1,0))-INDEX(AH22:AS22,1,MATCH(EDATE($C$2,-12),AH$1:AS$1,0)) -> #REF! | AU22: =IFERROR(INDEX($E22:$P22,1,MATCH($C$2,$E$1:$P$1,0))/INDEX(AH22:AS22,1,MATCH(EDATE($C$2,-12),AH$1:AS$1,0))-1,0) -> 0 | AW22: =SUMIF(E$1:P$1,"<="&AW$2,E22:P22) -> #REF! | BA22: =SUMIF(S$1:AD$1,"<="&BA$2,S22:AD22) -> #REF! | BC22: =$AW22-BA22 -> #REF! | BD22: =IFERROR($AW22/BA22-1,"-") -> - | BG22: =SUMIF(AH$1:AS$1,"<="&BG$2,AH22:AS22) -> #REF! | BI22: =$AW22-BG22 -> #REF! | BJ22: =IFERROR($AW22/BG22-1,"-") -> -
A23: Receita | C23: Espátula | E23: {=INDEX(#REF!,MATCH($C23,#REF!,0),MATCH(E$1,#REF!,0))} -> #REF! | F23: {=INDEX(#REF!,MATCH($C23,#REF!,0),MATCH(F$1,#REF!,0))} -> #REF! | G23: {=INDEX(#REF!,MATCH($C23,#REF!,0),MATCH(G$1,#REF!,0))} -> #REF! | H23: {=INDEX(#REF!,MATCH($C23,#REF!,0),MATCH(H$1,#REF!,0))} -> #REF! | I23: {=INDEX(#REF!,MATCH($C23,#REF!,0),MATCH(I$1,#REF!,0))} -> #REF! | J23: {=INDEX(#REF!,MATCH($C23,#REF!,0),MATCH(J$1,#REF!,0))} -> #REF! | K23: {=INDEX(#REF!,MATCH($C23,#REF!,0),MATCH(K$1,#REF!,0))} -> #REF! | L23: {=INDEX(#REF!,MATCH($C23,#REF!,0),MATCH(L$1,#REF!,0))} -> #REF! | ... P23: {=INDEX(#REF!,MATCH($C23,#REF!,0),MATCH(P$1,#REF!,0))} -> #REF! | S23: {=INDEX(#REF!,MATCH($C23,#REF!,0),MATCH(S$1,#REF!,0))} -> #REF! | T23: {=INDEX(#REF!,MATCH($C23,#REF!,0),MATCH(T$1,#REF!,0))} -> #REF! | U23: {=INDEX(#REF!,MATCH($C23,#REF!,0),MATCH(U$1,#REF!,0))} -> #REF! | V23: {=INDEX(#REF!,MATCH($C23,#REF!,0),MATCH(V$1,#REF!,0))} -> #REF! | W23: {=INDEX(#REF!,MATCH($C23,#REF!,0),MATCH(W$1,#REF!,0))} -> #REF! | X23: {=INDEX(#REF!,MATCH($C23,#REF!,0),MATCH(X$1,#REF!,0))} -> #REF! | Y23: {=INDEX(#REF!,MATCH($C23,#REF!,0),MATCH(Y$1,#REF!,0))} -> #REF! | Z23: {=INDEX(#REF!,MATCH($C23,#REF!,0),MATCH(Z$1,#REF!,0))} -> #REF! | ... AD23: {=INDEX(#REF!,MATCH($C23,#REF!,0),MATCH(AD$1,#REF!,0))} -> #REF! | AE23: =INDEX($E23:$P23,1,MATCH($C$2,$E$1:$P$1,0))-INDEX(S23:AD23,1,MATCH($C$2,S$1:AD$1,0)) -> #REF! | AF23: =IFERROR(INDEX($E23:$P23,1,MATCH($C$2,$E$1:$P$1,0))/INDEX($S23:$AD23,1,MATCH($C$2,S$1:AD$1,0))-1,0) -> 0 | AH23: {=INDEX(#REF!,MATCH($C23,#REF!,0),MATCH(AH$1,#REF!,0))} -> #REF! | AI23: {=INDEX(#REF!,MATCH($C23,#REF!,0),MATCH(AI$1,#REF!,0))} -> #REF! | AJ23: {=INDEX(#REF!,MATCH($C23,#REF!,0),MATCH(AJ$1,#REF!,0))} -> #REF! | AK23: {=INDEX(#REF!,MATCH($C23,#REF!,0),MATCH(AK$1,#REF!,0))} -> #REF! | AL23: {=INDEX(#REF!,MATCH($C23,#REF!,0),MATCH(AL$1,#REF!,0))} -> #REF! | AM23: {=INDEX(#REF!,MATCH($C23,#REF!,0),MATCH(AM$1,#REF!,0))} -> #REF! | AN23: {=INDEX(#REF!,MATCH($C23,#REF!,0),MATCH(AN$1,#REF!,0))} -> #REF! | AO23: {=INDEX(#REF!,MATCH($C23,#REF!,0),MATCH(AO$1,#REF!,0))} -> #REF! | ... AS23: {=INDEX(#REF!,MATCH($C23,#REF!,0),MATCH(AS$1,#REF!,0))} -> #REF! | AT23: =INDEX($E23:$P23,1,MATCH($C$2,$E$1:$P$1,0))-INDEX(AH23:AS23,1,MATCH(EDATE($C$2,-12),AH$1:AS$1,0)) -> #REF! | AU23: =IFERROR(INDEX($E23:$P23,1,MATCH($C$2,$E$1:$P$1,0))/INDEX(AH23:AS23,1,MATCH(EDATE($C$2,-12),AH$1:AS$1,0))-1,0) -> 0 | AW23: =SUMIF(E$1:P$1,"<="&AW$2,E23:P23) -> #REF! | BA23: =SUMIF(S$1:AD$1,"<="&BA$2,S23:AD23) -> #REF! | BC23: =$AW23-BA23 -> #REF! | BD23: =IFERROR($AW23/BA23-1,"-") -> - | BG23: =SUMIF(AH$1:AS$1,"<="&BG$2,AH23:AS23) -> #REF! | BI23: =$AW23-BG23 -> #REF! | BJ23: =IFERROR($AW23/BG23-1,"-") -> -
A24: Receita | C24: Escova oval | E24: {=INDEX(#REF!,MATCH($C24,#REF!,0),MATCH(E$1,#REF!,0))} -> #REF! | F24: {=INDEX(#REF!,MATCH($C24,#REF!,0),MATCH(F$1,#REF!,0))} -> #REF! | G24: {=INDEX(#REF!,MATCH($C24,#REF!,0),MATCH(G$1,#REF!,0))} -> #REF! | H24: {=INDEX(#REF!,MATCH($C24,#REF!,0),MATCH(H$1,#REF!,0))} -> #REF! | I24: {=INDEX(#REF!,MATCH($C24,#REF!,0),MATCH(I$1,#REF!,0))} -> #REF! | J24: {=INDEX(#REF!,MATCH($C24,#REF!,0),MATCH(J$1,#REF!,0))} -> #REF! | K24: {=INDEX(#REF!,MATCH($C24,#REF!,0),MATCH(K$1,#REF!,0))} -> #REF! | L24: {=INDEX(#REF!,MATCH($C24,#REF!,0),MATCH(L$1,#REF!,0))} -> #REF! | ... P24: {=INDEX(#REF!,MATCH($C24,#REF!,0),MATCH(P$1,#REF!,0))} -> #REF! | S24: {=INDEX(#REF!,MATCH($C24,#REF!,0),MATCH(S$1,#REF!,0))} -> #REF! | T24: {=INDEX(#REF!,MATCH($C24,#REF!,0),MATCH(T$1,#REF!,0))} -> #REF! | U24: {=INDEX(#REF!,MATCH($C24,#REF!,0),MATCH(U$1,#REF!,0))} -> #REF! | V24: {=INDEX(#REF!,MATCH($C24,#REF!,0),MATCH(V$1,#REF!,0))} -> #REF! | W24: {=INDEX(#REF!,MATCH($C24,#REF!,0),MATCH(W$1,#REF!,0))} -> #REF! | X24: {=INDEX(#REF!,MATCH($C24,#REF!,0),MATCH(X$1,#REF!,0))} -> #REF! | Y24: {=INDEX(#REF!,MATCH($C24,#REF!,0),MATCH(Y$1,#REF!,0))} -> #REF! | Z24: {=INDEX(#REF!,MATCH($C24,#REF!,0),MATCH(Z$1,#REF!,0))} -> #REF! | ... AD24: {=INDEX(#REF!,MATCH($C24,#REF!,0),MATCH(AD$1,#REF!,0))} -> #REF! | AE24: =INDEX($E24:$P24,1,MATCH($C$2,$E$1:$P$1,0))-INDEX(S24:AD24,1,MATCH($C$2,S$1:AD$1,0)) -> #REF! | AF24: =IFERROR(INDEX($E24:$P24,1,MATCH($C$2,$E$1:$P$1,0))/INDEX($S24:$AD24,1,MATCH($C$2,S$1:AD$1,0))-1,0) -> 0 | AH24: {=INDEX(#REF!,MATCH($C24,#REF!,0),MATCH(AH$1,#REF!,0))} -> #REF! | AI24: {=INDEX(#REF!,MATCH($C24,#REF!,0),MATCH(AI$1,#REF!,0))} -> #REF! | AJ24: {=INDEX(#REF!,MATCH($C24,#REF!,0),MATCH(AJ$1,#REF!,0))} -> #REF! | AK24: {=INDEX(#REF!,MATCH($C24,#REF!,0),MATCH(AK$1,#REF!,0))} -> #REF! | AL24: {=INDEX(#REF!,MATCH($C24,#REF!,0),MATCH(AL$1,#REF!,0))} -> #REF! | AM24: {=INDEX(#REF!,MATCH($C24,#REF!,0),MATCH(AM$1,#REF!,0))} -> #REF! | AN24: {=INDEX(#REF!,MATCH($C24,#REF!,0),MATCH(AN$1,#REF!,0))} -> #REF! | AO24: {=INDEX(#REF!,MATCH($C24,#REF!,0),MATCH(AO$1,#REF!,0))} -> #REF! | ... AS24: {=INDEX(#REF!,MATCH($C24,#REF!,0),MATCH(AS$1,#REF!,0))} -> #REF! | AT24: =INDEX($E24:$P24,1,MATCH($C$2,$E$1:$P$1,0))-INDEX(AH24:AS24,1,MATCH(EDATE($C$2,-12),AH$1:AS$1,0)) -> #REF! | AU24: =IFERROR(INDEX($E24:$P24,1,MATCH($C$2,$E$1:$P$1,0))/INDEX(AH24:AS24,1,MATCH(EDATE($C$2,-12),AH$1:AS$1,0))-1,0) -> 0 | AW24: =SUMIF(E$1:P$1,"<="&AW$2,E24:P24) -> #REF! | BA24: =SUMIF(S$1:AD$1,"<="&BA$2,S24:AD24) -> #REF! | BC24: =$AW24-BA24 -> #REF! | BD24: =IFERROR($AW24/BA24-1,"-") -> - | BG24: =SUMIF(AH$1:AS$1,"<="&BG$2,AH24:AS24) -> #REF! | BI24: =$AW24-BG24 -> #REF! | BJ24: =IFERROR($AW24/BG24-1,"-") -> -
A25: Receita | C25: Escova polvo | E25: {=INDEX(#REF!,MATCH($C25,#REF!,0),MATCH(E$1,#REF!,0))} -> #REF! | F25: {=INDEX(#REF!,MATCH($C25,#REF!,0),MATCH(F$1,#REF!,0))} -> #REF! | G25: {=INDEX(#REF!,MATCH($C25,#REF!,0),MATCH(G$1,#REF!,0))} -> #REF! | H25: {=INDEX(#REF!,MATCH($C25,#REF!,0),MATCH(H$1,#REF!,0))} -> #REF! | I25: {=INDEX(#REF!,MATCH($C25,#REF!,0),MATCH(I$1,#REF!,0))} -> #REF! | J25: {=INDEX(#REF!,MATCH($C25,#REF!,0),MATCH(J$1,#REF!,0))} -> #REF! | K25: {=INDEX(#REF!,MATCH($C25,#REF!,0),MATCH(K$1,#REF!,0))} -> #REF! | L25: {=INDEX(#REF!,MATCH($C25,#REF!,0),MATCH(L$1,#REF!,0))} -> #REF! | ... P25: {=INDEX(#REF!,MATCH($C25,#REF!,0),MATCH(P$1,#REF!,0))} -> #REF! | S25: {=INDEX(#REF!,MATCH($C25,#REF!,0),MATCH(S$1,#REF!,0))} -> #REF! | T25: {=INDEX(#REF!,MATCH($C25,#REF!,0),MATCH(T$1,#REF!,0))} -> #REF! | U25: {=INDEX(#REF!,MATCH($C25,#REF!,0),MATCH(U$1,#REF!,0))} -> #REF! | V25: {=INDEX(#REF!,MATCH($C25,#REF!,0),MATCH(V$1,#REF!,0))} -> #REF! | W25: {=INDEX(#REF!,MATCH($C25,#REF!,0),MATCH(W$1,#REF!,0))} -> #REF! | X25: {=INDEX(#REF!,MATCH($C25,#REF!,0),MATCH(X$1,#REF!,0))} -> #REF! | Y25: {=INDEX(#REF!,MATCH($C25,#REF!,0),MATCH(Y$1,#REF!,0))} -> #REF! | Z25: {=INDEX(#REF!,MATCH($C25,#REF!,0),MATCH(Z$1,#REF!,0))} -> #REF! | ... AD25: {=INDEX(#REF!,MATCH($C25,#REF!,0),MATCH(AD$1,#REF!,0))} -> #REF! | AE25: =INDEX($E25:$P25,1,MATCH($C$2,$E$1:$P$1,0))-INDEX(S25:AD25,1,MATCH($C$2,S$1:AD$1,0)) -> #REF! | AF25: =IFERROR(INDEX($E25:$P25,1,MATCH($C$2,$E$1:$P$1,0))/INDEX($S25:$AD25,1,MATCH($C$2,S$1:AD$1,0))-1,0) -> 0 | AH25: {=INDEX(#REF!,MATCH($C25,#REF!,0),MATCH(AH$1,#REF!,0))} -> #REF! | AI25: {=INDEX(#REF!,MATCH($C25,#REF!,0),MATCH(AI$1,#REF!,0))} -> #REF! | AJ25: {=INDEX(#REF!,MATCH($C25,#REF!,0),MATCH(AJ$1,#REF!,0))} -> #REF! | AK25: {=INDEX(#REF!,MATCH($C25,#REF!,0),MATCH(AK$1,#REF!,0))} -> #REF! | AL25: {=INDEX(#REF!,MATCH($C25,#REF!,0),MATCH(AL$1,#REF!,0))} -> #REF! | AM25: {=INDEX(#REF!,MATCH($C25,#REF!,0),MATCH(AM$1,#REF!,0))} -> #REF! | AN25: {=INDEX(#REF!,MATCH($C25,#REF!,0),MATCH(AN$1,#REF!,0))} -> #REF! | AO25: {=INDEX(#REF!,MATCH($C25,#REF!,0),MATCH(AO$1,#REF!,0))} -> #REF! | ... AS25: {=INDEX(#REF!,MATCH($C25,#REF!,0),MATCH(AS$1,#REF!,0))} -> #REF! | AT25: =INDEX($E25:$P25,1,MATCH($C$2,$E$1:$P$1,0))-INDEX(AH25:AS25,1,MATCH(EDATE($C$2,-12),AH$1:AS$1,0)) -> #REF! | AU25: =IFERROR(INDEX($E25:$P25,1,MATCH($C$2,$E$1:$P$1,0))/INDEX(AH25:AS25,1,MATCH(EDATE($C$2,-12),AH$1:AS$1,0))-1,0) -> 0 | AW25: =SUMIF(E$1:P$1,"<="&AW$2,E25:P25) -> #REF! | BA25: =SUMIF(S$1:AD$1,"<="&BA$2,S25:AD25) -> #REF! | BC25: =$AW25-BA25 -> #REF! | BD25: =IFERROR($AW25/BA25-1,"-") -> - | BG25: =SUMIF(AH$1:AS$1,"<="&BG$2,AH25:AS25) -> #REF! | BI25: =$AW25-BG25 -> #REF! | BJ25: =IFERROR($AW25/BG25-1,"-") -> -
A26: Receita | C26: Necessaire GE Beauty | E26: {=INDEX(#REF!,MATCH($C26,#REF!,0),MATCH(E$1,#REF!,0))} -> #REF! | F26: {=INDEX(#REF!,MATCH($C26,#REF!,0),MATCH(F$1,#REF!,0))} -> #REF! | G26: {=INDEX(#REF!,MATCH($C26,#REF!,0),MATCH(G$1,#REF!,0))} -> #REF! | H26: {=INDEX(#REF!,MATCH($C26,#REF!,0),MATCH(H$1,#REF!,0))} -> #REF! | I26: {=INDEX(#REF!,MATCH($C26,#REF!,0),MATCH(I$1,#REF!,0))} -> #REF! | J26: {=INDEX(#REF!,MATCH($C26,#REF!,0),MATCH(J$1,#REF!,0))} -> #REF! | K26: {=INDEX(#REF!,MATCH($C26,#REF!,0),MATCH(K$1,#REF!,0))} -> #REF! | L26: {=INDEX(#REF!,MATCH($C26,#REF!,0),MATCH(L$1,#REF!,0))} -> #REF! | ... P26: {=INDEX(#REF!,MATCH($C26,#REF!,0),MATCH(P$1,#REF!,0))} -> #REF! | S26: {=INDEX(#REF!,MATCH($C26,#REF!,0),MATCH(S$1,#REF!,0))} -> #REF! | T26: {=INDEX(#REF!,MATCH($C26,#REF!,0),MATCH(T$1,#REF!,0))} -> #REF! | U26: {=INDEX(#REF!,MATCH($C26,#REF!,0),MATCH(U$1,#REF!,0))} -> #REF! | V26: {=INDEX(#REF!,MATCH($C26,#REF!,0),MATCH(V$1,#REF!,0))} -> #REF! | W26: {=INDEX(#REF!,MATCH($C26,#REF!,0),MATCH(W$1,#REF!,0))} -> #REF! | X26: {=INDEX(#REF!,MATCH($C26,#REF!,0),MATCH(X$1,#REF!,0))} -> #REF! | Y26: {=INDEX(#REF!,MATCH($C26,#REF!,0),MATCH(Y$1,#REF!,0))} -> #REF! | Z26: {=INDEX(#REF!,MATCH($C26,#REF!,0),MATCH(Z$1,#REF!,0))} -> #REF! | ... AD26: {=INDEX(#REF!,MATCH($C26,#REF!,0),MATCH(AD$1,#REF!,0))} -> #REF! | AE26: =INDEX($E26:$P26,1,MATCH($C$2,$E$1:$P$1,0))-INDEX(S26:AD26,1,MATCH($C$2,S$1:AD$1,0)) -> #REF! | AF26: =IFERROR(INDEX($E26:$P26,1,MATCH($C$2,$E$1:$P$1,0))/INDEX($S26:$AD26,1,MATCH($C$2,S$1:AD$1,0))-1,0) -> 0 | AH26: {=INDEX(#REF!,MATCH($C26,#REF!,0),MATCH(AH$1,#REF!,0))} -> #REF! | AI26: {=INDEX(#REF!,MATCH($C26,#REF!,0),MATCH(AI$1,#REF!,0))} -> #REF! | AJ26: {=INDEX(#REF!,MATCH($C26,#REF!,0),MATCH(AJ$1,#REF!,0))} -> #REF! | AK26: {=INDEX(#REF!,MATCH($C26,#REF!,0),MATCH(AK$1,#REF!,0))} -> #REF! | AL26: {=INDEX(#REF!,MATCH($C26,#REF!,0),MATCH(AL$1,#REF!,0))} -> #REF! | AM26: {=INDEX(#REF!,MATCH($C26,#REF!,0),MATCH(AM$1,#REF!,0))} -> #REF! | AN26: {=INDEX(#REF!,MATCH($C26,#REF!,0),MATCH(AN$1,#REF!,0))} -> #REF! | AO26: {=INDEX(#REF!,MATCH($C26,#REF!,0),MATCH(AO$1,#REF!,0))} -> #REF! | ... AS26: {=INDEX(#REF!,MATCH($C26,#REF!,0),MATCH(AS$1,#REF!,0))} -> #REF! | AT26: =INDEX($E26:$P26,1,MATCH($C$2,$E$1:$P$1,0))-INDEX(AH26:AS26,1,MATCH(EDATE($C$2,-12),AH$1:AS$1,0)) -> #REF! | AU26: =IFERROR(INDEX($E26:$P26,1,MATCH($C$2,$E$1:$P$1,0))/INDEX(AH26:AS26,1,MATCH(EDATE($C$2,-12),AH$1:AS$1,0))-1,0) -> 0 | AW26: =SUMIF(E$1:P$1,"<="&AW$2,E26:P26) -> #REF! | BA26: =SUMIF(S$1:AD$1,"<="&BA$2,S26:AD26) -> #REF! | BC26: =$AW26-BA26 -> #REF! | BD26: =IFERROR($AW26/BA26-1,"-") -> - | BG26: =SUMIF(AH$1:AS$1,"<="&BG$2,AH26:AS26) -> #REF! | BI26: =$AW26-BG26 -> #REF! | BJ26: =IFERROR($AW26/BG26-1,"-") -> -
